Workbook

Sheet Resumo
A1: Categoria | B1: 11.24 | C1: 12.24 | D1: 01.25 | E1: 02.25 | F1: 03.25 | G1: 04.25 | H1: 05.25 | I1: 06.25 | J1: 07.25 | K1: 08.25 | L1: 09.25 | M1: 10.25 | N1: 11.25 | O1: 12.25 | P1: Total
A2: Enviado | B2: =COUNTIF(INDIRECT(B$1&"!E2:E1000"),$A2) | C2: =COUNTIF(INDIRECT(C$1&"!E2:E1000"),$A2) | D2: =COUNTIF(INDIRECT(D$1&"!E2:E1000"),$A2) | E2: =COUNTIF(INDIRECT(E$1&"!E2:E1000"),$A2) | F2: =COUNTIF(INDIRECT(F$1&"!E2:E1000"),$A2) | G2: =COUNTIF(INDIRECT(G$1&"!E2:E1000"),$A2) | H2: =COUNTIF(INDIRECT(H$1&"!E2:E1000"),$A2) | I2: =COUNTIF(INDIRECT(I$1&"!E2:E1000"),$A2) | ... O2: =COUNTIF(INDIRECT(O$1&"!E2:E1000"),$A2) | P2: =SUM(B2:O2)
A3: Atrasado | B3: =COUNTIF(INDIRECT("11.24!E2:E1000"),$A3) | C3: =COUNTIF(INDIRECT(C$1&"!E2:E1000"),$A3) | D3: =COUNTIF(INDIRECT(D$1&"!E2:E1000"),$A3) | E3: =COUNTIF(INDIRECT(E$1&"!E2:E1000"),$A3) | F3: =COUNTIF(INDIRECT(F$1&"!E2:E1000"),$A3) | G3: =COUNTIF(INDIRECT(G$1&"!E2:E1000"),$A3) | H3: =COUNTIF(INDIRECT(H$1&"!E2:E1000"),$A3) | I3: =COUNTIF(INDIRECT(I$1&"!E2:E1000"),$A3) | J3: =COUNTIF(INDIRECT(J$1&"!E2:E1000"),$A3) | ... O3: =COUNTIF(INDIRECT(O$1&"!E2:E1000"),$A3) | P3: =SUM(B3:O3)
A4: Atrasado >= 2 | B4: =COUNTIF(INDIRECT("11.24!E2:E1000"),$A4) | C4: =COUNTIF(INDIRECT(C$1&"!E2:E1000"),$A4) | D4: =COUNTIF(INDIRECT(D$1&"!E2:E1000"),$A4) | E4: =COUNTIF(INDIRECT(E$1&"!E2:E1000"),$A4) | F4: =COUNTIF(INDIRECT(F$1&"!E2:E1000"),$A4) | G4: =COUNTIF(INDIRECT(G$1&"!E2:E1000"),$A4) | H4: =COUNTIF(INDIRECT(H$1&"!E2:E1000"),$A4) | I4: =COUNTIF(INDIRECT(I$1&"!E2:E1000"),$A4) | J4: =COUNTIF(INDIRECT(J$1&"!E2:E1000"),$A4) | ... O4: =COUNTIF(INDIRECT(O$1&"!E2:E1000"),$A4) | P4: =SUM(B4:O4)
A5: Duplicado | B5: =COUNTIF(INDIRECT("11.24!E2:E1000"),$A5) | C5: =COUNTIF(INDIRECT(C$1&"!E2:E1000"),$A5) | D5: =COUNTIF(INDIRECT(D$1&"!E2:E1000"),$A5) | E5: =COUNTIF(INDIRECT(E$1&"!E2:E1000"),$A5) | F5: =COUNTIF(INDIRECT(F$1&"!E2:E1000"),$A5) | G5: =COUNTIF(INDIRECT(G$1&"!E2:E1000"),$A5) | H5: =COUNTIF(INDIRECT(H$1&"!E2:E1000"),$A5) | I5: =COUNTIF(INDIRECT(I$1&"!E2:E1000"),$A5) | J5: =COUNTIF(INDIRECT(J$1&"!E2:E1000"),$A5) | ... O5: =COUNTIF(INDIRECT(O$1&"!E2:E1000"),$A5) | P5: =SUM(B5:O5)
A6: Outras Ocorrências | B6: =COUNTIF(INDIRECT("11.24!E2:E1000"),$A6) | C6: =COUNTIF(INDIRECT(C$1&"!E2:E1000"),$A6) | D6: =COUNTIF(INDIRECT(D$1&"!E2:E1000"),$A6) | E6: =COUNTIF(INDIRECT(E$1&"!E2:E1000"),$A6) | F6: =COUNTIF(INDIRECT(F$1&"!E2:E1000"),$A6) | G6: =COUNTIF(INDIRECT(G$1&"!E2:E1000"),$A6) | H6: =COUNTIF(INDIRECT(H$1&"!E2:E1000"),$A6) | I6: =COUNTIF(INDIRECT(I$1&"!E2:E1000"),$A6) | J6: =COUNTIF(INDIRECT(J$1&"!E2:E1000"),$A6) | ... O6: =COUNTIF(INDIRECT(O$1&"!E2:E1000"),$A6) | P6: =SUM(B6:O6)
A7: Sem Técnico | B7: =COUNTIF(INDIRECT("11.24!E2:E1000"),$A7) | C7: =COUNTIF(INDIRECT(C$1&"!E2:E1000"),$A7) | D7: =COUNTIF(INDIRECT(D$1&"!E2:E1000"),$A7) | E7: =COUNTIF(INDIRECT(E$1&"!E2:E1000"),$A7) | F7: =COUNTIF(INDIRECT(F$1&"!E2:E1000"),$A7) | G7: =COUNTIF(INDIRECT(G$1&"!E2:E1000"),$A7) | H7: =COUNTIF(INDIRECT(H$1&"!E2:E1000"),$A7) | I7: =COUNTIF(INDIRECT(I$1&"!E2:E1000"),$A7) | J7: =COUNTIF(INDIRECT(J$1&"!E2:E1000"),$A7) | ... O7: =COUNTIF(INDIRECT(O$1&"!E2:E1000"),$A7) | P7: =SUM(B7:O7)
A8: Total | B8: =SUM(B2:B7) | C8: =SUM(C2:C7) | D8: =SUM(D2:D7) | E8: =SUM(E2:E7) | F8: =SUM(F2:F7) | G8: =SUM(G2:G7) | H8: =SUM(H2:H7) | I8: =SUM(I2:I7) | ... O8: =SUM(O2:O7) | P8: =SUM(B8:O8)
A11: Digite o Mês de Referência | C11: Mês de Referência | K11: Acumulado (Total) | R11: Resumo por Regional
A12: 10.25 | C12: Monitoramento (Envios) | K12: Monitoramento (Envios) | R12: Regional | T12: Valquiria
C13: Regional | D13: Envi. | E13: Atra. | F13: Atra. >= 2 | G13: Dup. | H13: Out. Ocor. | I13: Sem Tec. | K13: Envi. | L13: Atra. | M13: Atra. >= 2 | N13: Dup. | O13: Out. Ocor. | P13: Sem Tec. | R13: =_xlfn.CONCAT("Envios - Mês de Referência - ", A12)
C14: Bianca | D14: {=IFERROR(ROWS(_xlfn._xlws.FILTER(INDIRECT($A$12&"!A2:E100"),(INDIRECT($A$12&"!A2:A100")=$C14)*(INDIRECT($A$12&"!E2:E100")="Enviado"))), 0)} | E14: {=IFERROR(ROWS(_xlfn._xlws.FILTER(INDIRECT($A$12&"!A2:E100"),(INDIRECT($A$12&"!A2:A100")=$C14)*(INDIRECT($A$12&"!E2:E100")="Atrasado"))), 0)} | F14: {=IFERROR(ROWS(_xlfn._xlws.FILTER(INDIRECT($A$12&"!A2:E100"),(INDIRECT($A$12&"!A2:A100")=$C14)*(INDIRECT($A$12&"!E2:E100")="Atrasado >= 2"))), 0)} | G14: {=IFERROR(ROWS(_xlfn._xlws.FILTER(INDIRECT($A$12&"!A2:E100"),(INDIRECT($A$12&"!A2:A100")=$C14)*(INDIRECT($A$12&"!E2:E100")="Duplicado"))), 0)} | H14: {=IFERROR(ROWS(_xlfn._xlws.FILTER(INDIRECT($A$12&"!A2:E100"),(INDIRECT($A$12&"!A2:A100")=$C14)*(INDIRECT($A$12&"!E2:E100")="Outras Ocorrências"))), 0)} | I14: {=IFERROR(ROWS(_xlfn._xlws.FILTER(INDIRECT($A$12&"!A2:E100"),(INDIRECT($A$12&"!A2:A100")=$C14)*(INDIRECT($A$12&"!E2:E100")="Sem Técnico"))), 0)} | K14: =COUNTIF(INDIRECT("Monitoramento!$D$2:$Q$12"), "Enviado") | L14: =COUNTIF(INDIRECT("Monitoramento!$D$2:$Q$12"), "Atrasado") | M14: =COUNTIF(INDIRECT("Monitoramento!$D$2:$Q$12"), "Atrasado >= 2") | N14: =COUNTIF(INDIRECT("Monitoramento!$D$2:$Q$12"), "Duplicado") | O14: =COUNTIF(INDIRECT("Monitoramento!$D$2:$Q$12"), "Outras Ocorrências") | P14: =COUNTIF(INDIRECT("Monitoramento!$D$2:$Q$12"), "Sem Técnico") | R14: Enviados | S14: =VLOOKUP($T$12,$C$14:$I$19,2, FALSE) | T14: =S14/SUM($S$14:$S$19)
C15: Gabriel | D15: {=IFERROR(ROWS(_xlfn._xlws.FILTER(INDIRECT($A$12&"!A2:E100"),(INDIRECT($A$12&"!A2:A100")=$C15)*(INDIRECT($A$12&"!E2:E100")="Enviado"))), 0)} | E15: {=IFERROR(ROWS(_xlfn._xlws.FILTER(INDIRECT($A$12&"!A2:E100"),(INDIRECT($A$12&"!A2:A100")=$C15)*(INDIRECT($A$12&"!E2:E100")="Atrasado"))), 0)} | F15: {=IFERROR(ROWS(_xlfn._xlws.FILTER(INDIRECT($A$12&"!A2:E100"),(INDIRECT($A$12&"!A2:A100")=$C15)*(INDIRECT($A$12&"!E2:E100")="Atrasado >= 2"))), 0)} | G15: {=IFERROR(ROWS(_xlfn._xlws.FILTER(INDIRECT($A$12&"!A2:E100"),(INDIRECT($A$12&"!A2:A100")=$C15)*(INDIRECT($A$12&"!E2:E100")="Duplicado"))), 0)} | H15: {=IFERROR(ROWS(_xlfn._xlws.FILTER(INDIRECT($A$12&"!A2:E100"),(INDIRECT($A$12&"!A2:A100")=$C15)*(INDIRECT($A$12&"!E2:E100")="Outras Ocorrências"))), 0)} | I15: {=IFERROR(ROWS(_xlfn._xlws.FILTER(INDIRECT($A$12&"!A2:E100"),(INDIRECT($A$12&"!A2:A100")=$C15)*(INDIRECT($A$12&"!E2:E100")="Sem Técnico"))), 0)} | K15: =COUNTIF(INDIRECT("Monitoramento!$D$15:$Q$25"), "Enviado") | L15: =COUNTIF(INDIRECT("Monitoramento!$D$15:$Q$25"), "Atrasado") | M15: =COUNTIF(INDIRECT("Monitoramento!$D$15:$Q$25"), "Atrasado >= 2") | N15: =COUNTIF(INDIRECT("Monitoramento!$D$15:$Q$25"), "Duplicado") | O15: =COUNTIF(INDIRECT("Monitoramento!$D$15:$Q$25"), "Outras Ocorrências") | P15: =COUNTIF(INDIRECT("Monitoramento!$D$15:$Q$25"), "Sem Técnico") | R15: Atrasados | S15: =VLOOKUP($T$12,$C$14:$I$19,3,FALSE) | T15: =S15/SUM($S$14:$S$19)
C16: Gustavo | D16: {=IFERROR(ROWS(_xlfn._xlws.FILTER(INDIRECT($A$12&"!A2:E100"),(INDIRECT($A$12&"!A2:A100")=$C16)*(INDIRECT($A$12&"!E2:E100")="Enviado"))), 0)} | E16: {=IFERROR(ROWS(_xlfn._xlws.FILTER(INDIRECT($A$12&"!A2:E100"),(INDIRECT($A$12&"!A2:A100")=$C16)*(INDIRECT($A$12&"!E2:E100")="Atrasado"))), 0)} | F16: {=IFERROR(ROWS(_xlfn._xlws.FILTER(INDIRECT($A$12&"!A2:E100"),(INDIRECT($A$12&"!A2:A100")=$C16)*(INDIRECT($A$12&"!E2:E100")="Atrasado >= 2"))), 0)} | G16: {=IFERROR(ROWS(_xlfn._xlws.FILTER(INDIRECT($A$12&"!A2:E100"),(INDIRECT($A$12&"!A2:A100")=$C16)*(INDIRECT($A$12&"!E2:E100")="Duplicado"))), 0)} | H16: {=IFERROR(ROWS(_xlfn._xlws.FILTER(INDIRECT($A$12&"!A2:E100"),(INDIRECT($A$12&"!A2:A100")=$C16)*(INDIRECT($A$12&"!E2:E100")="Outras Ocorrências"))), 0)} | I16: {=IFERROR(ROWS(_xlfn._xlws.FILTER(INDIRECT($A$12&"!A2:E100"),(INDIRECT($A$12&"!A2:A100")=$C16)*(INDIRECT($A$12&"!E2:E100")="Sem Técnico"))), 0)} | K16: =COUNTIF(INDIRECT("Monitoramento!$D$28:$Q$38"), "Enviado") | L16: =COUNTIF(INDIRECT("Monitoramento!$D$28:$Q$38"), "Atrasado") | M16: =COUNTIF(INDIRECT("Monitoramento!$D$28:$Q$38"), "Atrasado >= 2") | N16: =COUNTIF(INDIRECT("Monitoramento!$D$28:$Q$38"), "Duplicado") | O16: =COUNTIF(INDIRECT("Monitoramento!$D$28:$Q$38"), "Outras Ocorrências") | P16: =COUNTIF(INDIRECT("Monitoramento!$D$28:$Q$38"), "Sem Técnico") | R16: Atrasados >= 2 | S16: =VLOOKUP($T$12,$C$14:$I$19,4,FALSE) | T16: =S16/SUM($S$14:$S$19)
C17: Larissa | D17: {=IFERROR(ROWS(_xlfn._xlws.FILTER(INDIRECT($A$12&"!A2:E100"),(INDIRECT($A$12&"!A2:A100")=$C17)*(INDIRECT($A$12&"!E2:E100")="Enviado"))), 0)} | E17: {=IFERROR(ROWS(_xlfn._xlws.FILTER(INDIRECT($A$12&"!A2:E100"),(INDIRECT($A$12&"!A2:A100")=$C17)*(INDIRECT($A$12&"!E2:E100")="Atrasado"))), 0)} | F17: {=IFERROR(ROWS(_xlfn._xlws.FILTER(INDIRECT($A$12&"!A2:E100"),(INDIRECT($A$12&"!A2:A100")=$C17)*(INDIRECT($A$12&"!E2:E100")="Atrasado >= 2"))), 0)} | G17: {=IFERROR(ROWS(_xlfn._xlws.FILTER(INDIRECT($A$12&"!A2:E100"),(INDIRECT($A$12&"!A2:A100")=$C17)*(INDIRECT($A$12&"!E2:E100")="Duplicado"))), 0)} | H17: {=IFERROR(ROWS(_xlfn._xlws.FILTER(INDIRECT($A$12&"!A2:E100"),(INDIRECT($A$12&"!A2:A100")=$C17)*(INDIRECT($A$12&"!E2:E100")="Outras Ocorrências"))), 0)} | I17: {=IFERROR(ROWS(_xlfn._xlws.FILTER(INDIRECT($A$12&"!A2:E100"),(INDIRECT($A$12&"!A2:A100")=$C17)*(INDIRECT($A$12&"!E2:E100")="Sem Técnico"))), 0)} | K17: =COUNTIF(INDIRECT("Monitoramento!$D$41:$Q$53"), "Enviado") | L17: =COUNTIF(INDIRECT("Monitoramento!$D$41:$Q$53"), "Atrasado") | M17: =COUNTIF(INDIRECT("Monitoramento!$D$41:$Q$53"), "Atrasado >= 2") | N17: =COUNTIF(INDIRECT("Monitoramento!$D$41:$Q$53"), "Duplicado") | O17: =COUNTIF(INDIRECT("Monitoramento!$D$41:$Q$53"), "Outras Ocorrências") | P17: =COUNTIF(INDIRECT("Monitoramento!$D$41:$Q$53"), "Sem Técnico") | R17: Duplicados | S17: =VLOOKUP($T$12,$C$14:$I$19,5,FALSE) | T17: =S17/SUM($S$14:$S$19)
C18: Luana | D18: {=IFERROR(ROWS(_xlfn._xlws.FILTER(INDIRECT($A$12&"!A2:E100"),(INDIRECT($A$12&"!A2:A100")=$C18)*(INDIRECT($A$12&"!E2:E100")="Enviado"))), 0)} | E18: {=IFERROR(ROWS(_xlfn._xlws.FILTER(INDIRECT($A$12&"!A2:E100"),(INDIRECT($A$12&"!A2:A100")=$C18)*(INDIRECT($A$12&"!E2:E100")="Atrasado"))), 0)} | F18: {=IFERROR(ROWS(_xlfn._xlws.FILTER(INDIRECT($A$12&"!A2:E100"),(INDIRECT($A$12&"!A2:A100")=$C18)*(INDIRECT($A$12&"!E2:E100")="Atrasado >= 2"))), 0)} | G18: {=IFERROR(ROWS(_xlfn._xlws.FILTER(INDIRECT($A$12&"!A2:E100"),(INDIRECT($A$12&"!A2:A100")=$C18)*(INDIRECT($A$12&"!E2:E100")="Duplicado"))), 0)} | H18: {=IFERROR(ROWS(_xlfn._xlws.FILTER(INDIRECT($A$12&"!A2:E100"),(INDIRECT($A$12&"!A2:A100")=$C18)*(INDIRECT($A$12&"!E2:E100")="Outras Ocorrências"))), 0)} | I18: {=IFERROR(ROWS(_xlfn._xlws.FILTER(INDIRECT($A$12&"!A2:E100"),(INDIRECT($A$12&"!A2:A100")=$C18)*(INDIRECT($A$12&"!E2:E100")="Sem Técnico"))), 0)} | K18: =COUNTIF(INDIRECT("Monitoramento!$D$56:$Q$67"), "Enviado") | L18: =COUNTIF(INDIRECT("Monitoramento!$D$56:$Q$67"), "Atrasado") | M18: =COUNTIF(INDIRECT("Monitoramento!$D$56:$Q$67"), "Atrasado >= 2") | N18: =COUNTIF(INDIRECT("Monitoramento!$D$56:$Q$67"), "Duplicado") | O18: =COUNTIF(INDIRECT("Monitoramento!$D$56:$Q$67"), "Outras Ocorrências") | P18: =COUNTIF(INDIRECT("Monitoramento!$D$56:$Q$67"), "Sem Técnico") | R18: Outras Ocorrências | S18: =VLOOKUP($T$12,$C$14:$I$19,6,FALSE) | T18: =S18/SUM($S$14:$S$19)
C19: Valquiria | D19: {=IFERROR(ROWS(_xlfn._xlws.FILTER(INDIRECT($A$12&"!A2:E100"),(INDIRECT($A$12&"!A2:A100")=$C19)*(INDIRECT($A$12&"!E2:E100")="Enviado"))), 0)} | E19: {=IFERROR(ROWS(_xlfn._xlws.FILTER(INDIRECT($A$12&"!A2:E100"),(INDIRECT($A$12&"!A2:A100")=$C19)*(INDIRECT($A$12&"!E2:E100")="Atrasado"))), 0)} | F19: {=IFERROR(ROWS(_xlfn._xlws.FILTER(INDIRECT($A$12&"!A2:E100"),(INDIRECT($A$12&"!A2:A100")=$C19)*(INDIRECT($A$12&"!E2:E100")="Atrasado >= 2"))), 0)} | G19: {=IFERROR(ROWS(_xlfn._xlws.FILTER(INDIRECT($A$12&"!A2:E100"),(INDIRECT($A$12&"!A2:A100")=$C19)*(INDIRECT($A$12&"!E2:E100")="Duplicado"))), 0)} | H19: {=IFERROR(ROWS(_xlfn._xlws.FILTER(INDIRECT($A$12&"!A2:E100"),(INDIRECT($A$12&"!A2:A100")=$C19)*(INDIRECT($A$12&"!E2:E100")="Outras Ocorrências"))), 0)} | I19: {=IFERROR(ROWS(_xlfn._xlws.FILTER(INDIRECT($A$12&"!A2:E100"),(INDIRECT($A$12&"!A2:A100")=$C19)*(INDIRECT($A$12&"!E2:E100")="Sem Técnico"))), 0)} | K19: =COUNTIF(INDIRECT("Monitoramento!$D$70:$Q$80"), "Enviado") | L19: =COUNTIF(INDIRECT("Monitoramento!$D$70:$Q$80"), "Atrasado") | M19: =COUNTIF(INDIRECT("Monitoramento!$D$70:$Q$80"), "Atrasado >= 2") | N19: =COUNTIF(INDIRECT("Monitoramento!$D$70:$Q$80"), "Duplicado") | O19: =COUNTIF(INDIRECT("Monitoramento!$D$70:$Q$80"), "Outras Ocorrências") | P19: =COUNTIF(INDIRECT("Monitoramento!$D$70:$Q$80"), "Sem Técnico") | R19: Sem Técnico | S19: =VLOOKUP($T$12,$C$14:$I$19,7,FALSE) | T19: =S19/SUM($S$14:$S$19)
C20: Regionais (Validações) | K20: Regionais (Validações) | R20: % Validação | S20: =VLOOKUP($T$12,$C$22:$I$27,7,FALSE)
C21: Regional | E21: Validados | G21: Não Validados | I21: % Val. | K21: Validados | M21: Não Validados | O21: % Validados | R21: Envios - Acumulado (Total)
C22: Bianca | E22: {=IFERROR(ROWS(_xlfn._xlws.FILTER(INDIRECT($A$12&"!A2:E100"),(INDIRECT($A$12&"!A2:A100")=$C22)*(INDIRECT($A$12&"!G2:G100")="Sim"))), 0)} | G22: {=IFERROR(ROWS(_xlfn._xlws.FILTER(INDIRECT($A$12&"!A2:E100"),(INDIRECT($A$12&"!A2:A100")=$C22)*(INDIRECT($A$12&"!G2:G100")="Não")))-E14, 0)} | I22: =IFERROR(E22/SUM(E22:H22),0) | K22: =COUNTIF(INDIRECT("Regionais!$D$2:$Q$12"), "Sim") | M22: =COUNTIF(INDIRECT("Regionais!$D$2:$Q$12"), "Não")-SUM(L14:M14) | O22: =IFERROR(K22/SUM(K22:N22), 0) | R22: Enviados | S22: =VLOOKUP($T$12,$C$13:$P$19,9,FALSE) | T22: =S22/SUM($S$22:$S$27)
C23: Gabriel | E23: {=IFERROR(ROWS(_xlfn._xlws.FILTER(INDIRECT($A$12&"!A2:E100"),(INDIRECT($A$12&"!A2:A100")=$C23)*(INDIRECT($A$12&"!G2:G100")="Sim"))), 0)} | G23: {=IFERROR(ROWS(_xlfn._xlws.FILTER(INDIRECT($A$12&"!A2:E100"),(INDIRECT($A$12&"!A2:A100")=$C23)*(INDIRECT($A$12&"!G2:G100")="Não")))-E15, 0)} | I23: =IFERROR(E23/SUM(E23:H23),0) | K23: =COUNTIF(INDIRECT("Regionais!$D$15:$Q$25"), "Sim") | M23: =COUNTIF(INDIRECT("Regionais!$D$15:$Q$25"), "Não")-SUM(L15:M15) | O23: =IFERROR(K23/SUM(K23:N23), 0) | R23: Atrasados | S23: =VLOOKUP($T$12,$C$13:$P$19,10,FALSE) | T23: =S23/SUM($S$22:$S$27)
C24: Gustavo | E24: {=IFERROR(ROWS(_xlfn._xlws.FILTER(INDIRECT($A$12&"!A2:E100"),(INDIRECT($A$12&"!A2:A100")=$C24)*(INDIRECT($A$12&"!G2:G100")="Sim"))), 0)} | G24: {=IFERROR(ROWS(_xlfn._xlws.FILTER(INDIRECT($A$12&"!A2:E100"),(INDIRECT($A$12&"!A2:A100")=$C24)*(INDIRECT($A$12&"!G2:G100")="Não")))-E16, 0)} | I24: =IFERROR(E24/SUM(E24:H24),0) | K24: =COUNTIF(INDIRECT("Regionais!$D$28:$Q$38"), "Sim") | M24: =COUNTIF(INDIRECT("Regionais!$D$28:$Q$38"), "Não")-SUM(L16:M16) | O24: =IFERROR(K24/SUM(K24:N24), 0) | R24: Atrasados >= 2 | S24: =VLOOKUP($T$12,$C$13:$P$19,11,FALSE) | T24: =S24/SUM($S$22:$S$27)
C25: Larissa | E25: {=IFERROR(ROWS(_xlfn._xlws.FILTER(INDIRECT($A$12&"!A2:E100"),(INDIRECT($A$12&"!A2:A100")=$C25)*(INDIRECT($A$12&"!G2:G100")="Sim"))), 0)} | G25: {=IFERROR(ROWS(_xlfn._xlws.FILTER(INDIRECT($A$12&"!A2:E100"),(INDIRECT($A$12&"!A2:A100")=$C25)*(INDIRECT($A$12&"!G2:G100")="Não")))-E17, 0)} | I25: =IFERROR(E25/SUM(E25:H25),0) | K25: =COUNTIF(INDIRECT("Regionais!$D$41:$Q$53"), "Sim") | M25: =COUNTIF(INDIRECT("Regionais!$D$41:$Q$53"), "Não")-SUM(L17:M17) | O25: =IFERROR(K25/SUM(K25:N25), 0) | R25: Duplicados | S25: =VLOOKUP($T$12,$C$13:$P$19,12,FALSE) | T25: =S25/SUM($S$22:$S$27)
C26: Luana | E26: {=IFERROR(ROWS(_xlfn._xlws.FILTER(INDIRECT($A$12&"!A2:E100"),(INDIRECT($A$12&"!A2:A100")=$C26)*(INDIRECT($A$12&"!G2:G100")="Sim"))), 0)} | G26: {=IFERROR(ROWS(_xlfn._xlws.FILTER(INDIRECT($A$12&"!A2:E100"),(INDIRECT($A$12&"!A2:A100")=$C26)*(INDIRECT($A$12&"!G2:G100")="Não")))-E18, 0)} | I26: =IFERROR(E26/SUM(E26:H26),0) | K26: =COUNTIF(INDIRECT("Regionais!$D$56:$Q$67"), "Sim") | M26: =COUNTIF(INDIRECT("Regionais!$D$56:$Q$67"), "Não")-SUM(L18:M18) | O26: =IFERROR(K26/SUM(K26:N26), 0) | R26: Outras Ocorrências | S26: =VLOOKUP($T$12,$C$13:$P$19,13,FALSE) | T26: =S26/SUM($S$22:$S$27)
C27: Valquiria | E27: {=IFERROR(ROWS(_xlfn._xlws.FILTER(INDIRECT($A$12&"!A2:E100"),(INDIRECT($A$12&"!A2:A100")=$C27)*(INDIRECT($A$12&"!G2:G100")="Sim"))), 0)} | G27: {=IFERROR(ROWS(_xlfn._xlws.FILTER(INDIRECT($A$12&"!A2:E100"),(INDIRECT($A$12&"!A2:A100")=$C27)*(INDIRECT($A$12&"!G2:G100")="Não")))-E19, 0)} | I27: =IFERROR(E27/SUM(E27:H27),0) | K27: =COUNTIF(INDIRECT("Regionais!$D$70:$Q$80"), "Sim") | M27: =COUNTIF(INDIRECT("Regionais!$D$70:$Q$80"), "Não")-SUM(L19:M19) | O27: =IFERROR(K27/SUM(K27:N27), 0) | R27: Sem Técnico | S27: =VLOOKUP($T$12,$C$13:$P$19,14,FALSE) | T27: =S27/SUM($S$22:$S$27)
R28: % Validação | S28: =VLOOKUP($T$12,$C$21:$P$27,13,FALSE)
C34: Formulários | E34: Enviado | F34: Atrasado | G34: Sem Téc | H34: Outras | I34: Total
C35: 4 - Receitas (11/24) | E35: =B$2+B$5 | F35: =B$3+B$4 | G35: =B$7 | H35: =B$6 | I35: =SUM(E35:H35)
C36: 4 - Receitas (12/24) | E36: =C$2+C$5 | F36: =C$3+C$4 | G36: =C$7 | H36: =C$6 | I36: =SUM(E36:H36)
C37: 4 - Receitas (01/25) | E37: =D$2+D$5 | F37: =D$3+D$4 | G37: =D$7 | H37: =D$6 | I37: =SUM(E37:H37)
C38: 4 - Receitas (02/25) | E38: =E$2+E$5 | F38: =E$3+E$4 | G38: =E$7 | H38: =E$6 | I38: =SUM(E38:H38)
C39: 4 - Receitas (03/25) | E39: =F$2+F$5 | F39: =F$3+F$4 | G39: =F$7 | H39: =F$6 | I39: =SUM(E39:H39)
C40: 4 - Receitas (04/25) | E40: =G$2+G$5 | F40: =G$3+G$4 | G40: =G$7 | H40: =G$6 | I40: =SUM(E40:H40)
C41: 4 - Receitas (05/25) | E41: =H$2+H$5 | F41: =H$3+H$4 | G41: =H$7 | H41: =H$6 | I41: =SUM(E41:H41)
C42: 4 - Receitas (06/25) | E42: =I$2+I$5 | F42: =I$3+I$4 | G42: =I$7 | H42: =I$6 | I42: =SUM(E42:H42)
C43: 4 - Receitas (07/25) | E43: =J$2+J$5 | F43: =J$3+J$4 | G43: =J$7 | H43: =J$6 | I43: =SUM(E43:H43)
C44: 4 - Receitas (08/25) | E44: =K$2+K$5 | F44: =K$3+K$4 | G44: =K$7 | H44: =K$6 | I44: =SUM(E44:H44)
C45: 4 - Receitas (09/25) | E45: =L$2+L$5 | F45: =L$3+L$4 | G45: =L$7 | H45: =L$6 | I45: =SUM(E45:H45)
C46: 4 - Receitas (10/25) | E46: =M$2+M$5 | F46: =M$3+M$4 | G46: =M$7 | H46: =M$6 | I46: =SUM(E46:H46)
C47: 4 - Receitas (11/25) | E47: =N$2+N$5 | F47: =N$3+N$4 | G47: =N$7 | H47: =N$6 | I47: =SUM(E47:H47)
...

Sheet Monitoramento
A1: Regional | B1: Municípios | C1: UVR | D1: 11.24 | E1: 12.24 | F1: 01.25 | G1: 02.25 | H1: 03.25 | I1: 04.25 | J1: 05.25 | K1: 06.25 | L1: 07.25 | M1: 08.25 | N1: 09.25 | O1: 10.25 | P1: 11.25 | Q1: 12.25
A2: Bianca | B2: Anahy | C2: 1 | D2: {=IF( VLOOKUP( $A2, _xlfn._xlws.FILTER( INDIRECT("'"&D$14&"'!A2:E1000"), (INDIRECT("'"&D$14&"'!B2:B1000")=$B2) * (INDIRECT("'"&D$14&"'!C2:C1000")=$C2) ), 5, FALSE )=0, "", VLOOKUP( $A2, _xlfn._xlws.FILTER( INDIRECT("'"&D$14&"'!A2:E1000"), (INDIRECT("'"&D$14&"'!B2:B1000")=$B2) * (INDIRECT("'"&D$14&"'!C2:C1000")=$C2) ), 5, FALSE ) )} | E2: {=IF( VLOOKUP( $A2, _xlfn._xlws.FILTER( INDIRECT("'"&E$14&"'!A2:E1000"), (INDIRECT("'"&E$14&"'!B2:B1000")=$B2) * (INDIRECT("'"&E$14&"'!C2:C1000")=$C2) ), 5, FALSE )=0, "", VLOOKUP( $A2, _xlfn._xlws.FILTER( INDIRECT("'"&E$14&"'!A2:E1000"), (INDIRECT("'"&E$14&"'!B2:B1000")=$B2) * (INDIRECT("'"&E$14&"'!C2:C1000")=$C2) ), 5, FALSE ) )} | F2: {=IF( VLOOKUP( $A2, _xlfn._xlws.FILTER( INDIRECT("'"&F$14&"'!A2:E1000"), (INDIRECT("'"&F$14&"'!B2:B1000")=$B2) * (INDIRECT("'"&F$14&"'!C2:C1000")=$C2) ), 5, FALSE )=0, "", VLOOKUP( $A2, _xlfn._xlws.FILTER( INDIRECT("'"&F$14&"'!A2:E1000"), (INDIRECT("'"&F$14&"'!B2:B1000")=$B2) * (INDIRECT("'"&F$14&"'!C2:C1000")=$C2) ), 5, FALSE ) )} | G2: {=IF( VLOOKUP( $A2, _xlfn._xlws.FILTER( INDIRECT("'"&G$14&"'!A2:E1000"), (INDIRECT("'"&G$14&"'!B2:B1000")=$B2) * (INDIRECT("'"&G$14&"'!C2:C1000")=$C2) ), 5, FALSE )=0, "", VLOOKUP( $A2, _xlfn._xlws.FILTER( INDIRECT("'"&G$14&"'!A2:E1000"), (INDIRECT("'"&G$14&"'!B2:B1000")=$B2) * (INDIRECT("'"&G$14&"'!C2:C1000")=$C2) ), 5, FALSE ) )} | H2: {=IF( VLOOKUP( $A2, _xlfn._xlws.FILTER( INDIRECT("'"&H$14&"'!A2:E1000"), (INDIRECT("'"&H$14&"'!B2:B1000")=$B2) * (INDIRECT("'"&H$14&"'!C2:C1000")=$C2) ), 5, FALSE )=0, "", VLOOKUP( $A2, _xlfn._xlws.FILTER( INDIRECT("'"&H$14&"'!A2:E1000"), (INDIRECT("'"&H$14&"'!B2:B1000")=$B2) * (INDIRECT("'"&H$14&"'!C2:C1000")=$C2) ), 5, FALSE ) )} | I2: {=IF( VLOOKUP( $A2, _xlfn._xlws.FILTER( INDIRECT("'"&I$14&"'!A2:E1000"), (INDIRECT("'"&I$14&"'!B2:B1000")=$B2) * (INDIRECT("'"&I$14&"'!C2:C1000")=$C2) ), 5, FALSE )=0, "", VLOOKUP( $A2, _xlfn._xlws.FILTER( INDIRECT("'"&I$14&"'!A2:E1000"), (INDIRECT("'"&I$14&"'!B2:B1000")=$B2) * (INDIRECT("'"&I$14&"'!C2:C1000")=$C2) ), 5, FALSE ) )} | J2: {=IF( VLOOKUP( $A2, _xlfn._xlws.FILTER( INDIRECT("'"&J$14&"'!A2:E1000"), (INDIRECT("'"&J$14&"'!B2:B1000")=$B2) * (INDIRECT("'"&J$14&"'!C2:C1000")=$C2) ), 5, FALSE )=0, "", VLOOKUP( $A2, _xlfn._xlws.FILTER( INDIRECT("'"&J$14&"'!A2:E1000"), (INDIRECT("'"&J$14&"'!B2:B1000")=$B2) * (INDIRECT("'"&J$14&"'!C2:C1000")=$C2) ), 5, FALSE ) )} | K2: {=IF( VLOOKUP( $A2, _xlfn._xlws.FILTER( INDIRECT("'"&K$14&"'!A2:E1000"), (INDIRECT("'"&K$14&"'!B2:B1000")=$B2) * (INDIRECT("'"&K$14&"'!C2:C1000")=$C2) ), 5, FALSE )=0, "", VLOOKUP( $A2, _xlfn._xlws.FILTER( INDIRECT("'"&K$14&"'!A2:E1000"), (INDIRECT("'"&K$14&"'!B2:B1000")=$B2) * (INDIRECT("'"&K$14&"'!C2:C1000")=$C2) ), 5, FALSE ) )} | ... Q2: {=IF( VLOOKUP( $A2, _xlfn._xlws.FILTER( INDIRECT("'"&Q$14&"'!A2:E1000"), (INDIRECT("'"&Q$14&"'!B2:B1000")=$B2) * (INDIRECT("'"&Q$14&"'!C2:C1000")=$C2) ), 5, FALSE )=0, "", VLOOKUP( $A2, _xlfn._xlws.FILTER( INDIRECT("'"&Q$14&"'!A2:E1000"), (INDIRECT("'"&Q$14&"'!B2:B1000")=$B2) * (INDIRECT("'"&Q$14&"'!C2:C1000")=$C2) ), 5, FALSE ) )}
A3: Bianca | B3: Boa Vista da Aparecida | C3: 1 | D3: {=IF( VLOOKUP( $A3, _xlfn._xlws.FILTER( INDIRECT("'"&D$14&"'!A2:E1000"), (INDIRECT("'"&D$14&"'!B2:B1000")=$B3) * (INDIRECT("'"&D$14&"'!C2:C1000")=$C3) ), 5, FALSE )=0, "", VLOOKUP( $A3, _xlfn._xlws.FILTER( INDIRECT("'"&D$14&"'!A2:E1000"), (INDIRECT("'"&D$14&"'!B2:B1000")=$B3) * (INDIRECT("'"&D$14&"'!C2:C1000")=$C3) ), 5, FALSE ) )} | E3: {=IF( VLOOKUP( $A3, _xlfn._xlws.FILTER( INDIRECT("'"&E$14&"'!A2:E1000"), (INDIRECT("'"&E$14&"'!B2:B1000")=$B3) * (INDIRECT("'"&E$14&"'!C2:C1000")=$C3) ), 5, FALSE )=0, "", VLOOKUP( $A3, _xlfn._xlws.FILTER( INDIRECT("'"&E$14&"'!A2:E1000"), (INDIRECT("'"&E$14&"'!B2:B1000")=$B3) * (INDIRECT("'"&E$14&"'!C2:C1000")=$C3) ), 5, FALSE ) )} | F3: {=IF( VLOOKUP( $A3, _xlfn._xlws.FILTER( INDIRECT("'"&F$14&"'!A2:E1000"), (INDIRECT("'"&F$14&"'!B2:B1000")=$B3) * (INDIRECT("'"&F$14&"'!C2:C1000")=$C3) ), 5, FALSE )=0, "", VLOOKUP( $A3, _xlfn._xlws.FILTER( INDIRECT("'"&F$14&"'!A2:E1000"), (INDIRECT("'"&F$14&"'!B2:B1000")=$B3) * (INDIRECT("'"&F$14&"'!C2:C1000")=$C3) ), 5, FALSE ) )} | G3: {=IF( VLOOKUP( $A3, _xlfn._xlws.FILTER( INDIRECT("'"&G$14&"'!A2:E1000"), (INDIRECT("'"&G$14&"'!B2:B1000")=$B3) * (INDIRECT("'"&G$14&"'!C2:C1000")=$C3) ), 5, FALSE )=0, "", VLOOKUP( $A3, _xlfn._xlws.FILTER( INDIRECT("'"&G$14&"'!A2:E1000"), (INDIRECT("'"&G$14&"'!B2:B1000")=$B3) * (INDIRECT("'"&G$14&"'!C2:C1000")=$C3) ), 5, FALSE ) )} | H3: {=IF( VLOOKUP( $A3, _xlfn._xlws.FILTER( INDIRECT("'"&H$14&"'!A2:E1000"), (INDIRECT("'"&H$14&"'!B2:B1000")=$B3) * (INDIRECT("'"&H$14&"'!C2:C1000")=$C3) ), 5, FALSE )=0, "", VLOOKUP( $A3, _xlfn._xlws.FILTER( INDIRECT("'"&H$14&"'!A2:E1000"), (INDIRECT("'"&H$14&"'!B2:B1000")=$B3) * (INDIRECT("'"&H$14&"'!C2:C1000")=$C3) ), 5, FALSE ) )} | I3: {=IF( VLOOKUP( $A3, _xlfn._xlws.FILTER( INDIRECT("'"&I$14&"'!A2:E1000"), (INDIRECT("'"&I$14&"'!B2:B1000")=$B3) * (INDIRECT("'"&I$14&"'!C2:C1000")=$C3) ), 5, FALSE )=0, "", VLOOKUP( $A3, _xlfn._xlws.FILTER( INDIRECT("'"&I$14&"'!A2:E1000"), (INDIRECT("'"&I$14&"'!B2:B1000")=$B3) * (INDIRECT("'"&I$14&"'!C2:C1000")=$C3) ), 5, FALSE ) )} | J3: {=IF( VLOOKUP( $A3, _xlfn._xlws.FILTER( INDIRECT("'"&J$14&"'!A2:E1000"), (INDIRECT("'"&J$14&"'!B2:B1000")=$B3) * (INDIRECT("'"&J$14&"'!C2:C1000")=$C3) ), 5, FALSE )=0, "", VLOOKUP( $A3, _xlfn._xlws.FILTER( INDIRECT("'"&J$14&"'!A2:E1000"), (INDIRECT("'"&J$14&"'!B2:B1000")=$B3) * (INDIRECT("'"&J$14&"'!C2:C1000")=$C3) ), 5, FALSE ) )} | K3: {=IF( VLOOKUP( $A3, _xlfn._xlws.FILTER( INDIRECT("'"&K$14&"'!A2:E1000"), (INDIRECT("'"&K$14&"'!B2:B1000")=$B3) * (INDIRECT("'"&K$14&"'!C2:C1000")=$C3) ), 5, FALSE )=0, "", VLOOKUP( $A3, _xlfn._xlws.FILTER( INDIRECT("'"&K$14&"'!A2:E1000"), (INDIRECT("'"&K$14&"'!B2:B1000")=$B3) * (INDIRECT("'"&K$14&"'!C2:C1000")=$C3) ), 5, FALSE ) )} | ... Q3: {=IF( VLOOKUP( $A3, _xlfn._xlws.FILTER( INDIRECT("'"&Q$14&"'!A2:E1000"), (INDIRECT("'"&Q$14&"'!B2:B1000")=$B3) * (INDIRECT("'"&Q$14&"'!C2:C1000")=$C3) ), 5, FALSE )=0, "", VLOOKUP( $A3, _xlfn._xlws.FILTER( INDIRECT("'"&Q$14&"'!A2:E1000"), (INDIRECT("'"&Q$14&"'!B2:B1000")=$B3) * (INDIRECT("'"&Q$14&"'!C2:C1000")=$C3) ), 5, FALSE ) )}
A4: Bianca | B4: Braganey | C4: 1 | D4: {=IF( VLOOKUP( $A4, _xlfn._xlws.FILTER( INDIRECT("'"&D$14&"'!A2:E1000"), (INDIRECT("'"&D$14&"'!B2:B1000")=$B4) * (INDIRECT("'"&D$14&"'!C2:C1000")=$C4) ), 5, FALSE )=0, "", VLOOKUP( $A4, _xlfn._xlws.FILTER( INDIRECT("'"&D$14&"'!A2:E1000"), (INDIRECT("'"&D$14&"'!B2:B1000")=$B4) * (INDIRECT("'"&D$14&"'!C2:C1000")=$C4) ), 5, FALSE ) )} | E4: {=IF( VLOOKUP( $A4, _xlfn._xlws.FILTER( INDIRECT("'"&E$14&"'!A2:E1000"), (INDIRECT("'"&E$14&"'!B2:B1000")=$B4) * (INDIRECT("'"&E$14&"'!C2:C1000")=$C4) ), 5, FALSE )=0, "", VLOOKUP( $A4, _xlfn._xlws.FILTER( INDIRECT("'"&E$14&"'!A2:E1000"), (INDIRECT("'"&E$14&"'!B2:B1000")=$B4) * (INDIRECT("'"&E$14&"'!C2:C1000")=$C4) ), 5, FALSE ) )} | F4: {=IF( VLOOKUP( $A4, _xlfn._xlws.FILTER( INDIRECT("'"&F$14&"'!A2:E1000"), (INDIRECT("'"&F$14&"'!B2:B1000")=$B4) * (INDIRECT("'"&F$14&"'!C2:C1000")=$C4) ), 5, FALSE )=0, "", VLOOKUP( $A4, _xlfn._xlws.FILTER( INDIRECT("'"&F$14&"'!A2:E1000"), (INDIRECT("'"&F$14&"'!B2:B1000")=$B4) * (INDIRECT("'"&F$14&"'!C2:C1000")=$C4) ), 5, FALSE ) )} | G4: {=IF( VLOOKUP( $A4, _xlfn._xlws.FILTER( INDIRECT("'"&G$14&"'!A2:E1000"), (INDIRECT("'"&G$14&"'!B2:B1000")=$B4) * (INDIRECT("'"&G$14&"'!C2:C1000")=$C4) ), 5, FALSE )=0, "", VLOOKUP( $A4, _xlfn._xlws.FILTER( INDIRECT("'"&G$14&"'!A2:E1000"), (INDIRECT("'"&G$14&"'!B2:B1000")=$B4) * (INDIRECT("'"&G$14&"'!C2:C1000")=$C4) ), 5, FALSE ) )} | H4: {=IF( VLOOKUP( $A4, _xlfn._xlws.FILTER( INDIRECT("'"&H$14&"'!A2:E1000"), (INDIRECT("'"&H$14&"'!B2:B1000")=$B4) * (INDIRECT("'"&H$14&"'!C2:C1000")=$C4) ), 5, FALSE )=0, "", VLOOKUP( $A4, _xlfn._xlws.FILTER( INDIRECT("'"&H$14&"'!A2:E1000"), (INDIRECT("'"&H$14&"'!B2:B1000")=$B4) * (INDIRECT("'"&H$14&"'!C2:C1000")=$C4) ), 5, FALSE ) )} | I4: {=IF( VLOOKUP( $A4, _xlfn._xlws.FILTER( INDIRECT("'"&I$14&"'!A2:E1000"), (INDIRECT("'"&I$14&"'!B2:B1000")=$B4) * (INDIRECT("'"&I$14&"'!C2:C1000")=$C4) ), 5, FALSE )=0, "", VLOOKUP( $A4, _xlfn._xlws.FILTER( INDIRECT("'"&I$14&"'!A2:E1000"), (INDIRECT("'"&I$14&"'!B2:B1000")=$B4) * (INDIRECT("'"&I$14&"'!C2:C1000")=$C4) ), 5, FALSE ) )} | J4: {=IF( VLOOKUP( $A4, _xlfn._xlws.FILTER( INDIRECT("'"&J$14&"'!A2:E1000"), (INDIRECT("'"&J$14&"'!B2:B1000")=$B4) * (INDIRECT("'"&J$14&"'!C2:C1000")=$C4) ), 5, FALSE )=0, "", VLOOKUP( $A4, _xlfn._xlws.FILTER( INDIRECT("'"&J$14&"'!A2:E1000"), (INDIRECT("'"&J$14&"'!B2:B1000")=$B4) * (INDIRECT("'"&J$14&"'!C2:C1000")=$C4) ), 5, FALSE ) )} | K4: {=IF( VLOOKUP( $A4, _xlfn._xlws.FILTER( INDIRECT("'"&K$14&"'!A2:E1000"), (INDIRECT("'"&K$14&"'!B2:B1000")=$B4) * (INDIRECT("'"&K$14&"'!C2:C1000")=$C4) ), 5, FALSE )=0, "", VLOOKUP( $A4, _xlfn._xlws.FILTER( INDIRECT("'"&K$14&"'!A2:E1000"), (INDIRECT("'"&K$14&"'!B2:B1000")=$B4) * (INDIRECT("'"&K$14&"'!C2:C1000")=$C4) ), 5, FALSE ) )} | ... Q4: {=IF( VLOOKUP( $A4, _xlfn._xlws.FILTER( INDIRECT("'"&Q$14&"'!A2:E1000"), (INDIRECT("'"&Q$14&"'!B2:B1000")=$B4) * (INDIRECT("'"&Q$14&"'!C2:C1000")=$C4) ), 5, FALSE )=0, "", VLOOKUP( $A4, _xlfn._xlws.FILTER( INDIRECT("'"&Q$14&"'!A2:E1000"), (INDIRECT("'"&Q$14&"'!B2:B1000")=$B4) * (INDIRECT("'"&Q$14&"'!C2:C1000")=$C4) ), 5, FALSE ) )}
A5: Bianca | B5: Campo Bonito | C5: 1 | D5: {=IF( VLOOKUP( $A5, _xlfn._xlws.FILTER( INDIRECT("'"&D$14&"'!A2:E1000"), (INDIRECT("'"&D$14&"'!B2:B1000")=$B5) * (INDIRECT("'"&D$14&"'!C2:C1000")=$C5) ), 5, FALSE )=0, "", VLOOKUP( $A5, _xlfn._xlws.FILTER( INDIRECT("'"&D$14&"'!A2:E1000"), (INDIRECT("'"&D$14&"'!B2:B1000")=$B5) * (INDIRECT("'"&D$14&"'!C2:C1000")=$C5) ), 5, FALSE ) )} | E5: {=IF( VLOOKUP( $A5, _xlfn._xlws.FILTER( INDIRECT("'"&E$14&"'!A2:E1000"), (INDIRECT("'"&E$14&"'!B2:B1000")=$B5) * (INDIRECT("'"&E$14&"'!C2:C1000")=$C5) ), 5, FALSE )=0, "", VLOOKUP( $A5, _xlfn._xlws.FILTER( INDIRECT("'"&E$14&"'!A2:E1000"), (INDIRECT("'"&E$14&"'!B2:B1000")=$B5) * (INDIRECT("'"&E$14&"'!C2:C1000")=$C5) ), 5, FALSE ) )} | F5: {=IF( VLOOKUP( $A5, _xlfn._xlws.FILTER( INDIRECT("'"&F$14&"'!A2:E1000"), (INDIRECT("'"&F$14&"'!B2:B1000")=$B5) * (INDIRECT("'"&F$14&"'!C2:C1000")=$C5) ), 5, FALSE )=0, "", VLOOKUP( $A5, _xlfn._xlws.FILTER( INDIRECT("'"&F$14&"'!A2:E1000"), (INDIRECT("'"&F$14&"'!B2:B1000")=$B5) * (INDIRECT("'"&F$14&"'!C2:C1000")=$C5) ), 5, FALSE ) )} | G5: {=IF( VLOOKUP( $A5, _xlfn._xlws.FILTER( INDIRECT("'"&G$14&"'!A2:E1000"), (INDIRECT("'"&G$14&"'!B2:B1000")=$B5) * (INDIRECT("'"&G$14&"'!C2:C1000")=$C5) ), 5, FALSE )=0, "", VLOOKUP( $A5, _xlfn._xlws.FILTER( INDIRECT("'"&G$14&"'!A2:E1000"), (INDIRECT("'"&G$14&"'!B2:B1000")=$B5) * (INDIRECT("'"&G$14&"'!C2:C1000")=$C5) ), 5, FALSE ) )} | H5: {=IF( VLOOKUP( $A5, _xlfn._xlws.FILTER( INDIRECT("'"&H$14&"'!A2:E1000"), (INDIRECT("'"&H$14&"'!B2:B1000")=$B5) * (INDIRECT("'"&H$14&"'!C2:C1000")=$C5) ), 5, FALSE )=0, "", VLOOKUP( $A5, _xlfn._xlws.FILTER( INDIRECT("'"&H$14&"'!A2:E1000"), (INDIRECT("'"&H$14&"'!B2:B1000")=$B5) * (INDIRECT("'"&H$14&"'!C2:C1000")=$C5) ), 5, FALSE ) )} | I5: {=IF( VLOOKUP( $A5, _xlfn._xlws.FILTER( INDIRECT("'"&I$14&"'!A2:E1000"), (INDIRECT("'"&I$14&"'!B2:B1000")=$B5) * (INDIRECT("'"&I$14&"'!C2:C1000")=$C5) ), 5, FALSE )=0, "", VLOOKUP( $A5, _xlfn._xlws.FILTER( INDIRECT("'"&I$14&"'!A2:E1000"), (INDIRECT("'"&I$14&"'!B2:B1000")=$B5) * (INDIRECT("'"&I$14&"'!C2:C1000")=$C5) ), 5, FALSE ) )} | J5: {=IF( VLOOKUP( $A5, _xlfn._xlws.FILTER( INDIRECT("'"&J$14&"'!A2:E1000"), (INDIRECT("'"&J$14&"'!B2:B1000")=$B5) * (INDIRECT("'"&J$14&"'!C2:C1000")=$C5) ), 5, FALSE )=0, "", VLOOKUP( $A5, _xlfn._xlws.FILTER( INDIRECT("'"&J$14&"'!A2:E1000"), (INDIRECT("'"&J$14&"'!B2:B1000")=$B5) * (INDIRECT("'"&J$14&"'!C2:C1000")=$C5) ), 5, FALSE ) )} | K5: {=IF( VLOOKUP( $A5, _xlfn._xlws.FILTER( INDIRECT("'"&K$14&"'!A2:E1000"), (INDIRECT("'"&K$14&"'!B2:B1000")=$B5) * (INDIRECT("'"&K$14&"'!C2:C1000")=$C5) ), 5, FALSE )=0, "", VLOOKUP( $A5, _xlfn._xlws.FILTER( INDIRECT("'"&K$14&"'!A2:E1000"), (INDIRECT("'"&K$14&"'!B2:B1000")=$B5) * (INDIRECT("'"&K$14&"'!C2:C1000")=$C5) ), 5, FALSE ) )} | ... Q5: {=IF( VLOOKUP( $A5, _xlfn._xlws.FILTER( INDIRECT("'"&Q$14&"'!A2:E1000"), (INDIRECT("'"&Q$14&"'!B2:B1000")=$B5) * (INDIRECT("'"&Q$14&"'!C2:C1000")=$C5) ), 5, FALSE )=0, "", VLOOKUP( $A5, _xlfn._xlws.FILTER( INDIRECT("'"&Q$14&"'!A2:E1000"), (INDIRECT("'"&Q$14&"'!B2:B1000")=$B5) * (INDIRECT("'"&Q$14&"'!C2:C1000")=$C5) ), 5, FALSE ) )}
A6: Bianca | B6: Catanduvas | C6: 1 | D6: {=IF( VLOOKUP( $A6, _xlfn._xlws.FILTER( INDIRECT("'"&D$14&"'!A2:E1000"), (INDIRECT("'"&D$14&"'!B2:B1000")=$B6) * (INDIRECT("'"&D$14&"'!C2:C1000")=$C6) ), 5, FALSE )=0, "", VLOOKUP( $A6, _xlfn._xlws.FILTER( INDIRECT("'"&D$14&"'!A2:E1000"), (INDIRECT("'"&D$14&"'!B2:B1000")=$B6) * (INDIRECT("'"&D$14&"'!C2:C1000")=$C6) ), 5, FALSE ) )} | E6: {=IF( VLOOKUP( $A6, _xlfn._xlws.FILTER( INDIRECT("'"&E$14&"'!A2:E1000"), (INDIRECT("'"&E$14&"'!B2:B1000")=$B6) * (INDIRECT("'"&E$14&"'!C2:C1000")=$C6) ), 5, FALSE )=0, "", VLOOKUP( $A6, _xlfn._xlws.FILTER( INDIRECT("'"&E$14&"'!A2:E1000"), (INDIRECT("'"&E$14&"'!B2:B1000")=$B6) * (INDIRECT("'"&E$14&"'!C2:C1000")=$C6) ), 5, FALSE ) )} | F6: {=IF( VLOOKUP( $A6, _xlfn._xlws.FILTER( INDIRECT("'"&F$14&"'!A2:E1000"), (INDIRECT("'"&F$14&"'!B2:B1000")=$B6) * (INDIRECT("'"&F$14&"'!C2:C1000")=$C6) ), 5, FALSE )=0, "", VLOOKUP( $A6, _xlfn._xlws.FILTER( INDIRECT("'"&F$14&"'!A2:E1000"), (INDIRECT("'"&F$14&"'!B2:B1000")=$B6) * (INDIRECT("'"&F$14&"'!C2:C1000")=$C6) ), 5, FALSE ) )} | G6: {=IF( VLOOKUP( $A6, _xlfn._xlws.FILTER( INDIRECT("'"&G$14&"'!A2:E1000"), (INDIRECT("'"&G$14&"'!B2:B1000")=$B6) * (INDIRECT("'"&G$14&"'!C2:C1000")=$C6) ), 5, FALSE )=0, "", VLOOKUP( $A6, _xlfn._xlws.FILTER( INDIRECT("'"&G$14&"'!A2:E1000"), (INDIRECT("'"&G$14&"'!B2:B1000")=$B6) * (INDIRECT("'"&G$14&"'!C2:C1000")=$C6) ), 5, FALSE ) )} | H6: {=IF( VLOOKUP( $A6, _xlfn._xlws.FILTER( INDIRECT("'"&H$14&"'!A2:E1000"), (INDIRECT("'"&H$14&"'!B2:B1000")=$B6) * (INDIRECT("'"&H$14&"'!C2:C1000")=$C6) ), 5, FALSE )=0, "", VLOOKUP( $A6, _xlfn._xlws.FILTER( INDIRECT("'"&H$14&"'!A2:E1000"), (INDIRECT("'"&H$14&"'!B2:B1000")=$B6) * (INDIRECT("'"&H$14&"'!C2:C1000")=$C6) ), 5, FALSE ) )} | I6: {=IF( VLOOKUP( $A6, _xlfn._xlws.FILTER( INDIRECT("'"&I$14&"'!A2:E1000"), (INDIRECT("'"&I$14&"'!B2:B1000")=$B6) * (INDIRECT("'"&I$14&"'!C2:C1000")=$C6) ), 5, FALSE )=0, "", VLOOKUP( $A6, _xlfn._xlws.FILTER( INDIRECT("'"&I$14&"'!A2:E1000"), (INDIRECT("'"&I$14&"'!B2:B1000")=$B6) * (INDIRECT("'"&I$14&"'!C2:C1000")=$C6) ), 5, FALSE ) )} | J6: {=IF( VLOOKUP( $A6, _xlfn._xlws.FILTER( INDIRECT("'"&J$14&"'!A2:E1000"), (INDIRECT("'"&J$14&"'!B2:B1000")=$B6) * (INDIRECT("'"&J$14&"'!C2:C1000")=$C6) ), 5, FALSE )=0, "", VLOOKUP( $A6, _xlfn._xlws.FILTER( INDIRECT("'"&J$14&"'!A2:E1000"), (INDIRECT("'"&J$14&"'!B2:B1000")=$B6) * (INDIRECT("'"&J$14&"'!C2:C1000")=$C6) ), 5, FALSE ) )} | K6: {=IF( VLOOKUP( $A6, _xlfn._xlws.FILTER( INDIRECT("'"&K$14&"'!A2:E1000"), (INDIRECT("'"&K$14&"'!B2:B1000")=$B6) * (INDIRECT("'"&K$14&"'!C2:C1000")=$C6) ), 5, FALSE )=0, "", VLOOKUP( $A6, _xlfn._xlws.FILTER( INDIRECT("'"&K$14&"'!A2:E1000"), (INDIRECT("'"&K$14&"'!B2:B1000")=$B6) * (INDIRECT("'"&K$14&"'!C2:C1000")=$C6) ), 5, FALSE ) )} | ... Q6: {=IF( VLOOKUP( $A6, _xlfn._xlws.FILTER( INDIRECT("'"&Q$14&"'!A2:E1000"), (INDIRECT("'"&Q$14&"'!B2:B1000")=$B6) * (INDIRECT("'"&Q$14&"'!C2:C1000")=$C6) ), 5, FALSE )=0, "", VLOOKUP( $A6, _xlfn._xlws.FILTER( INDIRECT("'"&Q$14&"'!A2:E1000"), (INDIRECT("'"&Q$14&"'!B2:B1000")=$B6) * (INDIRECT("'"&Q$14&"'!C2:C1000")=$C6) ), 5, FALSE ) )}
A7: Bianca | B7: Corbélia | C7: 1 | D7: {=IF( VLOOKUP( $A7, _xlfn._xlws.FILTER( INDIRECT("'"&D$14&"'!A2:E1000"), (INDIRECT("'"&D$14&"'!B2:B1000")=$B7) * (INDIRECT("'"&D$14&"'!C2:C1000")=$C7) ), 5, FALSE )=0, "", VLOOKUP( $A7, _xlfn._xlws.FILTER( INDIRECT("'"&D$14&"'!A2:E1000"), (INDIRECT("'"&D$14&"'!B2:B1000")=$B7) * (INDIRECT("'"&D$14&"'!C2:C1000")=$C7) ), 5, FALSE ) )} | E7: {=IF( VLOOKUP( $A7, _xlfn._xlws.FILTER( INDIRECT("'"&E$14&"'!A2:E1000"), (INDIRECT("'"&E$14&"'!B2:B1000")=$B7) * (INDIRECT("'"&E$14&"'!C2:C1000")=$C7) ), 5, FALSE )=0, "", VLOOKUP( $A7, _xlfn._xlws.FILTER( INDIRECT("'"&E$14&"'!A2:E1000"), (INDIRECT("'"&E$14&"'!B2:B1000")=$B7) * (INDIRECT("'"&E$14&"'!C2:C1000")=$C7) ), 5, FALSE ) )} | F7: {=IF( VLOOKUP( $A7, _xlfn._xlws.FILTER( INDIRECT("'"&F$14&"'!A2:E1000"), (INDIRECT("'"&F$14&"'!B2:B1000")=$B7) * (INDIRECT("'"&F$14&"'!C2:C1000")=$C7) ), 5, FALSE )=0, "", VLOOKUP( $A7, _xlfn._xlws.FILTER( INDIRECT("'"&F$14&"'!A2:E1000"), (INDIRECT("'"&F$14&"'!B2:B1000")=$B7) * (INDIRECT("'"&F$14&"'!C2:C1000")=$C7) ), 5, FALSE ) )} | G7: {=IF( VLOOKUP( $A7, _xlfn._xlws.FILTER( INDIRECT("'"&G$14&"'!A2:E1000"), (INDIRECT("'"&G$14&"'!B2:B1000")=$B7) * (INDIRECT("'"&G$14&"'!C2:C1000")=$C7) ), 5, FALSE )=0, "", VLOOKUP( $A7, _xlfn._xlws.FILTER( INDIRECT("'"&G$14&"'!A2:E1000"), (INDIRECT("'"&G$14&"'!B2:B1000")=$B7) * (INDIRECT("'"&G$14&"'!C2:C1000")=$C7) ), 5, FALSE ) )} | H7: {=IF( VLOOKUP( $A7, _xlfn._xlws.FILTER( INDIRECT("'"&H$14&"'!A2:E1000"), (INDIRECT("'"&H$14&"'!B2:B1000")=$B7) * (INDIRECT("'"&H$14&"'!C2:C1000")=$C7) ), 5, FALSE )=0, "", VLOOKUP( $A7, _xlfn._xlws.FILTER( INDIRECT("'"&H$14&"'!A2:E1000"), (INDIRECT("'"&H$14&"'!B2:B1000")=$B7) * (INDIRECT("'"&H$14&"'!C2:C1000")=$C7) ), 5, FALSE ) )} | I7: {=IF( VLOOKUP( $A7, _xlfn._xlws.FILTER( INDIRECT("'"&I$14&"'!A2:E1000"), (INDIRECT("'"&I$14&"'!B2:B1000")=$B7) * (INDIRECT("'"&I$14&"'!C2:C1000")=$C7) ), 5, FALSE )=0, "", VLOOKUP( $A7, _xlfn._xlws.FILTER( INDIRECT("'"&I$14&"'!A2:E1000"), (INDIRECT("'"&I$14&"'!B2:B1000")=$B7) * (INDIRECT("'"&I$14&"'!C2:C1000")=$C7) ), 5, FALSE ) )} | J7: {=IF( VLOOKUP( $A7, _xlfn._xlws.FILTER( INDIRECT("'"&J$14&"'!A2:E1000"), (INDIRECT("'"&J$14&"'!B2:B1000")=$B7) * (INDIRECT("'"&J$14&"'!C2:C1000")=$C7) ), 5, FALSE )=0, "", VLOOKUP( $A7, _xlfn._xlws.FILTER( INDIRECT("'"&J$14&"'!A2:E1000"), (INDIRECT("'"&J$14&"'!B2:B1000")=$B7) * (INDIRECT("'"&J$14&"'!C2:C1000")=$C7) ), 5, FALSE ) )} | K7: {=IF( VLOOKUP( $A7, _xlfn._xlws.FILTER( INDIRECT("'"&K$14&"'!A2:E1000"), (INDIRECT("'"&K$14&"'!B2:B1000")=$B7) * (INDIRECT("'"&K$14&"'!C2:C1000")=$C7) ), 5, FALSE )=0, "", VLOOKUP( $A7, _xlfn._xlws.FILTER( INDIRECT("'"&K$14&"'!A2:E1000"), (INDIRECT("'"&K$14&"'!B2:B1000")=$B7) * (INDIRECT("'"&K$14&"'!C2:C1000")=$C7) ), 5, FALSE ) )} | ... Q7: {=IF( VLOOKUP( $A7, _xlfn._xlws.FILTER( INDIRECT("'"&Q$14&"'!A2:E1000"), (INDIRECT("'"&Q$14&"'!B2:B1000")=$B7) * (INDIRECT("'"&Q$14&"'!C2:C1000")=$C7) ), 5, FALSE )=0, "", VLOOKUP( $A7, _xlfn._xlws.FILTER( INDIRECT("'"&Q$14&"'!A2:E1000"), (INDIRECT("'"&Q$14&"'!B2:B1000")=$B7) * (INDIRECT("'"&Q$14&"'!C2:C1000")=$C7) ), 5, FALSE ) )}
A8: Bianca | B8: Diamante do Sul | C8: 1 | D8: {=IF( VLOOKUP( $A8, _xlfn._xlws.FILTER( INDIRECT("'"&D$14&"'!A2:E1000"), (INDIRECT("'"&D$14&"'!B2:B1000")=$B8) * (INDIRECT("'"&D$14&"'!C2:C1000")=$C8) ), 5, FALSE )=0, "", VLOOKUP( $A8, _xlfn._xlws.FILTER( INDIRECT("'"&D$14&"'!A2:E1000"), (INDIRECT("'"&D$14&"'!B2:B1000")=$B8) * (INDIRECT("'"&D$14&"'!C2:C1000")=$C8) ), 5, FALSE ) )} | E8: {=IF( VLOOKUP( $A8, _xlfn._xlws.FILTER( INDIRECT("'"&E$14&"'!A2:E1000"), (INDIRECT("'"&E$14&"'!B2:B1000")=$B8) * (INDIRECT("'"&E$14&"'!C2:C1000")=$C8) ), 5, FALSE )=0, "", VLOOKUP( $A8, _xlfn._xlws.FILTER( INDIRECT("'"&E$14&"'!A2:E1000"), (INDIRECT("'"&E$14&"'!B2:B1000")=$B8) * (INDIRECT("'"&E$14&"'!C2:C1000")=$C8) ), 5, FALSE ) )} | F8: {=IF( VLOOKUP( $A8, _xlfn._xlws.FILTER( INDIRECT("'"&F$14&"'!A2:E1000"), (INDIRECT("'"&F$14&"'!B2:B1000")=$B8) * (INDIRECT("'"&F$14&"'!C2:C1000")=$C8) ), 5, FALSE )=0, "", VLOOKUP( $A8, _xlfn._xlws.FILTER( INDIRECT("'"&F$14&"'!A2:E1000"), (INDIRECT("'"&F$14&"'!B2:B1000")=$B8) * (INDIRECT("'"&F$14&"'!C2:C1000")=$C8) ), 5, FALSE ) )} | G8: {=IF( VLOOKUP( $A8, _xlfn._xlws.FILTER( INDIRECT("'"&G$14&"'!A2:E1000"), (INDIRECT("'"&G$14&"'!B2:B1000")=$B8) * (INDIRECT("'"&G$14&"'!C2:C1000")=$C8) ), 5, FALSE )=0, "", VLOOKUP( $A8, _xlfn._xlws.FILTER( INDIRECT("'"&G$14&"'!A2:E1000"), (INDIRECT("'"&G$14&"'!B2:B1000")=$B8) * (INDIRECT("'"&G$14&"'!C2:C1000")=$C8) ), 5, FALSE ) )} | H8: {=IF( VLOOKUP( $A8, _xlfn._xlws.FILTER( INDIRECT("'"&H$14&"'!A2:E1000"), (INDIRECT("'"&H$14&"'!B2:B1000")=$B8) * (INDIRECT("'"&H$14&"'!C2:C1000")=$C8) ), 5, FALSE )=0, "", VLOOKUP( $A8, _xlfn._xlws.FILTER( INDIRECT("'"&H$14&"'!A2:E1000"), (INDIRECT("'"&H$14&"'!B2:B1000")=$B8) * (INDIRECT("'"&H$14&"'!C2:C1000")=$C8) ), 5, FALSE ) )} | I8: {=IF( VLOOKUP( $A8, _xlfn._xlws.FILTER( INDIRECT("'"&I$14&"'!A2:E1000"), (INDIRECT("'"&I$14&"'!B2:B1000")=$B8) * (INDIRECT("'"&I$14&"'!C2:C1000")=$C8) ), 5, FALSE )=0, "", VLOOKUP( $A8, _xlfn._xlws.FILTER( INDIRECT("'"&I$14&"'!A2:E1000"), (INDIRECT("'"&I$14&"'!B2:B1000")=$B8) * (INDIRECT("'"&I$14&"'!C2:C1000")=$C8) ), 5, FALSE ) )} | J8: {=IF( VLOOKUP( $A8, _xlfn._xlws.FILTER( INDIRECT("'"&J$14&"'!A2:E1000"), (INDIRECT("'"&J$14&"'!B2:B1000")=$B8) * (INDIRECT("'"&J$14&"'!C2:C1000")=$C8) ), 5, FALSE )=0, "", VLOOKUP( $A8, _xlfn._xlws.FILTER( INDIRECT("'"&J$14&"'!A2:E1000"), (INDIRECT("'"&J$14&"'!B2:B1000")=$B8) * (INDIRECT("'"&J$14&"'!C2:C1000")=$C8) ), 5, FALSE ) )} | K8: {=IF( VLOOKUP( $A8, _xlfn._xlws.FILTER( INDIRECT("'"&K$14&"'!A2:E1000"), (INDIRECT("'"&K$14&"'!B2:B1000")=$B8) * (INDIRECT("'"&K$14&"'!C2:C1000")=$C8) ), 5, FALSE )=0, "", VLOOKUP( $A8, _xlfn._xlws.FILTER( INDIRECT("'"&K$14&"'!A2:E1000"), (INDIRECT("'"&K$14&"'!B2:B1000")=$B8) * (INDIRECT("'"&K$14&"'!C2:C1000")=$C8) ), 5, FALSE ) )} | ... Q8: {=IF( VLOOKUP( $A8, _xlfn._xlws.FILTER( INDIRECT("'"&Q$14&"'!A2:E1000"), (INDIRECT("'"&Q$14&"'!B2:B1000")=$B8) * (INDIRECT("'"&Q$14&"'!C2:C1000")=$C8) ), 5, FALSE )=0, "", VLOOKUP( $A8, _xlfn._xlws.FILTER( INDIRECT("'"&Q$14&"'!A2:E1000"), (INDIRECT("'"&Q$14&"'!B2:B1000")=$B8) * (INDIRECT("'"&Q$14&"'!C2:C1000")=$C8) ), 5, FALSE ) )}
A9: Bianca | B9: Guaraniacu | C9: 1 | D9: {=IF( VLOOKUP( $A9, _xlfn._xlws.FILTER( INDIRECT("'"&D$14&"'!A2:E1000"), (INDIRECT("'"&D$14&"'!B2:B1000")=$B9) * (INDIRECT("'"&D$14&"'!C2:C1000")=$C9) ), 5, FALSE )=0, "", VLOOKUP( $A9, _xlfn._xlws.FILTER( INDIRECT("'"&D$14&"'!A2:E1000"), (INDIRECT("'"&D$14&"'!B2:B1000")=$B9) * (INDIRECT("'"&D$14&"'!C2:C1000")=$C9) ), 5, FALSE ) )} | E9: {=IF( VLOOKUP( $A9, _xlfn._xlws.FILTER( INDIRECT("'"&E$14&"'!A2:E1000"), (INDIRECT("'"&E$14&"'!B2:B1000")=$B9) * (INDIRECT("'"&E$14&"'!C2:C1000")=$C9) ), 5, FALSE )=0, "", VLOOKUP( $A9, _xlfn._xlws.FILTER( INDIRECT("'"&E$14&"'!A2:E1000"), (INDIRECT("'"&E$14&"'!B2:B1000")=$B9) * (INDIRECT("'"&E$14&"'!C2:C1000")=$C9) ), 5, FALSE ) )} | F9: {=IF( VLOOKUP( $A9, _xlfn._xlws.FILTER( INDIRECT("'"&F$14&"'!A2:E1000"), (INDIRECT("'"&F$14&"'!B2:B1000")=$B9) * (INDIRECT("'"&F$14&"'!C2:C1000")=$C9) ), 5, FALSE )=0, "", VLOOKUP( $A9, _xlfn._xlws.FILTER( INDIRECT("'"&F$14&"'!A2:E1000"), (INDIRECT("'"&F$14&"'!B2:B1000")=$B9) * (INDIRECT("'"&F$14&"'!C2:C1000")=$C9) ), 5, FALSE ) )} | G9: {=IF( VLOOKUP( $A9, _xlfn._xlws.FILTER( INDIRECT("'"&G$14&"'!A2:E1000"), (INDIRECT("'"&G$14&"'!B2:B1000")=$B9) * (INDIRECT("'"&G$14&"'!C2:C1000")=$C9) ), 5, FALSE )=0, "", VLOOKUP( $A9, _xlfn._xlws.FILTER( INDIRECT("'"&G$14&"'!A2:E1000"), (INDIRECT("'"&G$14&"'!B2:B1000")=$B9) * (INDIRECT("'"&G$14&"'!C2:C1000")=$C9) ), 5, FALSE ) )} | H9: {=IF( VLOOKUP( $A9, _xlfn._xlws.FILTER( INDIRECT("'"&H$14&"'!A2:E1000"), (INDIRECT("'"&H$14&"'!B2:B1000")=$B9) * (INDIRECT("'"&H$14&"'!C2:C1000")=$C9) ), 5, FALSE )=0, "", VLOOKUP( $A9, _xlfn._xlws.FILTER( INDIRECT("'"&H$14&"'!A2:E1000"), (INDIRECT("'"&H$14&"'!B2:B1000")=$B9) * (INDIRECT("'"&H$14&"'!C2:C1000")=$C9) ), 5, FALSE ) )} | I9: {=IF( VLOOKUP( $A9, _xlfn._xlws.FILTER( INDIRECT("'"&I$14&"'!A2:E1000"), (INDIRECT("'"&I$14&"'!B2:B1000")=$B9) * (INDIRECT("'"&I$14&"'!C2:C1000")=$C9) ), 5, FALSE )=0, "", VLOOKUP( $A9, _xlfn._xlws.FILTER( INDIRECT("'"&I$14&"'!A2:E1000"), (INDIRECT("'"&I$14&"'!B2:B1000")=$B9) * (INDIRECT("'"&I$14&"'!C2:C1000")=$C9) ), 5, FALSE ) )} | J9: {=IF( VLOOKUP( $A9, _xlfn._xlws.FILTER( INDIRECT("'"&J$14&"'!A2:E1000"), (INDIRECT("'"&J$14&"'!B2:B1000")=$B9) * (INDIRECT("'"&J$14&"'!C2:C1000")=$C9) ), 5, FALSE )=0, "", VLOOKUP( $A9, _xlfn._xlws.FILTER( INDIRECT("'"&J$14&"'!A2:E1000"), (INDIRECT("'"&J$14&"'!B2:B1000")=$B9) * (INDIRECT("'"&J$14&"'!C2:C1000")=$C9) ), 5, FALSE ) )} | K9: {=IF( VLOOKUP( $A9, _xlfn._xlws.FILTER( INDIRECT("'"&K$14&"'!A2:E1000"), (INDIRECT("'"&K$14&"'!B2:B1000")=$B9) * (INDIRECT("'"&K$14&"'!C2:C1000")=$C9) ), 5, FALSE )=0, "", VLOOKUP( $A9, _xlfn._xlws.FILTER( INDIRECT("'"&K$14&"'!A2:E1000"), (INDIRECT("'"&K$14&"'!B2:B1000")=$B9) * (INDIRECT("'"&K$14&"'!C2:C1000")=$C9) ), 5, FALSE ) )} | ... Q9: {=IF( VLOOKUP( $A9, _xlfn._xlws.FILTER( INDIRECT("'"&Q$14&"'!A2:E1000"), (INDIRECT("'"&Q$14&"'!B2:B1000")=$B9) * (INDIRECT("'"&Q$14&"'!C2:C1000")=$C9) ), 5, FALSE )=0, "", VLOOKUP( $A9, _xlfn._xlws.FILTER( INDIRECT("'"&Q$14&"'!A2:E1000"), (INDIRECT("'"&Q$14&"'!B2:B1000")=$B9) * (INDIRECT("'"&Q$14&"'!C2:C1000")=$C9) ), 5, FALSE ) )}
A10: Bianca | B10: Ibema | C10: 1 | D10: {=IF( VLOOKUP( $A10, _xlfn._xlws.FILTER( INDIRECT("'"&D$14&"'!A2:E1000"), (INDIRECT("'"&D$14&"'!B2:B1000")=$B10) * (INDIRECT("'"&D$14&"'!C2:C1000")=$C10) ), 5, FALSE )=0, "", VLOOKUP( $A10, _xlfn._xlws.FILTER( INDIRECT("'"&D$14&"'!A2:E1000"), (INDIRECT("'"&D$14&"'!B2:B1000")=$B10) * (INDIRECT("'"&D$14&"'!C2:C1000")=$C10) ), 5, FALSE ) )} | E10: {=IF( VLOOKUP( $A10, _xlfn._xlws.FILTER( INDIRECT("'"&E$14&"'!A2:E1000"), (INDIRECT("'"&E$14&"'!B2:B1000")=$B10) * (INDIRECT("'"&E$14&"'!C2:C1000")=$C10) ), 5, FALSE )=0, "", VLOOKUP( $A10, _xlfn._xlws.FILTER( INDIRECT("'"&E$14&"'!A2:E1000"), (INDIRECT("'"&E$14&"'!B2:B1000")=$B10) * (INDIRECT("'"&E$14&"'!C2:C1000")=$C10) ), 5, FALSE ) )} | F10: {=IF( VLOOKUP( $A10, _xlfn._xlws.FILTER( INDIRECT("'"&F$14&"'!A2:E1000"), (INDIRECT("'"&F$14&"'!B2:B1000")=$B10) * (INDIRECT("'"&F$14&"'!C2:C1000")=$C10) ), 5, FALSE )=0, "", VLOOKUP( $A10, _xlfn._xlws.FILTER( INDIRECT("'"&F$14&"'!A2:E1000"), (INDIRECT("'"&F$14&"'!B2:B1000")=$B10) * (INDIRECT("'"&F$14&"'!C2:C1000")=$C10) ), 5, FALSE ) )} | G10: {=IF( VLOOKUP( $A10, _xlfn._xlws.FILTER( INDIRECT("'"&G$14&"'!A2:E1000"), (INDIRECT("'"&G$14&"'!B2:B1000")=$B10) * (INDIRECT("'"&G$14&"'!C2:C1000")=$C10) ), 5, FALSE )=0, "", VLOOKUP( $A10, _xlfn._xlws.FILTER( INDIRECT("'"&G$14&"'!A2:E1000"), (INDIRECT("'"&G$14&"'!B2:B1000")=$B10) * (INDIRECT("'"&G$14&"'!C2:C1000")=$C10) ), 5, FALSE ) )} | H10: {=IF( VLOOKUP( $A10, _xlfn._xlws.FILTER( INDIRECT("'"&H$14&"'!A2:E1000"), (INDIRECT("'"&H$14&"'!B2:B1000")=$B10) * (INDIRECT("'"&H$14&"'!C2:C1000")=$C10) ), 5, FALSE )=0, "", VLOOKUP( $A10, _xlfn._xlws.FILTER( INDIRECT("'"&H$14&"'!A2:E1000"), (INDIRECT("'"&H$14&"'!B2:B1000")=$B10) * (INDIRECT("'"&H$14&"'!C2:C1000")=$C10) ), 5, FALSE ) )} | I10: {=IF( VLOOKUP( $A10, _xlfn._xlws.FILTER( INDIRECT("'"&I$14&"'!A2:E1000"), (INDIRECT("'"&I$14&"'!B2:B1000")=$B10) * (INDIRECT("'"&I$14&"'!C2:C1000")=$C10) ), 5, FALSE )=0, "", VLOOKUP( $A10, _xlfn._xlws.FILTER( INDIRECT("'"&I$14&"'!A2:E1000"), (INDIRECT("'"&I$14&"'!B2:B1000")=$B10) * (INDIRECT("'"&I$14&"'!C2:C1000")=$C10) ), 5, FALSE ) )} | J10: {=IF( VLOOKUP( $A10, _xlfn._xlws.FILTER( INDIRECT("'"&J$14&"'!A2:E1000"), (INDIRECT("'"&J$14&"'!B2:B1000")=$B10) * (INDIRECT("'"&J$14&"'!C2:C1000")=$C10) ), 5, FALSE )=0, "", VLOOKUP( $A10, _xlfn._xlws.FILTER( INDIRECT("'"&J$14&"'!A2:E1000"), (INDIRECT("'"&J$14&"'!B2:B1000")=$B10) * (INDIRECT("'"&J$14&"'!C2:C1000")=$C10) ), 5, FALSE ) )} | K10: {=IF( VLOOKUP( $A10, _xlfn._xlws.FILTER( INDIRECT("'"&K$14&"'!A2:E1000"), (INDIRECT("'"&K$14&"'!B2:B1000")=$B10) * (INDIRECT("'"&K$14&"'!C2:C1000")=$C10) ), 5, FALSE )=0, "", VLOOKUP( $A10, _xlfn._xlws.FILTER( INDIRECT("'"&K$14&"'!A2:E1000"), (INDIRECT("'"&K$14&"'!B2:B1000")=$B10) * (INDIRECT("'"&K$14&"'!C2:C1000")=$C10) ), 5, FALSE ) )} | ... Q10: {=IF( VLOOKUP( $A10, _xlfn._xlws.FILTER( INDIRECT("'"&Q$14&"'!A2:E1000"), (INDIRECT("'"&Q$14&"'!B2:B1000")=$B10) * (INDIRECT("'"&Q$14&"'!C2:C1000")=$C10) ), 5, FALSE )=0, "", VLOOKUP( $A10, _xlfn._xlws.FILTER( INDIRECT("'"&Q$14&"'!A2:E1000"), (INDIRECT("'"&Q$14&"'!B2:B1000")=$B10) * (INDIRECT("'"&Q$14&"'!C2:C1000")=$C10) ), 5, FALSE ) )}
A11: Bianca | B11: Iguatu | C11: 1 | D11: {=IF( VLOOKUP( $A11, _xlfn._xlws.FILTER( INDIRECT("'"&D$14&"'!A2:E1000"), (INDIRECT("'"&D$14&"'!B2:B1000")=$B11) * (INDIRECT("'"&D$14&"'!C2:C1000")=$C11) ), 5, FALSE )=0, "", VLOOKUP( $A11, _xlfn._xlws.FILTER( INDIRECT("'"&D$14&"'!A2:E1000"), (INDIRECT("'"&D$14&"'!B2:B1000")=$B11) * (INDIRECT("'"&D$14&"'!C2:C1000")=$C11) ), 5, FALSE ) )} | E11: {=IF( VLOOKUP( $A11, _xlfn._xlws.FILTER( INDIRECT("'"&E$14&"'!A2:E1000"), (INDIRECT("'"&E$14&"'!B2:B1000")=$B11) * (INDIRECT("'"&E$14&"'!C2:C1000")=$C11) ), 5, FALSE )=0, "", VLOOKUP( $A11, _xlfn._xlws.FILTER( INDIRECT("'"&E$14&"'!A2:E1000"), (INDIRECT("'"&E$14&"'!B2:B1000")=$B11) * (INDIRECT("'"&E$14&"'!C2:C1000")=$C11) ), 5, FALSE ) )} | F11: {=IF( VLOOKUP( $A11, _xlfn._xlws.FILTER( INDIRECT("'"&F$14&"'!A2:E1000"), (INDIRECT("'"&F$14&"'!B2:B1000")=$B11) * (INDIRECT("'"&F$14&"'!C2:C1000")=$C11) ), 5, FALSE )=0, "", VLOOKUP( $A11, _xlfn._xlws.FILTER( INDIRECT("'"&F$14&"'!A2:E1000"), (INDIRECT("'"&F$14&"'!B2:B1000")=$B11) * (INDIRECT("'"&F$14&"'!C2:C1000")=$C11) ), 5, FALSE ) )} | G11: {=IF( VLOOKUP( $A11, _xlfn._xlws.FILTER( INDIRECT("'"&G$14&"'!A2:E1000"), (INDIRECT("'"&G$14&"'!B2:B1000")=$B11) * (INDIRECT("'"&G$14&"'!C2:C1000")=$C11) ), 5, FALSE )=0, "", VLOOKUP( $A11, _xlfn._xlws.FILTER( INDIRECT("'"&G$14&"'!A2:E1000"), (INDIRECT("'"&G$14&"'!B2:B1000")=$B11) * (INDIRECT("'"&G$14&"'!C2:C1000")=$C11) ), 5, FALSE ) )} | H11: {=IF( VLOOKUP( $A11, _xlfn._xlws.FILTER( INDIRECT("'"&H$14&"'!A2:E1000"), (INDIRECT("'"&H$14&"'!B2:B1000")=$B11) * (INDIRECT("'"&H$14&"'!C2:C1000")=$C11) ), 5, FALSE )=0, "", VLOOKUP( $A11, _xlfn._xlws.FILTER( INDIRECT("'"&H$14&"'!A2:E1000"), (INDIRECT("'"&H$14&"'!B2:B1000")=$B11) * (INDIRECT("'"&H$14&"'!C2:C1000")=$C11) ), 5, FALSE ) )} | I11: {=IF( VLOOKUP( $A11, _xlfn._xlws.FILTER( INDIRECT("'"&I$14&"'!A2:E1000"), (INDIRECT("'"&I$14&"'!B2:B1000")=$B11) * (INDIRECT("'"&I$14&"'!C2:C1000")=$C11) ), 5, FALSE )=0, "", VLOOKUP( $A11, _xlfn._xlws.FILTER( INDIRECT("'"&I$14&"'!A2:E1000"), (INDIRECT("'"&I$14&"'!B2:B1000")=$B11) * (INDIRECT("'"&I$14&"'!C2:C1000")=$C11) ), 5, FALSE ) )} | J11: {=IF( VLOOKUP( $A11, _xlfn._xlws.FILTER( INDIRECT("'"&J$14&"'!A2:E1000"), (INDIRECT("'"&J$14&"'!B2:B1000")=$B11) * (INDIRECT("'"&J$14&"'!C2:C1000")=$C11) ), 5, FALSE )=0, "", VLOOKUP( $A11, _xlfn._xlws.FILTER( INDIRECT("'"&J$14&"'!A2:E1000"), (INDIRECT("'"&J$14&"'!B2:B1000")=$B11) * (INDIRECT("'"&J$14&"'!C2:C1000")=$C11) ), 5, FALSE ) )} | K11: {=IF( VLOOKUP( $A11, _xlfn._xlws.FILTER( INDIRECT("'"&K$14&"'!A2:E1000"), (INDIRECT("'"&K$14&"'!B2:B1000")=$B11) * (INDIRECT("'"&K$14&"'!C2:C1000")=$C11) ), 5, FALSE )=0, "", VLOOKUP( $A11, _xlfn._xlws.FILTER( INDIRECT("'"&K$14&"'!A2:E1000"), (INDIRECT("'"&K$14&"'!B2:B1000")=$B11) * (INDIRECT("'"&K$14&"'!C2:C1000")=$C11) ), 5, FALSE ) )} | ... Q11: {=IF( VLOOKUP( $A11, _xlfn._xlws.FILTER( INDIRECT("'"&Q$14&"'!A2:E1000"), (INDIRECT("'"&Q$14&"'!B2:B1000")=$B11) * (INDIRECT("'"&Q$14&"'!C2:C1000")=$C11) ), 5, FALSE )=0, "", VLOOKUP( $A11, _xlfn._xlws.FILTER( INDIRECT("'"&Q$14&"'!A2:E1000"), (INDIRECT("'"&Q$14&"'!B2:B1000")=$B11) * (INDIRECT("'"&Q$14&"'!C2:C1000")=$C11) ), 5, FALSE ) )}
A12: Bianca | B12: Tres Barras do Parana | C12: 1 | D12: {=IF( VLOOKUP( $A12, _xlfn._xlws.FILTER( INDIRECT("'"&D$14&"'!A2:E1000"), (INDIRECT("'"&D$14&"'!B2:B1000")=$B12) * (INDIRECT("'"&D$14&"'!C2:C1000")=$C12) ), 5, FALSE )=0, "", VLOOKUP( $A12, _xlfn._xlws.FILTER( INDIRECT("'"&D$14&"'!A2:E1000"), (INDIRECT("'"&D$14&"'!B2:B1000")=$B12) * (INDIRECT("'"&D$14&"'!C2:C1000")=$C12) ), 5, FALSE ) )} | E12: {=IF( VLOOKUP( $A12, _xlfn._xlws.FILTER( INDIRECT("'"&E$14&"'!A2:E1000"), (INDIRECT("'"&E$14&"'!B2:B1000")=$B12) * (INDIRECT("'"&E$14&"'!C2:C1000")=$C12) ), 5, FALSE )=0, "", VLOOKUP( $A12, _xlfn._xlws.FILTER( INDIRECT("'"&E$14&"'!A2:E1000"), (INDIRECT("'"&E$14&"'!B2:B1000")=$B12) * (INDIRECT("'"&E$14&"'!C2:C1000")=$C12) ), 5, FALSE ) )} | F12: {=IF( VLOOKUP( $A12, _xlfn._xlws.FILTER( INDIRECT("'"&F$14&"'!A2:E1000"), (INDIRECT("'"&F$14&"'!B2:B1000")=$B12) * (INDIRECT("'"&F$14&"'!C2:C1000")=$C12) ), 5, FALSE )=0, "", VLOOKUP( $A12, _xlfn._xlws.FILTER( INDIRECT("'"&F$14&"'!A2:E1000"), (INDIRECT("'"&F$14&"'!B2:B1000")=$B12) * (INDIRECT("'"&F$14&"'!C2:C1000")=$C12) ), 5, FALSE ) )} | G12: {=IF( VLOOKUP( $A12, _xlfn._xlws.FILTER( INDIRECT("'"&G$14&"'!A2:E1000"), (INDIRECT("'"&G$14&"'!B2:B1000")=$B12) * (INDIRECT("'"&G$14&"'!C2:C1000")=$C12) ), 5, FALSE )=0, "", VLOOKUP( $A12, _xlfn._xlws.FILTER( INDIRECT("'"&G$14&"'!A2:E1000"), (INDIRECT("'"&G$14&"'!B2:B1000")=$B12) * (INDIRECT("'"&G$14&"'!C2:C1000")=$C12) ), 5, FALSE ) )} | H12: {=IF( VLOOKUP( $A12, _xlfn._xlws.FILTER( INDIRECT("'"&H$14&"'!A2:E1000"), (INDIRECT("'"&H$14&"'!B2:B1000")=$B12) * (INDIRECT("'"&H$14&"'!C2:C1000")=$C12) ), 5, FALSE )=0, "", VLOOKUP( $A12, _xlfn._xlws.FILTER( INDIRECT("'"&H$14&"'!A2:E1000"), (INDIRECT("'"&H$14&"'!B2:B1000")=$B12) * (INDIRECT("'"&H$14&"'!C2:C1000")=$C12) ), 5, FALSE ) )} | I12: {=IF( VLOOKUP( $A12, _xlfn._xlws.FILTER( INDIRECT("'"&I$14&"'!A2:E1000"), (INDIRECT("'"&I$14&"'!B2:B1000")=$B12) * (INDIRECT("'"&I$14&"'!C2:C1000")=$C12) ), 5, FALSE )=0, "", VLOOKUP( $A12, _xlfn._xlws.FILTER( INDIRECT("'"&I$14&"'!A2:E1000"), (INDIRECT("'"&I$14&"'!B2:B1000")=$B12) * (INDIRECT("'"&I$14&"'!C2:C1000")=$C12) ), 5, FALSE ) )} | J12: {=IF( VLOOKUP( $A12, _xlfn._xlws.FILTER( INDIRECT("'"&J$14&"'!A2:E1000"), (INDIRECT("'"&J$14&"'!B2:B1000")=$B12) * (INDIRECT("'"&J$14&"'!C2:C1000")=$C12) ), 5, FALSE )=0, "", VLOOKUP( $A12, _xlfn._xlws.FILTER( INDIRECT("'"&J$14&"'!A2:E1000"), (INDIRECT("'"&J$14&"'!B2:B1000")=$B12) * (INDIRECT("'"&J$14&"'!C2:C1000")=$C12) ), 5, FALSE ) )} | K12: {=IF( VLOOKUP( $A12, _xlfn._xlws.FILTER( INDIRECT("'"&K$14&"'!A2:E1000"), (INDIRECT("'"&K$14&"'!B2:B1000")=$B12) * (INDIRECT("'"&K$14&"'!C2:C1000")=$C12) ), 5, FALSE )=0, "", VLOOKUP( $A12, _xlfn._xlws.FILTER( INDIRECT("'"&K$14&"'!A2:E1000"), (INDIRECT("'"&K$14&"'!B2:B1000")=$B12) * (INDIRECT("'"&K$14&"'!C2:C1000")=$C12) ), 5, FALSE ) )} | ... Q12: {=IF( VLOOKUP( $A12, _xlfn._xlws.FILTER( INDIRECT("'"&Q$14&"'!A2:E1000"), (INDIRECT("'"&Q$14&"'!B2:B1000")=$B12) * (INDIRECT("'"&Q$14&"'!C2:C1000")=$C12) ), 5, FALSE )=0, "", VLOOKUP( $A12, _xlfn._xlws.FILTER( INDIRECT("'"&Q$14&"'!A2:E1000"), (INDIRECT("'"&Q$14&"'!B2:B1000")=$B12) * (INDIRECT("'"&Q$14&"'!C2:C1000")=$C12) ), 5, FALSE ) )}
A14: Regional | B14: Municípios | C14: UVR | D14: 11.24 | E14: 12.24 | F14: 01.25 | G14: 02.25 | H14: 03.25 | I14: 04.25 | J14: 05.25 | K14: 06.25 | L14: 07.25 | M14: 08.25 | N14: 09.25 | O14: 10.25 | P14: 11.25 | Q14: 12.25
A15: Gabriel | B15: Altônia | C15: 1 | D15: {=IF( VLOOKUP( $A15, _xlfn._xlws.FILTER( INDIRECT("'"&D$14&"'!A2:E1000"), (INDIRECT("'"&D$14&"'!B2:B1000")=$B15) * (INDIRECT("'"&D$14&"'!C2:C1000")=$C15) ), 5, FALSE )=0, "", VLOOKUP( $A15, _xlfn._xlws.FILTER( INDIRECT("'"&D$14&"'!A2:E1000"), (INDIRECT("'"&D$14&"'!B2:B1000")=$B15) * (INDIRECT("'"&D$14&"'!C2:C1000")=$C15) ), 5, FALSE ) )} | E15: {=IF( VLOOKUP( $A15, _xlfn._xlws.FILTER( INDIRECT("'"&E$14&"'!A2:E1000"), (INDIRECT("'"&E$14&"'!B2:B1000")=$B15) * (INDIRECT("'"&E$14&"'!C2:C1000")=$C15) ), 5, FALSE )=0, "", VLOOKUP( $A15, _xlfn._xlws.FILTER( INDIRECT("'"&E$14&"'!A2:E1000"), (INDIRECT("'"&E$14&"'!B2:B1000")=$B15) * (INDIRECT("'"&E$14&"'!C2:C1000")=$C15) ), 5, FALSE ) )} | F15: {=IF( VLOOKUP( $A15, _xlfn._xlws.FILTER( INDIRECT("'"&F$14&"'!A2:E1000"), (INDIRECT("'"&F$14&"'!B2:B1000")=$B15) * (INDIRECT("'"&F$14&"'!C2:C1000")=$C15) ), 5, FALSE )=0, "", VLOOKUP( $A15, _xlfn._xlws.FILTER( INDIRECT("'"&F$14&"'!A2:E1000"), (INDIRECT("'"&F$14&"'!B2:B1000")=$B15) * (INDIRECT("'"&F$14&"'!C2:C1000")=$C15) ), 5, FALSE ) )} | G15: {=IF( VLOOKUP( $A15, _xlfn._xlws.FILTER( INDIRECT("'"&G$14&"'!A2:E1000"), (INDIRECT("'"&G$14&"'!B2:B1000")=$B15) * (INDIRECT("'"&G$14&"'!C2:C1000")=$C15) ), 5, FALSE )=0, "", VLOOKUP( $A15, _xlfn._xlws.FILTER( INDIRECT("'"&G$14&"'!A2:E1000"), (INDIRECT("'"&G$14&"'!B2:B1000")=$B15) * (INDIRECT("'"&G$14&"'!C2:C1000")=$C15) ), 5, FALSE ) )} | H15: {=IF( VLOOKUP( $A15, _xlfn._xlws.FILTER( INDIRECT("'"&H$14&"'!A2:E1000"), (INDIRECT("'"&H$14&"'!B2:B1000")=$B15) * (INDIRECT("'"&H$14&"'!C2:C1000")=$C15) ), 5, FALSE )=0, "", VLOOKUP( $A15, _xlfn._xlws.FILTER( INDIRECT("'"&H$14&"'!A2:E1000"), (INDIRECT("'"&H$14&"'!B2:B1000")=$B15) * (INDIRECT("'"&H$14&"'!C2:C1000")=$C15) ), 5, FALSE ) )} | I15: {=IF( VLOOKUP( $A15, _xlfn._xlws.FILTER( INDIRECT("'"&I$14&"'!A2:E1000"), (INDIRECT("'"&I$14&"'!B2:B1000")=$B15) * (INDIRECT("'"&I$14&"'!C2:C1000")=$C15) ), 5, FALSE )=0, "", VLOOKUP( $A15, _xlfn._xlws.FILTER( INDIRECT("'"&I$14&"'!A2:E1000"), (INDIRECT("'"&I$14&"'!B2:B1000")=$B15) * (INDIRECT("'"&I$14&"'!C2:C1000")=$C15) ), 5, FALSE ) )} | J15: {=IF( VLOOKUP( $A15, _xlfn._xlws.FILTER( INDIRECT("'"&J$14&"'!A2:E1000"), (INDIRECT("'"&J$14&"'!B2:B1000")=$B15) * (INDIRECT("'"&J$14&"'!C2:C1000")=$C15) ), 5, FALSE )=0, "", VLOOKUP( $A15, _xlfn._xlws.FILTER( INDIRECT("'"&J$14&"'!A2:E1000"), (INDIRECT("'"&J$14&"'!B2:B1000")=$B15) * (INDIRECT("'"&J$14&"'!C2:C1000")=$C15) ), 5, FALSE ) )} | K15: {=IF( VLOOKUP( $A15, _xlfn._xlws.FILTER( INDIRECT("'"&K$14&"'!A2:E1000"), (INDIRECT("'"&K$14&"'!B2:B1000")=$B15) * (INDIRECT("'"&K$14&"'!C2:C1000")=$C15) ), 5, FALSE )=0, "", VLOOKUP( $A15, _xlfn._xlws.FILTER( INDIRECT("'"&K$14&"'!A2:E1000"), (INDIRECT("'"&K$14&"'!B2:B1000")=$B15) * (INDIRECT("'"&K$14&"'!C2:C1000")=$C15) ), 5, FALSE ) )} | ... Q15: {=IF( VLOOKUP( $A15, _xlfn._xlws.FILTER( INDIRECT("'"&Q$14&"'!A2:E1000"), (INDIRECT("'"&Q$14&"'!B2:B1000")=$B15) * (INDIRECT("'"&Q$14&"'!C2:C1000")=$C15) ), 5, FALSE )=0, "", VLOOKUP( $A15, _xlfn._xlws.FILTER( INDIRECT("'"&Q$14&"'!A2:E1000"), (INDIRECT("'"&Q$14&"'!B2:B1000")=$B15) * (INDIRECT("'"&Q$14&"'!C2:C1000")=$C15) ), 5, FALSE ) )}
A16: Gabriel | B16: Francisco Alves | C16: 1 | D16: {=IF( VLOOKUP( $A16, _xlfn._xlws.FILTER( INDIRECT("'"&D$14&"'!A2:E1000"), (INDIRECT("'"&D$14&"'!B2:B1000")=$B16) * (INDIRECT("'"&D$14&"'!C2:C1000")=$C16) ), 5, FALSE )=0, "", VLOOKUP( $A16, _xlfn._xlws.FILTER( INDIRECT("'"&D$14&"'!A2:E1000"), (INDIRECT("'"&D$14&"'!B2:B1000")=$B16) * (INDIRECT("'"&D$14&"'!C2:C1000")=$C16) ), 5, FALSE ) )} | E16: {=IF( VLOOKUP( $A16, _xlfn._xlws.FILTER( INDIRECT("'"&E$14&"'!A2:E1000"), (INDIRECT("'"&E$14&"'!B2:B1000")=$B16) * (INDIRECT("'"&E$14&"'!C2:C1000")=$C16) ), 5, FALSE )=0, "", VLOOKUP( $A16, _xlfn._xlws.FILTER( INDIRECT("'"&E$14&"'!A2:E1000"), (INDIRECT("'"&E$14&"'!B2:B1000")=$B16) * (INDIRECT("'"&E$14&"'!C2:C1000")=$C16) ), 5, FALSE ) )} | F16: {=IF( VLOOKUP( $A16, _xlfn._xlws.FILTER( INDIRECT("'"&F$14&"'!A2:E1000"), (INDIRECT("'"&F$14&"'!B2:B1000")=$B16) * (INDIRECT("'"&F$14&"'!C2:C1000")=$C16) ), 5, FALSE )=0, "", VLOOKUP( $A16, _xlfn._xlws.FILTER( INDIRECT("'"&F$14&"'!A2:E1000"), (INDIRECT("'"&F$14&"'!B2:B1000")=$B16) * (INDIRECT("'"&F$14&"'!C2:C1000")=$C16) ), 5, FALSE ) )} | G16: {=IF( VLOOKUP( $A16, _xlfn._xlws.FILTER( INDIRECT("'"&G$14&"'!A2:E1000"), (INDIRECT("'"&G$14&"'!B2:B1000")=$B16) * (INDIRECT("'"&G$14&"'!C2:C1000")=$C16) ), 5, FALSE )=0, "", VLOOKUP( $A16, _xlfn._xlws.FILTER( INDIRECT("'"&G$14&"'!A2:E1000"), (INDIRECT("'"&G$14&"'!B2:B1000")=$B16) * (INDIRECT("'"&G$14&"'!C2:C1000")=$C16) ), 5, FALSE ) )} | H16: {=IF( VLOOKUP( $A16, _xlfn._xlws.FILTER( INDIRECT("'"&H$14&"'!A2:E1000"), (INDIRECT("'"&H$14&"'!B2:B1000")=$B16) * (INDIRECT("'"&H$14&"'!C2:C1000")=$C16) ), 5, FALSE )=0, "", VLOOKUP( $A16, _xlfn._xlws.FILTER( INDIRECT("'"&H$14&"'!A2:E1000"), (INDIRECT("'"&H$14&"'!B2:B1000")=$B16) * (INDIRECT("'"&H$14&"'!C2:C1000")=$C16) ), 5, FALSE ) )} | I16: {=IF( VLOOKUP( $A16, _xlfn._xlws.FILTER( INDIRECT("'"&I$14&"'!A2:E1000"), (INDIRECT("'"&I$14&"'!B2:B1000")=$B16) * (INDIRECT("'"&I$14&"'!C2:C1000")=$C16) ), 5, FALSE )=0, "", VLOOKUP( $A16, _xlfn._xlws.FILTER( INDIRECT("'"&I$14&"'!A2:E1000"), (INDIRECT("'"&I$14&"'!B2:B1000")=$B16) * (INDIRECT("'"&I$14&"'!C2:C1000")=$C16) ), 5, FALSE ) )} | J16: {=IF( VLOOKUP( $A16, _xlfn._xlws.FILTER( INDIRECT("'"&J$14&"'!A2:E1000"), (INDIRECT("'"&J$14&"'!B2:B1000")=$B16) * (INDIRECT("'"&J$14&"'!C2:C1000")=$C16) ), 5, FALSE )=0, "", VLOOKUP( $A16, _xlfn._xlws.FILTER( INDIRECT("'"&J$14&"'!A2:E1000"), (INDIRECT("'"&J$14&"'!B2:B1000")=$B16) * (INDIRECT("'"&J$14&"'!C2:C1000")=$C16) ), 5, FALSE ) )} | K16: {=IF( VLOOKUP( $A16, _xlfn._xlws.FILTER( INDIRECT("'"&K$14&"'!A2:E1000"), (INDIRECT("'"&K$14&"'!B2:B1000")=$B16) * (INDIRECT("'"&K$14&"'!C2:C1000")=$C16) ), 5, FALSE )=0, "", VLOOKUP( $A16, _xlfn._xlws.FILTER( INDIRECT("'"&K$14&"'!A2:E1000"), (INDIRECT("'"&K$14&"'!B2:B1000")=$B16) * (INDIRECT("'"&K$14&"'!C2:C1000")=$C16) ), 5, FALSE ) )} | ... Q16: {=IF( VLOOKUP( $A16, _xlfn._xlws.FILTER( INDIRECT("'"&Q$14&"'!A2:E1000"), (INDIRECT("'"&Q$14&"'!B2:B1000")=$B16) * (INDIRECT("'"&Q$14&"'!C2:C1000")=$C16) ), 5, FALSE )=0, "", VLOOKUP( $A16, _xlfn._xlws.FILTER( INDIRECT("'"&Q$14&"'!A2:E1000"), (INDIRECT("'"&Q$14&"'!B2:B1000")=$B16) * (INDIRECT("'"&Q$14&"'!C2:C1000")=$C16) ), 5, FALSE ) )}
