Workbook

Sheet Resumo
A1: Categoria | B1: 11.24 | C1: 12.24 | D1: 01.25 | E1: 02.25 | F1: 03.25 | G1: 04.25 | H1: 05.25 | I1: 06.25 | J1: 07.25 | K1: 08.25 | L1: 09.25 | M1: 10.25 | N1: 11.25 | O1: 12.25 | P1: Total
A2: Enviado | B2: =COUNTIF(INDIRECT(B$1&"!E2:E1000"),$A2) -> 59 | C2: =COUNTIF(INDIRECT(C$1&"!E2:E1000"),$A2) -> 61 | D2: =COUNTIF(INDIRECT(D$1&"!E2:E1000"),$A2) -> 63 | E2: =COUNTIF(INDIRECT(E$1&"!E2:E1000"),$A2) -> 64 | F2: =COUNTIF(INDIRECT(F$1&"!E2:E1000"),$A2) -> 67 | G2: =COUNTIF(INDIRECT(G$1&"!E2:E1000"),$A2) -> 67 | H2: =COUNTIF(INDIRECT(H$1&"!E2:E1000"),$A2) -> 67 | I2: =COUNTIF(INDIRECT(I$1&"!E2:E1000"),$A2) -> 68 | ... O2: =COUNTIF(INDIRECT(O$1&"!E2:E1000"),$A2) -> 1 | P2: =SUM(B2:O2) -> 846
A3: Atrasado | B3: =COUNTIF(INDIRECT("11.24!E2:E1000"),$A3) -> 0 | C3: =COUNTIF(INDIRECT(C$1&"!E2:E1000"),$A3) -> 0 | D3: =COUNTIF(INDIRECT(D$1&"!E2:E1000"),$A3) -> 0 | E3: =COUNTIF(INDIRECT(E$1&"!E2:E1000"),$A3) -> 0 | F3: =COUNTIF(INDIRECT(F$1&"!E2:E1000"),$A3) -> 0 | G3: =COUNTIF(INDIRECT(G$1&"!E2:E1000"),$A3) -> 0 | H3: =COUNTIF(INDIRECT(H$1&"!E2:E1000"),$A3) -> 0 | I3: =COUNTIF(INDIRECT(I$1&"!E2:E1000"),$A3) -> 0 | J3: =COUNTIF(INDIRECT(J$1&"!E2:E1000"),$A3) -> 0 | ... O3: =COUNTIF(INDIRECT(O$1&"!E2:E1000"),$A3) -> 0 | P3: =SUM(B3:O3) -> 10
A4: Atrasado >= 2 | B4: =COUNTIF(INDIRECT("11.24!E2:E1000"),$A4) -> 1 | C4: =COUNTIF(INDIRECT(C$1&"!E2:E1000"),$A4) -> 2 | D4: =COUNTIF(INDIRECT(D$1&"!E2:E1000"),$A4) -> 2 | E4: =COUNTIF(INDIRECT(E$1&"!E2:E1000"),$A4) -> 2 | F4: =COUNTIF(INDIRECT(F$1&"!E2:E1000"),$A4) -> 0 | G4: =COUNTIF(INDIRECT(G$1&"!E2:E1000"),$A4) -> 0 | H4: =COUNTIF(INDIRECT(H$1&"!E2:E1000"),$A4) -> 1 | I4: =COUNTIF(INDIRECT(I$1&"!E2:E1000"),$A4) -> 0 | J4: =COUNTIF(INDIRECT(J$1&"!E2:E1000"),$A4) -> 0 | ... O4: =COUNTIF(INDIRECT(O$1&"!E2:E1000"),$A4) -> 0 | P4: =SUM(B4:O4) -> 11
A5: Duplicado | B5: =COUNTIF(INDIRECT("11.24!E2:E1000"),$A5) -> 7 | C5: =COUNTIF(INDIRECT(C$1&"!E2:E1000"),$A5) -> 4 | D5: =COUNTIF(INDIRECT(D$1&"!E2:E1000"),$A5) -> 2 | E5: =COUNTIF(INDIRECT(E$1&"!E2:E1000"),$A5) -> 1 | F5: =COUNTIF(INDIRECT(F$1&"!E2:E1000"),$A5) -> 0 | G5: =COUNTIF(INDIRECT(G$1&"!E2:E1000"),$A5) -> 0 | H5: =COUNTIF(INDIRECT(H$1&"!E2:E1000"),$A5) -> 0 | I5: =COUNTIF(INDIRECT(I$1&"!E2:E1000"),$A5) -> 0 | J5: =COUNTIF(INDIRECT(J$1&"!E2:E1000"),$A5) -> 1 | ... O5: =COUNTIF(INDIRECT(O$1&"!E2:E1000"),$A5) -> 0 | P5: =SUM(B5:O5) -> 16
A6: Outras Ocorrências | B6: =COUNTIF(INDIRECT("11.24!E2:E1000"),$A6) -> 0 | C6: =COUNTIF(INDIRECT(C$1&"!E2:E1000"),$A6) -> 0 | D6: =COUNTIF(INDIRECT(D$1&"!E2:E1000"),$A6) -> 0 | E6: =COUNTIF(INDIRECT(E$1&"!E2:E1000"),$A6) -> 0 | F6: =COUNTIF(INDIRECT(F$1&"!E2:E1000"),$A6) -> 0 | G6: =COUNTIF(INDIRECT(G$1&"!E2:E1000"),$A6) -> 0 | H6: =COUNTIF(INDIRECT(H$1&"!E2:E1000"),$A6) -> 0 | I6: =COUNTIF(INDIRECT(I$1&"!E2:E1000"),$A6) -> 0 | J6: =COUNTIF(INDIRECT(J$1&"!E2:E1000"),$A6) -> 0 | ... O6: =COUNTIF(INDIRECT(O$1&"!E2:E1000"),$A6) -> 0 | P6: =SUM(B6:O6) -> 0
A7: Sem Técnico | B7: =COUNTIF(INDIRECT("11.24!E2:E1000"),$A7) -> 2 | C7: =COUNTIF(INDIRECT(C$1&"!E2:E1000"),$A7) -> 2 | D7: =COUNTIF(INDIRECT(D$1&"!E2:E1000"),$A7) -> 2 | E7: =COUNTIF(INDIRECT(E$1&"!E2:E1000"),$A7) -> 2 | F7: =COUNTIF(INDIRECT(F$1&"!E2:E1000"),$A7) -> 2 | G7: =COUNTIF(INDIRECT(G$1&"!E2:E1000"),$A7) -> 2 | H7: =COUNTIF(INDIRECT(H$1&"!E2:E1000"),$A7) -> 1 | I7: =COUNTIF(INDIRECT(I$1&"!E2:E1000"),$A7) -> 1 | J7: =COUNTIF(INDIRECT(J$1&"!E2:E1000"),$A7) -> 1 | ... O7: =COUNTIF(INDIRECT(O$1&"!E2:E1000"),$A7) -> 0 | P7: =SUM(B7:O7) -> 15
A8: Total | B8: =SUM(B2:B7) -> 69 | C8: =SUM(C2:C7) -> 69 | D8: =SUM(D2:D7) -> 69 | E8: =SUM(E2:E7) -> 69 | F8: =SUM(F2:F7) -> 69 | G8: =SUM(G2:G7) -> 69 | H8: =SUM(H2:H7) -> 69 | I8: =SUM(I2:I7) -> 69 | ... O8: =SUM(O2:O7) -> 1 | P8: =SUM(B8:O8) -> 898
A11: Digite o Mês de Referência | C11: Mês de Referência | K11: Acumulado (Total) | R11: Resumo por Regional
A12: 11.25 | C12: Monitoramento (Envios) | K12: Monitoramento (Envios) | R12: Regional | T12: Bianca
C13: Regional | D13: Envi. | E13: Atra. | F13: Atra. >= 2 | G13: Dup. | H13: Out. Ocor. | I13: Sem Tec. | K13: Envi. | L13: Atra. | M13: Atra. >= 2 | N13: Dup. | O13: Out. Ocor. | P13: Sem Tec. | R13: =_xlfn.CONCAT("Envios - Mês de Referência - ", A12) -> Envios - Mês de Referência - 11.25
C14: Bianca | D14: {=IFERROR(ROWS(_xlfn._xlws.FILTER(INDIRECT($A$12&"!A2:E100"),(INDIRECT($A$12&"!A2:A100")=$C14)*(INDIRECT($A$12&"!E2:E100")="Enviado"))), 0)} -> 10 | E14: {=IFERROR(ROWS(_xlfn._xlws.FILTER(INDIRECT($A$12&"!A2:E100"),(INDIRECT($A$12&"!A2:A100")=$C14)*(INDIRECT($A$12&"!E2:E100")="Atrasado"))), 0)} -> 1 | F14: {=IFERROR(ROWS(_xlfn._xlws.FILTER(INDIRECT($A$12&"!A2:E100"),(INDIRECT($A$12&"!A2:A100")=$C14)*(INDIRECT($A$12&"!E2:E100")="Atrasado >= 2"))), 0)} -> 0 | G14: {=IFERROR(ROWS(_xlfn._xlws.FILTER(INDIRECT($A$12&"!A2:E100"),(INDIRECT($A$12&"!A2:A100")=$C14)*(INDIRECT($A$12&"!E2:E100")="Duplicado"))), 0)} -> 0 | H14: {=IFERROR(ROWS(_xlfn._xlws.FILTER(INDIRECT($A$12&"!A2:E100"),(INDIRECT($A$12&"!A2:A100")=$C14)*(INDIRECT($A$12&"!E2:E100")="Outras Ocorrências"))), 0)} -> 0 | I14: {=IFERROR(ROWS(_xlfn._xlws.FILTER(INDIRECT($A$12&"!A2:E100"),(INDIRECT($A$12&"!A2:A100")=$C14)*(INDIRECT($A$12&"!E2:E100")="Sem Técnico"))), 0)} -> 0 | K14: =COUNTIF(INDIRECT("Monitoramento!$D$2:$Q$12"), "Enviado") -> 142 | L14: =COUNTIF(INDIRECT("Monitoramento!$D$2:$Q$12"), "Atrasado") -> 1 | M14: =COUNTIF(INDIRECT("Monitoramento!$D$2:$Q$12"), "Atrasado >= 2") -> 0 | N14: =COUNTIF(INDIRECT("Monitoramento!$D$2:$Q$12"), "Duplicado") -> 0 | O14: =COUNTIF(INDIRECT("Monitoramento!$D$2:$Q$12"), "Outras Ocorrências") -> 0 | P14: =COUNTIF(INDIRECT("Monitoramento!$D$2:$Q$12"), "Sem Técnico") -> 0 | R14: Enviados | S14: =VLOOKUP($T$12,$C$14:$I$19,2, FALSE) -> 10 | T14: =S14/SUM($S$14:$S$19) -> 0.90909091
C15: Gabriel | D15: {=IFERROR(ROWS(_xlfn._xlws.FILTER(INDIRECT($A$12&"!A2:E100"),(INDIRECT($A$12&"!A2:A100")=$C15)*(INDIRECT($A$12&"!E2:E100")="Enviado"))), 0)} -> 10 | E15: {=IFERROR(ROWS(_xlfn._xlws.FILTER(INDIRECT($A$12&"!A2:E100"),(INDIRECT($A$12&"!A2:A100")=$C15)*(INDIRECT($A$12&"!E2:E100")="Atrasado"))), 0)} -> 1 | F15: {=IFERROR(ROWS(_xlfn._xlws.FILTER(INDIRECT($A$12&"!A2:E100"),(INDIRECT($A$12&"!A2:A100")=$C15)*(INDIRECT($A$12&"!E2:E100")="Atrasado >= 2"))), 0)} -> 0 | G15: {=IFERROR(ROWS(_xlfn._xlws.FILTER(INDIRECT($A$12&"!A2:E100"),(INDIRECT($A$12&"!A2:A100")=$C15)*(INDIRECT($A$12&"!E2:E100")="Duplicado"))), 0)} -> 0 | H15: {=IFERROR(ROWS(_xlfn._xlws.FILTER(INDIRECT($A$12&"!A2:E100"),(INDIRECT($A$12&"!A2:A100")=$C15)*(INDIRECT($A$12&"!E2:E100")="Outras Ocorrências"))), 0)} -> 0 | I15: {=IFERROR(ROWS(_xlfn._xlws.FILTER(INDIRECT($A$12&"!A2:E100"),(INDIRECT($A$12&"!A2:A100")=$C15)*(INDIRECT($A$12&"!E2:E100")="Sem Técnico"))), 0)} -> 0 | K15: =COUNTIF(INDIRECT("Monitoramento!$D$15:$Q$25"), "Enviado") -> 141 | L15: =COUNTIF(INDIRECT("Monitoramento!$D$15:$Q$25"), "Atrasado") -> 1 | M15: =COUNTIF(INDIRECT("Monitoramento!$D$15:$Q$25"), "Atrasado >= 2") -> 1 | N15: =COUNTIF(INDIRECT("Monitoramento!$D$15:$Q$25"), "Duplicado") -> 0 | O15: =COUNTIF(INDIRECT("Monitoramento!$D$15:$Q$25"), "Outras Ocorrências") -> 0 | P15: =COUNTIF(INDIRECT("Monitoramento!$D$15:$Q$25"), "Sem Técnico") -> 0 | R15: Atrasados | S15: =VLOOKUP($T$12,$C$14:$I$19,3,FALSE) -> 1 | T15: =S15/SUM($S$14:$S$19) -> 0.090909091
C16: Gustavo | D16: {=IFERROR(ROWS(_xlfn._xlws.FILTER(INDIRECT($A$12&"!A2:E100"),(INDIRECT($A$12&"!A2:A100")=$C16)*(INDIRECT($A$12&"!E2:E100")="Enviado"))), 0)} -> 10 | E16: {=IFERROR(ROWS(_xlfn._xlws.FILTER(INDIRECT($A$12&"!A2:E100"),(INDIRECT($A$12&"!A2:A100")=$C16)*(INDIRECT($A$12&"!E2:E100")="Atrasado"))), 0)} -> 1 | F16: {=IFERROR(ROWS(_xlfn._xlws.FILTER(INDIRECT($A$12&"!A2:E100"),(INDIRECT($A$12&"!A2:A100")=$C16)*(INDIRECT($A$12&"!E2:E100")="Atrasado >= 2"))), 0)} -> 0 | G16: {=IFERROR(ROWS(_xlfn._xlws.FILTER(INDIRECT($A$12&"!A2:E100"),(INDIRECT($A$12&"!A2:A100")=$C16)*(INDIRECT($A$12&"!E2:E100")="Duplicado"))), 0)} -> 0 | H16: {=IFERROR(ROWS(_xlfn._xlws.FILTER(INDIRECT($A$12&"!A2:E100"),(INDIRECT($A$12&"!A2:A100")=$C16)*(INDIRECT($A$12&"!E2:E100")="Outras Ocorrências"))), 0)} -> 0 | I16: {=IFERROR(ROWS(_xlfn._xlws.FILTER(INDIRECT($A$12&"!A2:E100"),(INDIRECT($A$12&"!A2:A100")=$C16)*(INDIRECT($A$12&"!E2:E100")="Sem Técnico"))), 0)} -> 0 | K16: =COUNTIF(INDIRECT("Monitoramento!$D$28:$Q$38"), "Enviado") -> 132 | L16: =COUNTIF(INDIRECT("Monitoramento!$D$28:$Q$38"), "Atrasado") -> 1 | M16: =COUNTIF(INDIRECT("Monitoramento!$D$28:$Q$38"), "Atrasado >= 2") -> 2 | N16: =COUNTIF(INDIRECT("Monitoramento!$D$28:$Q$38"), "Duplicado") -> 9 | O16: =COUNTIF(INDIRECT("Monitoramento!$D$28:$Q$38"), "Outras Ocorrências") -> 0 | P16: =COUNTIF(INDIRECT("Monitoramento!$D$28:$Q$38"), "Sem Técnico") -> 0 | R16: Atrasados >= 2 | S16: =VLOOKUP($T$12,$C$14:$I$19,4,FALSE) -> 0 | T16: =S16/SUM($S$14:$S$19) -> 0
C17: Larissa | D17: {=IFERROR(ROWS(_xlfn._xlws.FILTER(INDIRECT($A$12&"!A2:E100"),(INDIRECT($A$12&"!A2:A100")=$C17)*(INDIRECT($A$12&"!E2:E100")="Enviado"))), 0)} -> 10 | E17: {=IFERROR(ROWS(_xlfn._xlws.FILTER(INDIRECT($A$12&"!A2:E100"),(INDIRECT($A$12&"!A2:A100")=$C17)*(INDIRECT($A$12&"!E2:E100")="Atrasado"))), 0)} -> 3 | F17: {=IFERROR(ROWS(_xlfn._xlws.FILTER(INDIRECT($A$12&"!A2:E100"),(INDIRECT($A$12&"!A2:A100")=$C17)*(INDIRECT($A$12&"!E2:E100")="Atrasado >= 2"))), 0)} -> 0 | G17: {=IFERROR(ROWS(_xlfn._xlws.FILTER(INDIRECT($A$12&"!A2:E100"),(INDIRECT($A$12&"!A2:A100")=$C17)*(INDIRECT($A$12&"!E2:E100")="Duplicado"))), 0)} -> 0 | H17: {=IFERROR(ROWS(_xlfn._xlws.FILTER(INDIRECT($A$12&"!A2:E100"),(INDIRECT($A$12&"!A2:A100")=$C17)*(INDIRECT($A$12&"!E2:E100")="Outras Ocorrências"))), 0)} -> 0 | I17: {=IFERROR(ROWS(_xlfn._xlws.FILTER(INDIRECT($A$12&"!A2:E100"),(INDIRECT($A$12&"!A2:A100")=$C17)*(INDIRECT($A$12&"!E2:E100")="Sem Técnico"))), 0)} -> 0 | K17: =COUNTIF(INDIRECT("Monitoramento!$D$41:$Q$53"), "Enviado") -> 151 | L17: =COUNTIF(INDIRECT("Monitoramento!$D$41:$Q$53"), "Atrasado") -> 3 | M17: =COUNTIF(INDIRECT("Monitoramento!$D$41:$Q$53"), "Atrasado >= 2") -> 0 | N17: =COUNTIF(INDIRECT("Monitoramento!$D$41:$Q$53"), "Duplicado") -> 0 | O17: =COUNTIF(INDIRECT("Monitoramento!$D$41:$Q$53"), "Outras Ocorrências") -> 0 | P17: =COUNTIF(INDIRECT("Monitoramento!$D$41:$Q$53"), "Sem Técnico") -> 15 | R17: Duplicados | S17: =VLOOKUP($T$12,$C$14:$I$19,5,FALSE) -> 0 | T17: =S17/SUM($S$14:$S$19) -> 0
C18: Luana | D18: {=IFERROR(ROWS(_xlfn._xlws.FILTER(INDIRECT($A$12&"!A2:E100"),(INDIRECT($A$12&"!A2:A100")=$C18)*(INDIRECT($A$12&"!E2:E100")="Enviado"))), 0)} -> 8 | E18: {=IFERROR(ROWS(_xlfn._xlws.FILTER(INDIRECT($A$12&"!A2:E100"),(INDIRECT($A$12&"!A2:A100")=$C18)*(INDIRECT($A$12&"!E2:E100")="Atrasado"))), 0)} -> 4 | F18: {=IFERROR(ROWS(_xlfn._xlws.FILTER(INDIRECT($A$12&"!A2:E100"),(INDIRECT($A$12&"!A2:A100")=$C18)*(INDIRECT($A$12&"!E2:E100")="Atrasado >= 2"))), 0)} -> 0 | G18: {=IFERROR(ROWS(_xlfn._xlws.FILTER(INDIRECT($A$12&"!A2:E100"),(INDIRECT($A$12&"!A2:A100")=$C18)*(INDIRECT($A$12&"!E2:E100")="Duplicado"))), 0)} -> 0 | H18: {=IFERROR(ROWS(_xlfn._xlws.FILTER(INDIRECT($A$12&"!A2:E100"),(INDIRECT($A$12&"!A2:A100")=$C18)*(INDIRECT($A$12&"!E2:E100")="Outras Ocorrências"))), 0)} -> 0 | I18: {=IFERROR(ROWS(_xlfn._xlws.FILTER(INDIRECT($A$12&"!A2:E100"),(INDIRECT($A$12&"!A2:A100")=$C18)*(INDIRECT($A$12&"!E2:E100")="Sem Técnico"))), 0)} -> 0 | K18: =COUNTIF(INDIRECT("Monitoramento!$D$56:$Q$67"), "Enviado") -> 145 | L18: =COUNTIF(INDIRECT("Monitoramento!$D$56:$Q$67"), "Atrasado") -> 4 | M18: =COUNTIF(INDIRECT("Monitoramento!$D$56:$Q$67"), "Atrasado >= 2") -> 4 | N18: =COUNTIF(INDIRECT("Monitoramento!$D$56:$Q$67"), "Duplicado") -> 3 | O18: =COUNTIF(INDIRECT("Monitoramento!$D$56:$Q$67"), "Outras Ocorrências") -> 0 | P18: =COUNTIF(INDIRECT("Monitoramento!$D$56:$Q$67"), "Sem Técnico") -> 0 | R18: Outras Ocorrências | S18: =VLOOKUP($T$12,$C$14:$I$19,6,FALSE) -> 0 | T18: =S18/SUM($S$14:$S$19) -> 0
C19: Valquiria | D19: {=IFERROR(ROWS(_xlfn._xlws.FILTER(INDIRECT($A$12&"!A2:E100"),(INDIRECT($A$12&"!A2:A100")=$C19)*(INDIRECT($A$12&"!E2:E100")="Enviado"))), 0)} -> 11 | E19: {=IFERROR(ROWS(_xlfn._xlws.FILTER(INDIRECT($A$12&"!A2:E100"),(INDIRECT($A$12&"!A2:A100")=$C19)*(INDIRECT($A$12&"!E2:E100")="Atrasado"))), 0)} -> 0 | F19: {=IFERROR(ROWS(_xlfn._xlws.FILTER(INDIRECT($A$12&"!A2:E100"),(INDIRECT($A$12&"!A2:A100")=$C19)*(INDIRECT($A$12&"!E2:E100")="Atrasado >= 2"))), 0)} -> 0 | G19: {=IFERROR(ROWS(_xlfn._xlws.FILTER(INDIRECT($A$12&"!A2:E100"),(INDIRECT($A$12&"!A2:A100")=$C19)*(INDIRECT($A$12&"!E2:E100")="Duplicado"))), 0)} -> 0 | H19: {=IFERROR(ROWS(_xlfn._xlws.FILTER(INDIRECT($A$12&"!A2:E100"),(INDIRECT($A$12&"!A2:A100")=$C19)*(INDIRECT($A$12&"!E2:E100")="Outras Ocorrências"))), 0)} -> 0 | I19: {=IFERROR(ROWS(_xlfn._xlws.FILTER(INDIRECT($A$12&"!A2:E100"),(INDIRECT($A$12&"!A2:A100")=$C19)*(INDIRECT($A$12&"!E2:E100")="Sem Técnico"))), 0)} -> 0 | K19: =COUNTIF(INDIRECT("Monitoramento!$D$70:$Q$80"), "Enviado") -> 135 | L19: =COUNTIF(INDIRECT("Monitoramento!$D$70:$Q$80"), "Atrasado") -> 0 | M19: =COUNTIF(INDIRECT("Monitoramento!$D$70:$Q$80"), "Atrasado >= 2") -> 4 | N19: =COUNTIF(INDIRECT("Monitoramento!$D$70:$Q$80"), "Duplicado") -> 4 | O19: =COUNTIF(INDIRECT("Monitoramento!$D$70:$Q$80"), "Outras Ocorrências") -> 0 | P19: =COUNTIF(INDIRECT("Monitoramento!$D$70:$Q$80"), "Sem Técnico") -> 0 | R19: Sem Técnico | S19: =VLOOKUP($T$12,$C$14:$I$19,7,FALSE) -> 0 | T19: =S19/SUM($S$14:$S$19) -> 0
C20: Regionais (Validações) | K20: Regionais (Validações) | R20: % Validação | S20: =VLOOKUP($T$12,$C$22:$I$27,7,FALSE) -> 0.7
C21: Regional | E21: Validados | G21: Não Validados | I21: % Val. | K21: Validados | M21: Não Validados | O21: % Validados | R21: Envios - Acumulado (Total)
C22: Bianca | E22: {=IFERROR(ROWS(_xlfn._xlws.FILTER(INDIRECT($A$12&"!A2:E100"),(INDIRECT($A$12&"!A2:A100")=$C22)*(INDIRECT($A$12&"!G2:G100")="Sim"))), 0)} -> 7 | G22: {=IFERROR(ROWS(_xlfn._xlws.FILTER(INDIRECT($A$12&"!A2:E100"),(INDIRECT($A$12&"!A2:A100")=$C22)*(INDIRECT($A$12&"!G2:G100")="Não")))-E14, 0)} -> 3 | I22: =IFERROR(E22/SUM(E22:H22),0) -> 0.7 | K22: =COUNTIF(INDIRECT("Regionais!$D$2:$Q$12"), "Sim") -> 138 | M22: =COUNTIF(INDIRECT("Regionais!$D$2:$Q$12"), "Não")-SUM(L14:M14) -> 4 | O22: =IFERROR(K22/SUM(K22:N22), 0) -> 0.97183099 | R22: Enviados | S22: =VLOOKUP($T$12,$C$13:$P$19,9,FALSE) -> 142 | T22: =S22/SUM($S$22:$S$27) -> 0.99300699
C23: Gabriel | E23: {=IFERROR(ROWS(_xlfn._xlws.FILTER(INDIRECT($A$12&"!A2:E100"),(INDIRECT($A$12&"!A2:A100")=$C23)*(INDIRECT($A$12&"!G2:G100")="Sim"))), 0)} -> 0 | G23: {=IFERROR(ROWS(_xlfn._xlws.FILTER(INDIRECT($A$12&"!A2:E100"),(INDIRECT($A$12&"!A2:A100")=$C23)*(INDIRECT($A$12&"!G2:G100")="Não")))-E15, 0)} -> 10 | I23: =IFERROR(E23/SUM(E23:H23),0) -> 0 | K23: =COUNTIF(INDIRECT("Regionais!$D$15:$Q$25"), "Sim") -> 54 | M23: =COUNTIF(INDIRECT("Regionais!$D$15:$Q$25"), "Não")-SUM(L15:M15) -> 87 | O23: =IFERROR(K23/SUM(K23:N23), 0) -> 0.38297872 | R23: Atrasados | S23: =VLOOKUP($T$12,$C$13:$P$19,10,FALSE) -> 1 | T23: =S23/SUM($S$22:$S$27) -> 0.006993007
C24: Gustavo | E24: {=IFERROR(ROWS(_xlfn._xlws.FILTER(INDIRECT($A$12&"!A2:E100"),(INDIRECT($A$12&"!A2:A100")=$C24)*(INDIRECT($A$12&"!G2:G100")="Sim"))), 0)} -> 4 | G24: {=IFERROR(ROWS(_xlfn._xlws.FILTER(INDIRECT($A$12&"!A2:E100"),(INDIRECT($A$12&"!A2:A100")=$C24)*(INDIRECT($A$12&"!G2:G100")="Não")))-E16, 0)} -> 6 | I24: =IFERROR(E24/SUM(E24:H24),0) -> 0.4 | K24: =COUNTIF(INDIRECT("Regionais!$D$28:$Q$38"), "Sim") -> 67 | M24: =COUNTIF(INDIRECT("Regionais!$D$28:$Q$38"), "Não")-SUM(L16:M16) -> 74 | O24: =IFERROR(K24/SUM(K24:N24), 0) -> 0.4751773 | R24: Atrasados >= 2 | S24: =VLOOKUP($T$12,$C$13:$P$19,11,FALSE) -> 0 | T24: =S24/SUM($S$22:$S$27) -> 0
C25: Larissa | E25: {=IFERROR(ROWS(_xlfn._xlws.FILTER(INDIRECT($A$12&"!A2:E100"),(INDIRECT($A$12&"!A2:A100")=$C25)*(INDIRECT($A$12&"!G2:G100")="Sim"))), 0)} -> 7 | G25: {=IFERROR(ROWS(_xlfn._xlws.FILTER(INDIRECT($A$12&"!A2:E100"),(INDIRECT($A$12&"!A2:A100")=$C25)*(INDIRECT($A$12&"!G2:G100")="Não")))-E17, 0)} -> 3 | I25: =IFERROR(E25/SUM(E25:H25),0) -> 0.7 | K25: =COUNTIF(INDIRECT("Regionais!$D$41:$Q$53"), "Sim") -> 162 | M25: =COUNTIF(INDIRECT("Regionais!$D$41:$Q$53"), "Não")-SUM(L17:M17) -> 4 | O25: =IFERROR(K25/SUM(K25:N25), 0) -> 0.97590361 | R25: Duplicados | S25: =VLOOKUP($T$12,$C$13:$P$19,12,FALSE) -> 0 | T25: =S25/SUM($S$22:$S$27) -> 0
C26: Luana | E26: {=IFERROR(ROWS(_xlfn._xlws.FILTER(INDIRECT($A$12&"!A2:E100"),(INDIRECT($A$12&"!A2:A100")=$C26)*(INDIRECT($A$12&"!G2:G100")="Sim"))), 0)} -> 0 | G26: {=IFERROR(ROWS(_xlfn._xlws.FILTER(INDIRECT($A$12&"!A2:E100"),(INDIRECT($A$12&"!A2:A100")=$C26)*(INDIRECT($A$12&"!G2:G100")="Não")))-E18, 0)} -> 8 | I26: =IFERROR(E26/SUM(E26:H26),0) -> 0 | K26: =COUNTIF(INDIRECT("Regionais!$D$56:$Q$67"), "Sim") -> 122 | M26: =COUNTIF(INDIRECT("Regionais!$D$56:$Q$67"), "Não")-SUM(L18:M18) -> 26 | O26: =IFERROR(K26/SUM(K26:N26), 0) -> 0.82432432 | R26: Outras Ocorrências | S26: =VLOOKUP($T$12,$C$13:$P$19,13,FALSE) -> 0 | T26: =S26/SUM($S$22:$S$27) -> 0
C27: Valquiria | E27: {=IFERROR(ROWS(_xlfn._xlws.FILTER(INDIRECT($A$12&"!A2:E100"),(INDIRECT($A$12&"!A2:A100")=$C27)*(INDIRECT($A$12&"!G2:G100")="Sim"))), 0)} -> 10 | G27: {=IFERROR(ROWS(_xlfn._xlws.FILTER(INDIRECT($A$12&"!A2:E100"),(INDIRECT($A$12&"!A2:A100")=$C27)*(INDIRECT($A$12&"!G2:G100")="Não")))-E19, 0)} -> 1 | I27: =IFERROR(E27/SUM(E27:H27),0) -> 0.90909091 | K27: =COUNTIF(INDIRECT("Regionais!$D$70:$Q$80"), "Sim") -> 129 | M27: =COUNTIF(INDIRECT("Regionais!$D$70:$Q$80"), "Não")-SUM(L19:M19) -> 10 | O27: =IFERROR(K27/SUM(K27:N27), 0) -> 0.92805755 | R27: Sem Técnico | S27: =VLOOKUP($T$12,$C$13:$P$19,14,FALSE) -> 0 | T27: =S27/SUM($S$22:$S$27) -> 0
R28: % Validação | S28: =VLOOKUP($T$12,$C$21:$P$27,13,FALSE) -> 0.97183099
C34: Formulários | E34: Enviado | F34: Atrasado | G34: Sem Téc | H34: Outras | I34: Total
C35: 4 - Receitas (11/24) | E35: =B$2+B$5 -> 66 | F35: =B$3+B$4 -> 1 | G35: =B$7 -> 2 | H35: =B$6 -> 0 | I35: =SUM(E35:H35) -> 69
C36: 4 - Receitas (12/24) | E36: =C$2+C$5 -> 65 | F36: =C$3+C$4 -> 2 | G36: =C$7 -> 2 | H36: =C$6 -> 0 | I36: =SUM(E36:H36) -> 69
C37: 4 - Receitas (01/25) | E37: =D$2+D$5 -> 65 | F37: =D$3+D$4 -> 2 | G37: =D$7 -> 2 | H37: =D$6 -> 0 | I37: =SUM(E37:H37) -> 69
C38: 4 - Receitas (02/25) | E38: =E$2+E$5 -> 65 | F38: =E$3+E$4 -> 2 | G38: =E$7 -> 2 | H38: =E$6 -> 0 | I38: =SUM(E38:H38) -> 69
C39: 4 - Receitas (03/25) | E39: =F$2+F$5 -> 67 | F39: =F$3+F$4 -> 0 | G39: =F$7 -> 2 | H39: =F$6 -> 0 | I39: =SUM(E39:H39) -> 69
C40: 4 - Receitas (04/25) | E40: =G$2+G$5 -> 67 | F40: =G$3+G$4 -> 0 | G40: =G$7 -> 2 | H40: =G$6 -> 0 | I40: =SUM(E40:H40) -> 69
C41: 4 - Receitas (05/25) | E41: =H$2+H$5 -> 67 | F41: =H$3+H$4 -> 1 | G41: =H$7 -> 1 | H41: =H$6 -> 0 | I41: =SUM(E41:H41) -> 69
C42: 4 - Receitas (06/25) | E42: =I$2+I$5 -> 68 | F42: =I$3+I$4 -> 0 | G42: =I$7 -> 1 | H42: =I$6 -> 0 | I42: =SUM(E42:H42) -> 69
C43: 4 - Receitas (07/25) | E43: =J$2+J$5 -> 68 | F43: =J$3+J$4 -> 0 | G43: =J$7 -> 1 | H43: =J$6 -> 0 | I43: =SUM(E43:H43) -> 69
C44: 4 - Receitas (08/25) | E44: =K$2+K$5 -> 69 | F44: =K$3+K$4 -> 0 | G44: =K$7 -> 0 | H44: =K$6 -> 0 | I44: =SUM(E44:H44) -> 69
C45: 4 - Receitas (09/25) | E45: =L$2+L$5 -> 68 | F45: =L$3+L$4 -> 1 | G45: =L$7 -> 0 | H45: =L$6 -> 0 | I45: =SUM(E45:H45) -> 69
C46: 4 - Receitas (10/25) | E46: =M$2+M$5 -> 67 | F46: =M$3+M$4 -> 2 | G46: =M$7 -> 0 | H46: =M$6 -> 0 | I46: =SUM(E46:H46) -> 69
C47: 4 - Receitas (11/25) | E47: =N$2+N$5 -> 59 | F47: =N$3+N$4 -> 10 | G47: =N$7 -> 0 | H47: =N$6 -> 0 | I47: =SUM(E47:H47) -> 69
...

Sheet Monitoramento
A1: Regional | B1: Municípios | C1: UVR | D1: 11.24 | E1: 12.24 | F1: 01.25 | G1: 02.25 | H1: 03.25 | I1: 04.25 | J1: 05.25 | K1: 06.25 | L1: 07.25 | M1: 08.25 | N1: 09.25 | O1: 10.25 | P1: 11.25 | Q1: 12.25
A2: Bianca | B2: Anahy | C2: 1 | D2: {=IF( VLOOKUP( $A2, _xlfn._xlws.FILTER( INDIRECT("'"&D$14&"'!A2:E1000"), (INDIRECT("'"&D$14&"'!B2:B1000")=$B2) * (INDIRECT("'"&D$14&"'!C2:C1000")=$C2) ), 5, FALSE )=0, "", VLOOKUP( $A2, _xlfn._xlws.FILTER( INDIRECT("'"&D$14&"'!A2:E1000"), (INDIRECT("'"&D$14&"'!B2:B1000")=$B2) * (INDIRECT("'"&D$14&"'!C2:C1000")=$C2) ), 5, FALSE ) )} -> Enviado | E2: {=IF( VLOOKUP( $A2, _xlfn._xlws.FILTER( INDIRECT("'"&E$14&"'!A2:E1000"), (INDIRECT("'"&E$14&"'!B2:B1000")=$B2) * (INDIRECT("'"&E$14&"'!C2:C1000")=$C2) ), 5, FALSE )=0, "", VLOOKUP( $A2, _xlfn._xlws.FILTER( INDIRECT("'"&E$14&"'!A2:E1000"), (INDIRECT("'"&E$14&"'!B2:B1000")=$B2) * (INDIRECT("'"&E$14&"'!C2:C1000")=$C2) ), 5, FALSE ) )} -> Enviado | F2: {=IF( VLOOKUP( $A2, _xlfn._xlws.FILTER( INDIRECT("'"&F$14&"'!A2:E1000"), (INDIRECT("'"&F$14&"'!B2:B1000")=$B2) * (INDIRECT("'"&F$14&"'!C2:C1000")=$C2) ), 5, FALSE )=0, "", VLOOKUP( $A2, _xlfn._xlws.FILTER( INDIRECT("'"&F$14&"'!A2:E1000"), (INDIRECT("'"&F$14&"'!B2:B1000")=$B2) * (INDIRECT("'"&F$14&"'!C2:C1000")=$C2) ), 5, FALSE ) )} -> Enviado | G2: {=IF( VLOOKUP( $A2, _xlfn._xlws.FILTER( INDIRECT("'"&G$14&"'!A2:E1000"), (INDIRECT("'"&G$14&"'!B2:B1000")=$B2) * (INDIRECT("'"&G$14&"'!C2:C1000")=$C2) ), 5, FALSE )=0, "", VLOOKUP( $A2, _xlfn._xlws.FILTER( INDIRECT("'"&G$14&"'!A2:E1000"), (INDIRECT("'"&G$14&"'!B2:B1000")=$B2) * (INDIRECT("'"&G$14&"'!C2:C1000")=$C2) ), 5, FALSE ) )} -> Enviado | H2: {=IF( VLOOKUP( $A2, _xlfn._xlws.FILTER( INDIRECT("'"&H$14&"'!A2:E1000"), (INDIRECT("'"&H$14&"'!B2:B1000")=$B2) * (INDIRECT("'"&H$14&"'!C2:C1000")=$C2) ), 5, FALSE )=0, "", VLOOKUP( $A2, _xlfn._xlws.FILTER( INDIRECT("'"&H$14&"'!A2:E1000"), (INDIRECT("'"&H$14&"'!B2:B1000")=$B2) * (INDIRECT("'"&H$14&"'!C2:C1000")=$C2) ), 5, FALSE ) )} -> Enviado | I2: {=IF( VLOOKUP( $A2, _xlfn._xlws.FILTER( INDIRECT("'"&I$14&"'!A2:E1000"), (INDIRECT("'"&I$14&"'!B2:B1000")=$B2) * (INDIRECT("'"&I$14&"'!C2:C1000")=$C2) ), 5, FALSE )=0, "", VLOOKUP( $A2, _xlfn._xlws.FILTER( INDIRECT("'"&I$14&"'!A2:E1000"), (INDIRECT("'"&I$14&"'!B2:B1000")=$B2) * (INDIRECT("'"&I$14&"'!C2:C1000")=$C2) ), 5, FALSE ) )} -> Enviado | J2: {=IF( VLOOKUP( $A2, _xlfn._xlws.FILTER( INDIRECT("'"&J$14&"'!A2:E1000"), (INDIRECT("'"&J$14&"'!B2:B1000")=$B2) * (INDIRECT("'"&J$14&"'!C2:C1000")=$C2) ), 5, FALSE )=0, "", VLOOKUP( $A2, _xlfn._xlws.FILTER( INDIRECT("'"&J$14&"'!A2:E1000"), (INDIRECT("'"&J$14&"'!B2:B1000")=$B2) * (INDIRECT("'"&J$14&"'!C2:C1000")=$C2) ), 5, FALSE ) )} -> Enviado | K2: {=IF( VLOOKUP( $A2, _xlfn._xlws.FILTER( INDIRECT("'"&K$14&"'!A2:E1000"), (INDIRECT("'"&K$14&"'!B2:B1000")=$B2) * (INDIRECT("'"&K$14&"'!C2:C1000")=$C2) ), 5, FALSE )=0, "", VLOOKUP( $A2, _xlfn._xlws.FILTER( INDIRECT("'"&K$14&"'!A2:E1000"), (INDIRECT("'"&K$14&"'!B2:B1000")=$B2) * (INDIRECT("'"&K$14&"'!C2:C1000")=$C2) ), 5, FALSE ) )} -> Enviado | ... Q2: {=IF( VLOOKUP( $A2, _xlfn._xlws.FILTER( INDIRECT("'"&Q$14&"'!A2:E1000"), (INDIRECT("'"&Q$14&"'!B2:B1000")=$B2) * (INDIRECT("'"&Q$14&"'!C2:C1000")=$C2) ), 5, FALSE )=0, "", VLOOKUP( $A2, _xlfn._xlws.FILTER( INDIRECT("'"&Q$14&"'!A2:E1000"), (INDIRECT("'"&Q$14&"'!B2:B1000")=$B2) * (INDIRECT("'"&Q$14&"'!C2:C1000")=$C2) ), 5, FALSE ) )}
A3: Bianca | B3: Boa Vista da Aparecida | C3: 1 | D3: {=IF( VLOOKUP( $A3, _xlfn._xlws.FILTER( INDIRECT("'"&D$14&"'!A2:E1000"), (INDIRECT("'"&D$14&"'!B2:B1000")=$B3) * (INDIRECT("'"&D$14&"'!C2:C1000")=$C3) ), 5, FALSE )=0, "", VLOOKUP( $A3, _xlfn._xlws.FILTER( INDIRECT("'"&D$14&"'!A2:E1000"), (INDIRECT("'"&D$14&"'!B2:B1000")=$B3) * (INDIRECT("'"&D$14&"'!C2:C1000")=$C3) ), 5, FALSE ) )} -> Enviado | E3: {=IF( VLOOKUP( $A3, _xlfn._xlws.FILTER( INDIRECT("'"&E$14&"'!A2:E1000"), (INDIRECT("'"&E$14&"'!B2:B1000")=$B3) * (INDIRECT("'"&E$14&"'!C2:C1000")=$C3) ), 5, FALSE )=0, "", VLOOKUP( $A3, _xlfn._xlws.FILTER( INDIRECT("'"&E$14&"'!A2:E1000"), (INDIRECT("'"&E$14&"'!B2:B1000")=$B3) * (INDIRECT("'"&E$14&"'!C2:C1000")=$C3) ), 5, FALSE ) )} -> Enviado | F3: {=IF( VLOOKUP( $A3, _xlfn._xlws.FILTER( INDIRECT("'"&F$14&"'!A2:E1000"), (INDIRECT("'"&F$14&"'!B2:B1000")=$B3) * (INDIRECT("'"&F$14&"'!C2:C1000")=$C3) ), 5, FALSE )=0, "", VLOOKUP( $A3, _xlfn._xlws.FILTER( INDIRECT("'"&F$14&"'!A2:E1000"), (INDIRECT("'"&F$14&"'!B2:B1000")=$B3) * (INDIRECT("'"&F$14&"'!C2:C1000")=$C3) ), 5, FALSE ) )} -> Enviado | G3: {=IF( VLOOKUP( $A3, _xlfn._xlws.FILTER( INDIRECT("'"&G$14&"'!A2:E1000"), (INDIRECT("'"&G$14&"'!B2:B1000")=$B3) * (INDIRECT("'"&G$14&"'!C2:C1000")=$C3) ), 5, FALSE )=0, "", VLOOKUP( $A3, _xlfn._xlws.FILTER( INDIRECT("'"&G$14&"'!A2:E1000"), (INDIRECT("'"&G$14&"'!B2:B1000")=$B3) * (INDIRECT("'"&G$14&"'!C2:C1000")=$C3) ), 5, FALSE ) )} -> Enviado | H3: {=IF( VLOOKUP( $A3, _xlfn._xlws.FILTER( INDIRECT("'"&H$14&"'!A2:E1000"), (INDIRECT("'"&H$14&"'!B2:B1000")=$B3) * (INDIRECT("'"&H$14&"'!C2:C1000")=$C3) ), 5, FALSE )=0, "", VLOOKUP( $A3, _xlfn._xlws.FILTER( INDIRECT("'"&H$14&"'!A2:E1000"), (INDIRECT("'"&H$14&"'!B2:B1000")=$B3) * (INDIRECT("'"&H$14&"'!C2:C1000")=$C3) ), 5, FALSE ) )} -> Enviado | I3: {=IF( VLOOKUP( $A3, _xlfn._xlws.FILTER( INDIRECT("'"&I$14&"'!A2:E1000"), (INDIRECT("'"&I$14&"'!B2:B1000")=$B3) * (INDIRECT("'"&I$14&"'!C2:C1000")=$C3) ), 5, FALSE )=0, "", VLOOKUP( $A3, _xlfn._xlws.FILTER( INDIRECT("'"&I$14&"'!A2:E1000"), (INDIRECT("'"&I$14&"'!B2:B1000")=$B3) * (INDIRECT("'"&I$14&"'!C2:C1000")=$C3) ), 5, FALSE ) )} -> Enviado | J3: {=IF( VLOOKUP( $A3, _xlfn._xlws.FILTER( INDIRECT("'"&J$14&"'!A2:E1000"), (INDIRECT("'"&J$14&"'!B2:B1000")=$B3) * (INDIRECT("'"&J$14&"'!C2:C1000")=$C3) ), 5, FALSE )=0, "", VLOOKUP( $A3, _xlfn._xlws.FILTER( INDIRECT("'"&J$14&"'!A2:E1000"), (INDIRECT("'"&J$14&"'!B2:B1000")=$B3) * (INDIRECT("'"&J$14&"'!C2:C1000")=$C3) ), 5, FALSE ) )} -> Enviado | K3: {=IF( VLOOKUP( $A3, _xlfn._xlws.FILTER( INDIRECT("'"&K$14&"'!A2:E1000"), (INDIRECT("'"&K$14&"'!B2:B1000")=$B3) * (INDIRECT("'"&K$14&"'!C2:C1000")=$C3) ), 5, FALSE )=0, "", VLOOKUP( $A3, _xlfn._xlws.FILTER( INDIRECT("'"&K$14&"'!A2:E1000"), (INDIRECT("'"&K$14&"'!B2:B1000")=$B3) * (INDIRECT("'"&K$14&"'!C2:C1000")=$C3) ), 5, FALSE ) )} -> Enviado | ... Q3: {=IF( VLOOKUP( $A3, _xlfn._xlws.FILTER( INDIRECT("'"&Q$14&"'!A2:E1000"), (INDIRECT("'"&Q$14&"'!B2:B1000")=$B3) * (INDIRECT("'"&Q$14&"'!C2:C1000")=$C3) ), 5, FALSE )=0, "", VLOOKUP( $A3, _xlfn._xlws.FILTER( INDIRECT("'"&Q$14&"'!A2:E1000"), (INDIRECT("'"&Q$14&"'!B2:B1000")=$B3) * (INDIRECT("'"&Q$14&"'!C2:C1000")=$C3) ), 5, FALSE ) )}
A4: Bianca | B4: Braganey | C4: 1 | D4: {=IF( VLOOKUP( $A4, _xlfn._xlws.FILTER( INDIRECT("'"&D$14&"'!A2:E1000"), (INDIRECT("'"&D$14&"'!B2:B1000")=$B4) * (INDIRECT("'"&D$14&"'!C2:C1000")=$C4) ), 5, FALSE )=0, "", VLOOKUP( $A4, _xlfn._xlws.FILTER( INDIRECT("'"&D$14&"'!A2:E1000"), (INDIRECT("'"&D$14&"'!B2:B1000")=$B4) * (INDIRECT("'"&D$14&"'!C2:C1000")=$C4) ), 5, FALSE ) )} -> Enviado | E4: {=IF( VLOOKUP( $A4, _xlfn._xlws.FILTER( INDIRECT("'"&E$14&"'!A2:E1000"), (INDIRECT("'"&E$14&"'!B2:B1000")=$B4) * (INDIRECT("'"&E$14&"'!C2:C1000")=$C4) ), 5, FALSE )=0, "", VLOOKUP( $A4, _xlfn._xlws.FILTER( INDIRECT("'"&E$14&"'!A2:E1000"), (INDIRECT("'"&E$14&"'!B2:B1000")=$B4) * (INDIRECT("'"&E$14&"'!C2:C1000")=$C4) ), 5, FALSE ) )} -> Enviado | F4: {=IF( VLOOKUP( $A4, _xlfn._xlws.FILTER( INDIRECT("'"&F$14&"'!A2:E1000"), (INDIRECT("'"&F$14&"'!B2:B1000")=$B4) * (INDIRECT("'"&F$14&"'!C2:C1000")=$C4) ), 5, FALSE )=0, "", VLOOKUP( $A4, _xlfn._xlws.FILTER( INDIRECT("'"&F$14&"'!A2:E1000"), (INDIRECT("'"&F$14&"'!B2:B1000")=$B4) * (INDIRECT("'"&F$14&"'!C2:C1000")=$C4) ), 5, FALSE ) )} -> Enviado | G4: {=IF( VLOOKUP( $A4, _xlfn._xlws.FILTER( INDIRECT("'"&G$14&"'!A2:E1000"), (INDIRECT("'"&G$14&"'!B2:B1000")=$B4) * (INDIRECT("'"&G$14&"'!C2:C1000")=$C4) ), 5, FALSE )=0, "", VLOOKUP( $A4, _xlfn._xlws.FILTER( INDIRECT("'"&G$14&"'!A2:E1000"), (INDIRECT("'"&G$14&"'!B2:B1000")=$B4) * (INDIRECT("'"&G$14&"'!C2:C1000")=$C4) ), 5, FALSE ) )} -> Enviado | H4: {=IF( VLOOKUP( $A4, _xlfn._xlws.FILTER( INDIRECT("'"&H$14&"'!A2:E1000"), (INDIRECT("'"&H$14&"'!B2:B1000")=$B4) * (INDIRECT("'"&H$14&"'!C2:C1000")=$C4) ), 5, FALSE )=0, "", VLOOKUP( $A4, _xlfn._xlws.FILTER( INDIRECT("'"&H$14&"'!A2:E1000"), (INDIRECT("'"&H$14&"'!B2:B1000")=$B4) * (INDIRECT("'"&H$14&"'!C2:C1000")=$C4) ), 5, FALSE ) )} -> Enviado | I4: {=IF( VLOOKUP( $A4, _xlfn._xlws.FILTER( INDIRECT("'"&I$14&"'!A2:E1000"), (INDIRECT("'"&I$14&"'!B2:B1000")=$B4) * (INDIRECT("'"&I$14&"'!C2:C1000")=$C4) ), 5, FALSE )=0, "", VLOOKUP( $A4, _xlfn._xlws.FILTER( INDIRECT("'"&I$14&"'!A2:E1000"), (INDIRECT("'"&I$14&"'!B2:B1000")=$B4) * (INDIRECT("'"&I$14&"'!C2:C1000")=$C4) ), 5, FALSE ) )} -> Enviado | J4: {=IF( VLOOKUP( $A4, _xlfn._xlws.FILTER( INDIRECT("'"&J$14&"'!A2:E1000"), (INDIRECT("'"&J$14&"'!B2:B1000")=$B4) * (INDIRECT("'"&J$14&"'!C2:C1000")=$C4) ), 5, FALSE )=0, "", VLOOKUP( $A4, _xlfn._xlws.FILTER( INDIRECT("'"&J$14&"'!A2:E1000"), (INDIRECT("'"&J$14&"'!B2:B1000")=$B4) * (INDIRECT("'"&J$14&"'!C2:C1000")=$C4) ), 5, FALSE ) )} -> Enviado | K4: {=IF( VLOOKUP( $A4, _xlfn._xlws.FILTER( INDIRECT("'"&K$14&"'!A2:E1000"), (INDIRECT("'"&K$14&"'!B2:B1000")=$B4) * (INDIRECT("'"&K$14&"'!C2:C1000")=$C4) ), 5, FALSE )=0, "", VLOOKUP( $A4, _xlfn._xlws.FILTER( INDIRECT("'"&K$14&"'!A2:E1000"), (INDIRECT("'"&K$14&"'!B2:B1000")=$B4) * (INDIRECT("'"&K$14&"'!C2:C1000")=$C4) ), 5, FALSE ) )} -> Enviado | ... Q4: {=IF( VLOOKUP( $A4, _xlfn._xlws.FILTER( INDIRECT("'"&Q$14&"'!A2:E1000"), (INDIRECT("'"&Q$14&"'!B2:B1000")=$B4) * (INDIRECT("'"&Q$14&"'!C2:C1000")=$C4) ), 5, FALSE )=0, "", VLOOKUP( $A4, _xlfn._xlws.FILTER( INDIRECT("'"&Q$14&"'!A2:E1000"), (INDIRECT("'"&Q$14&"'!B2:B1000")=$B4) * (INDIRECT("'"&Q$14&"'!C2:C1000")=$C4) ), 5, FALSE ) )}
A5: Bianca | B5: Campo Bonito | C5: 1 | D5: {=IF( VLOOKUP( $A5, _xlfn._xlws.FILTER( INDIRECT("'"&D$14&"'!A2:E1000"), (INDIRECT("'"&D$14&"'!B2:B1000")=$B5) * (INDIRECT("'"&D$14&"'!C2:C1000")=$C5) ), 5, FALSE )=0, "", VLOOKUP( $A5, _xlfn._xlws.FILTER( INDIRECT("'"&D$14&"'!A2:E1000"), (INDIRECT("'"&D$14&"'!B2:B1000")=$B5) * (INDIRECT("'"&D$14&"'!C2:C1000")=$C5) ), 5, FALSE ) )} -> Enviado | E5: {=IF( VLOOKUP( $A5, _xlfn._xlws.FILTER( INDIRECT("'"&E$14&"'!A2:E1000"), (INDIRECT("'"&E$14&"'!B2:B1000")=$B5) * (INDIRECT("'"&E$14&"'!C2:C1000")=$C5) ), 5, FALSE )=0, "", VLOOKUP( $A5, _xlfn._xlws.FILTER( INDIRECT("'"&E$14&"'!A2:E1000"), (INDIRECT("'"&E$14&"'!B2:B1000")=$B5) * (INDIRECT("'"&E$14&"'!C2:C1000")=$C5) ), 5, FALSE ) )} -> Enviado | F5: {=IF( VLOOKUP( $A5, _xlfn._xlws.FILTER( INDIRECT("'"&F$14&"'!A2:E1000"), (INDIRECT("'"&F$14&"'!B2:B1000")=$B5) * (INDIRECT("'"&F$14&"'!C2:C1000")=$C5) ), 5, FALSE )=0, "", VLOOKUP( $A5, _xlfn._xlws.FILTER( INDIRECT("'"&F$14&"'!A2:E1000"), (INDIRECT("'"&F$14&"'!B2:B1000")=$B5) * (INDIRECT("'"&F$14&"'!C2:C1000")=$C5) ), 5, FALSE ) )} -> Enviado | G5: {=IF( VLOOKUP( $A5, _xlfn._xlws.FILTER( INDIRECT("'"&G$14&"'!A2:E1000"), (INDIRECT("'"&G$14&"'!B2:B1000")=$B5) * (INDIRECT("'"&G$14&"'!C2:C1000")=$C5) ), 5, FALSE )=0, "", VLOOKUP( $A5, _xlfn._xlws.FILTER( INDIRECT("'"&G$14&"'!A2:E1000"), (INDIRECT("'"&G$14&"'!B2:B1000")=$B5) * (INDIRECT("'"&G$14&"'!C2:C1000")=$C5) ), 5, FALSE ) )} -> Enviado | H5: {=IF( VLOOKUP( $A5, _xlfn._xlws.FILTER( INDIRECT("'"&H$14&"'!A2:E1000"), (INDIRECT("'"&H$14&"'!B2:B1000")=$B5) * (INDIRECT("'"&H$14&"'!C2:C1000")=$C5) ), 5, FALSE )=0, "", VLOOKUP( $A5, _xlfn._xlws.FILTER( INDIRECT("'"&H$14&"'!A2:E1000"), (INDIRECT("'"&H$14&"'!B2:B1000")=$B5) * (INDIRECT("'"&H$14&"'!C2:C1000")=$C5) ), 5, FALSE ) )} -> Enviado | I5: {=IF( VLOOKUP( $A5, _xlfn._xlws.FILTER( INDIRECT("'"&I$14&"'!A2:E1000"), (INDIRECT("'"&I$14&"'!B2:B1000")=$B5) * (INDIRECT("'"&I$14&"'!C2:C1000")=$C5) ), 5, FALSE )=0, "", VLOOKUP( $A5, _xlfn._xlws.FILTER( INDIRECT("'"&I$14&"'!A2:E1000"), (INDIRECT("'"&I$14&"'!B2:B1000")=$B5) * (INDIRECT("'"&I$14&"'!C2:C1000")=$C5) ), 5, FALSE ) )} -> Enviado | J5: {=IF( VLOOKUP( $A5, _xlfn._xlws.FILTER( INDIRECT("'"&J$14&"'!A2:E1000"), (INDIRECT("'"&J$14&"'!B2:B1000")=$B5) * (INDIRECT("'"&J$14&"'!C2:C1000")=$C5) ), 5, FALSE )=0, "", VLOOKUP( $A5, _xlfn._xlws.FILTER( INDIRECT("'"&J$14&"'!A2:E1000"), (INDIRECT("'"&J$14&"'!B2:B1000")=$B5) * (INDIRECT("'"&J$14&"'!C2:C1000")=$C5) ), 5, FALSE ) )} -> Enviado | K5: {=IF( VLOOKUP( $A5, _xlfn._xlws.FILTER( INDIRECT("'"&K$14&"'!A2:E1000"), (INDIRECT("'"&K$14&"'!B2:B1000")=$B5) * (INDIRECT("'"&K$14&"'!C2:C1000")=$C5) ), 5, FALSE )=0, "", VLOOKUP( $A5, _xlfn._xlws.FILTER( INDIRECT("'"&K$14&"'!A2:E1000"), (INDIRECT("'"&K$14&"'!B2:B1000")=$B5) * (INDIRECT("'"&K$14&"'!C2:C1000")=$C5) ), 5, FALSE ) )} -> Enviado | ... Q5: {=IF( VLOOKUP( $A5, _xlfn._xlws.FILTER( INDIRECT("'"&Q$14&"'!A2:E1000"), (INDIRECT("'"&Q$14&"'!B2:B1000")=$B5) * (INDIRECT("'"&Q$14&"'!C2:C1000")=$C5) ), 5, FALSE )=0, "", VLOOKUP( $A5, _xlfn._xlws.FILTER( INDIRECT("'"&Q$14&"'!A2:E1000"), (INDIRECT("'"&Q$14&"'!B2:B1000")=$B5) * (INDIRECT("'"&Q$14&"'!C2:C1000")=$C5) ), 5, FALSE ) )}
A6: Bianca | B6: Catanduvas | C6: 1 | D6: {=IF( VLOOKUP( $A6, _xlfn._xlws.FILTER( INDIRECT("'"&D$14&"'!A2:E1000"), (INDIRECT("'"&D$14&"'!B2:B1000")=$B6) * (INDIRECT("'"&D$14&"'!C2:C1000")=$C6) ), 5, FALSE )=0, "", VLOOKUP( $A6, _xlfn._xlws.FILTER( INDIRECT("'"&D$14&"'!A2:E1000"), (INDIRECT("'"&D$14&"'!B2:B1000")=$B6) * (INDIRECT("'"&D$14&"'!C2:C1000")=$C6) ), 5, FALSE ) )} -> Enviado | E6: {=IF( VLOOKUP( $A6, _xlfn._xlws.FILTER( INDIRECT("'"&E$14&"'!A2:E1000"), (INDIRECT("'"&E$14&"'!B2:B1000")=$B6) * (INDIRECT("'"&E$14&"'!C2:C1000")=$C6) ), 5, FALSE )=0, "", VLOOKUP( $A6, _xlfn._xlws.FILTER( INDIRECT("'"&E$14&"'!A2:E1000"), (INDIRECT("'"&E$14&"'!B2:B1000")=$B6) * (INDIRECT("'"&E$14&"'!C2:C1000")=$C6) ), 5, FALSE ) )} -> Enviado | F6: {=IF( VLOOKUP( $A6, _xlfn._xlws.FILTER( INDIRECT("'"&F$14&"'!A2:E1000"), (INDIRECT("'"&F$14&"'!B2:B1000")=$B6) * (INDIRECT("'"&F$14&"'!C2:C1000")=$C6) ), 5, FALSE )=0, "", VLOOKUP( $A6, _xlfn._xlws.FILTER( INDIRECT("'"&F$14&"'!A2:E1000"), (INDIRECT("'"&F$14&"'!B2:B1000")=$B6) * (INDIRECT("'"&F$14&"'!C2:C1000")=$C6) ), 5, FALSE ) )} -> Enviado | G6: {=IF( VLOOKUP( $A6, _xlfn._xlws.FILTER( INDIRECT("'"&G$14&"'!A2:E1000"), (INDIRECT("'"&G$14&"'!B2:B1000")=$B6) * (INDIRECT("'"&G$14&"'!C2:C1000")=$C6) ), 5, FALSE )=0, "", VLOOKUP( $A6, _xlfn._xlws.FILTER( INDIRECT("'"&G$14&"'!A2:E1000"), (INDIRECT("'"&G$14&"'!B2:B1000")=$B6) * (INDIRECT("'"&G$14&"'!C2:C1000")=$C6) ), 5, FALSE ) )} -> Enviado | H6: {=IF( VLOOKUP( $A6, _xlfn._xlws.FILTER( INDIRECT("'"&H$14&"'!A2:E1000"), (INDIRECT("'"&H$14&"'!B2:B1000")=$B6) * (INDIRECT("'"&H$14&"'!C2:C1000")=$C6) ), 5, FALSE )=0, "", VLOOKUP( $A6, _xlfn._xlws.FILTER( INDIRECT("'"&H$14&"'!A2:E1000"), (INDIRECT("'"&H$14&"'!B2:B1000")=$B6) * (INDIRECT("'"&H$14&"'!C2:C1000")=$C6) ), 5, FALSE ) )} -> Enviado | I6: {=IF( VLOOKUP( $A6, _xlfn._xlws.FILTER( INDIRECT("'"&I$14&"'!A2:E1000"), (INDIRECT("'"&I$14&"'!B2:B1000")=$B6) * (INDIRECT("'"&I$14&"'!C2:C1000")=$C6) ), 5, FALSE )=0, "", VLOOKUP( $A6, _xlfn._xlws.FILTER( INDIRECT("'"&I$14&"'!A2:E1000"), (INDIRECT("'"&I$14&"'!B2:B1000")=$B6) * (INDIRECT("'"&I$14&"'!C2:C1000")=$C6) ), 5, FALSE ) )} -> Enviado | J6: {=IF( VLOOKUP( $A6, _xlfn._xlws.FILTER( INDIRECT("'"&J$14&"'!A2:E1000"), (INDIRECT("'"&J$14&"'!B2:B1000")=$B6) * (INDIRECT("'"&J$14&"'!C2:C1000")=$C6) ), 5, FALSE )=0, "", VLOOKUP( $A6, _xlfn._xlws.FILTER( INDIRECT("'"&J$14&"'!A2:E1000"), (INDIRECT("'"&J$14&"'!B2:B1000")=$B6) * (INDIRECT("'"&J$14&"'!C2:C1000")=$C6) ), 5, FALSE ) )} -> Enviado | K6: {=IF( VLOOKUP( $A6, _xlfn._xlws.FILTER( INDIRECT("'"&K$14&"'!A2:E1000"), (INDIRECT("'"&K$14&"'!B2:B1000")=$B6) * (INDIRECT("'"&K$14&"'!C2:C1000")=$C6) ), 5, FALSE )=0, "", VLOOKUP( $A6, _xlfn._xlws.FILTER( INDIRECT("'"&K$14&"'!A2:E1000"), (INDIRECT("'"&K$14&"'!B2:B1000")=$B6) * (INDIRECT("'"&K$14&"'!C2:C1000")=$C6) ), 5, FALSE ) )} -> Enviado | ... Q6: {=IF( VLOOKUP( $A6, _xlfn._xlws.FILTER( INDIRECT("'"&Q$14&"'!A2:E1000"), (INDIRECT("'"&Q$14&"'!B2:B1000")=$B6) * (INDIRECT("'"&Q$14&"'!C2:C1000")=$C6) ), 5, FALSE )=0, "", VLOOKUP( $A6, _xlfn._xlws.FILTER( INDIRECT("'"&Q$14&"'!A2:E1000"), (INDIRECT("'"&Q$14&"'!B2:B1000")=$B6) * (INDIRECT("'"&Q$14&"'!C2:C1000")=$C6) ), 5, FALSE ) )}
A7: Bianca | B7: Corbélia | C7: 1 | D7: {=IF( VLOOKUP( $A7, _xlfn._xlws.FILTER( INDIRECT("'"&D$14&"'!A2:E1000"), (INDIRECT("'"&D$14&"'!B2:B1000")=$B7) * (INDIRECT("'"&D$14&"'!C2:C1000")=$C7) ), 5, FALSE )=0, "", VLOOKUP( $A7, _xlfn._xlws.FILTER( INDIRECT("'"&D$14&"'!A2:E1000"), (INDIRECT("'"&D$14&"'!B2:B1000")=$B7) * (INDIRECT("'"&D$14&"'!C2:C1000")=$C7) ), 5, FALSE ) )} -> Enviado | E7: {=IF( VLOOKUP( $A7, _xlfn._xlws.FILTER( INDIRECT("'"&E$14&"'!A2:E1000"), (INDIRECT("'"&E$14&"'!B2:B1000")=$B7) * (INDIRECT("'"&E$14&"'!C2:C1000")=$C7) ), 5, FALSE )=0, "", VLOOKUP( $A7, _xlfn._xlws.FILTER( INDIRECT("'"&E$14&"'!A2:E1000"), (INDIRECT("'"&E$14&"'!B2:B1000")=$B7) * (INDIRECT("'"&E$14&"'!C2:C1000")=$C7) ), 5, FALSE ) )} -> Enviado | F7: {=IF( VLOOKUP( $A7, _xlfn._xlws.FILTER( INDIRECT("'"&F$14&"'!A2:E1000"), (INDIRECT("'"&F$14&"'!B2:B1000")=$B7) * (INDIRECT("'"&F$14&"'!C2:C1000")=$C7) ), 5, FALSE )=0, "", VLOOKUP( $A7, _xlfn._xlws.FILTER( INDIRECT("'"&F$14&"'!A2:E1000"), (INDIRECT("'"&F$14&"'!B2:B1000")=$B7) * (INDIRECT("'"&F$14&"'!C2:C1000")=$C7) ), 5, FALSE ) )} -> Enviado | G7: {=IF( VLOOKUP( $A7, _xlfn._xlws.FILTER( INDIRECT("'"&G$14&"'!A2:E1000"), (INDIRECT("'"&G$14&"'!B2:B1000")=$B7) * (INDIRECT("'"&G$14&"'!C2:C1000")=$C7) ), 5, FALSE )=0, "", VLOOKUP( $A7, _xlfn._xlws.FILTER( INDIRECT("'"&G$14&"'!A2:E1000"), (INDIRECT("'"&G$14&"'!B2:B1000")=$B7) * (INDIRECT("'"&G$14&"'!C2:C1000")=$C7) ), 5, FALSE ) )} -> Enviado | H7: {=IF( VLOOKUP( $A7, _xlfn._xlws.FILTER( INDIRECT("'"&H$14&"'!A2:E1000"), (INDIRECT("'"&H$14&"'!B2:B1000")=$B7) * (INDIRECT("'"&H$14&"'!C2:C1000")=$C7) ), 5, FALSE )=0, "", VLOOKUP( $A7, _xlfn._xlws.FILTER( INDIRECT("'"&H$14&"'!A2:E1000"), (INDIRECT("'"&H$14&"'!B2:B1000")=$B7) * (INDIRECT("'"&H$14&"'!C2:C1000")=$C7) ), 5, FALSE ) )} -> Enviado | I7: {=IF( VLOOKUP( $A7, _xlfn._xlws.FILTER( INDIRECT("'"&I$14&"'!A2:E1000"), (INDIRECT("'"&I$14&"'!B2:B1000")=$B7) * (INDIRECT("'"&I$14&"'!C2:C1000")=$C7) ), 5, FALSE )=0, "", VLOOKUP( $A7, _xlfn._xlws.FILTER( INDIRECT("'"&I$14&"'!A2:E1000"), (INDIRECT("'"&I$14&"'!B2:B1000")=$B7) * (INDIRECT("'"&I$14&"'!C2:C1000")=$C7) ), 5, FALSE ) )} -> Enviado | J7: {=IF( VLOOKUP( $A7, _xlfn._xlws.FILTER( INDIRECT("'"&J$14&"'!A2:E1000"), (INDIRECT("'"&J$14&"'!B2:B1000")=$B7) * (INDIRECT("'"&J$14&"'!C2:C1000")=$C7) ), 5, FALSE )=0, "", VLOOKUP( $A7, _xlfn._xlws.FILTER( INDIRECT("'"&J$14&"'!A2:E1000"), (INDIRECT("'"&J$14&"'!B2:B1000")=$B7) * (INDIRECT("'"&J$14&"'!C2:C1000")=$C7) ), 5, FALSE ) )} -> Enviado | K7: {=IF( VLOOKUP( $A7, _xlfn._xlws.FILTER( INDIRECT("'"&K$14&"'!A2:E1000"), (INDIRECT("'"&K$14&"'!B2:B1000")=$B7) * (INDIRECT("'"&K$14&"'!C2:C1000")=$C7) ), 5, FALSE )=0, "", VLOOKUP( $A7, _xlfn._xlws.FILTER( INDIRECT("'"&K$14&"'!A2:E1000"), (INDIRECT("'"&K$14&"'!B2:B1000")=$B7) * (INDIRECT("'"&K$14&"'!C2:C1000")=$C7) ), 5, FALSE ) )} -> Enviado | ... Q7: {=IF( VLOOKUP( $A7, _xlfn._xlws.FILTER( INDIRECT("'"&Q$14&"'!A2:E1000"), (INDIRECT("'"&Q$14&"'!B2:B1000")=$B7) * (INDIRECT("'"&Q$14&"'!C2:C1000")=$C7) ), 5, FALSE )=0, "", VLOOKUP( $A7, _xlfn._xlws.FILTER( INDIRECT("'"&Q$14&"'!A2:E1000"), (INDIRECT("'"&Q$14&"'!B2:B1000")=$B7) * (INDIRECT("'"&Q$14&"'!C2:C1000")=$C7) ), 5, FALSE ) )}
A8: Bianca | B8: Diamante do Sul | C8: 1 | D8: {=IF( VLOOKUP( $A8, _xlfn._xlws.FILTER( INDIRECT("'"&D$14&"'!A2:E1000"), (INDIRECT("'"&D$14&"'!B2:B1000")=$B8) * (INDIRECT("'"&D$14&"'!C2:C1000")=$C8) ), 5, FALSE )=0, "", VLOOKUP( $A8, _xlfn._xlws.FILTER( INDIRECT("'"&D$14&"'!A2:E1000"), (INDIRECT("'"&D$14&"'!B2:B1000")=$B8) * (INDIRECT("'"&D$14&"'!C2:C1000")=$C8) ), 5, FALSE ) )} -> Enviado | E8: {=IF( VLOOKUP( $A8, _xlfn._xlws.FILTER( INDIRECT("'"&E$14&"'!A2:E1000"), (INDIRECT("'"&E$14&"'!B2:B1000")=$B8) * (INDIRECT("'"&E$14&"'!C2:C1000")=$C8) ), 5, FALSE )=0, "", VLOOKUP( $A8, _xlfn._xlws.FILTER( INDIRECT("'"&E$14&"'!A2:E1000"), (INDIRECT("'"&E$14&"'!B2:B1000")=$B8) * (INDIRECT("'"&E$14&"'!C2:C1000")=$C8) ), 5, FALSE ) )} -> Enviado | F8: {=IF( VLOOKUP( $A8, _xlfn._xlws.FILTER( INDIRECT("'"&F$14&"'!A2:E1000"), (INDIRECT("'"&F$14&"'!B2:B1000")=$B8) * (INDIRECT("'"&F$14&"'!C2:C1000")=$C8) ), 5, FALSE )=0, "", VLOOKUP( $A8, _xlfn._xlws.FILTER( INDIRECT("'"&F$14&"'!A2:E1000"), (INDIRECT("'"&F$14&"'!B2:B1000")=$B8) * (INDIRECT("'"&F$14&"'!C2:C1000")=$C8) ), 5, FALSE ) )} -> Enviado | G8: {=IF( VLOOKUP( $A8, _xlfn._xlws.FILTER( INDIRECT("'"&G$14&"'!A2:E1000"), (INDIRECT("'"&G$14&"'!B2:B1000")=$B8) * (INDIRECT("'"&G$14&"'!C2:C1000")=$C8) ), 5, FALSE )=0, "", VLOOKUP( $A8, _xlfn._xlws.FILTER( INDIRECT("'"&G$14&"'!A2:E1000"), (INDIRECT("'"&G$14&"'!B2:B1000")=$B8) * (INDIRECT("'"&G$14&"'!C2:C1000")=$C8) ), 5, FALSE ) )} -> Enviado | H8: {=IF( VLOOKUP( $A8, _xlfn._xlws.FILTER( INDIRECT("'"&H$14&"'!A2:E1000"), (INDIRECT("'"&H$14&"'!B2:B1000")=$B8) * (INDIRECT("'"&H$14&"'!C2:C1000")=$C8) ), 5, FALSE )=0, "", VLOOKUP( $A8, _xlfn._xlws.FILTER( INDIRECT("'"&H$14&"'!A2:E1000"), (INDIRECT("'"&H$14&"'!B2:B1000")=$B8) * (INDIRECT("'"&H$14&"'!C2:C1000")=$C8) ), 5, FALSE ) )} -> Enviado | I8: {=IF( VLOOKUP( $A8, _xlfn._xlws.FILTER( INDIRECT("'"&I$14&"'!A2:E1000"), (INDIRECT("'"&I$14&"'!B2:B1000")=$B8) * (INDIRECT("'"&I$14&"'!C2:C1000")=$C8) ), 5, FALSE )=0, "", VLOOKUP( $A8, _xlfn._xlws.FILTER( INDIRECT("'"&I$14&"'!A2:E1000"), (INDIRECT("'"&I$14&"'!B2:B1000")=$B8) * (INDIRECT("'"&I$14&"'!C2:C1000")=$C8) ), 5, FALSE ) )} -> Enviado | J8: {=IF( VLOOKUP( $A8, _xlfn._xlws.FILTER( INDIRECT("'"&J$14&"'!A2:E1000"), (INDIRECT("'"&J$14&"'!B2:B1000")=$B8) * (INDIRECT("'"&J$14&"'!C2:C1000")=$C8) ), 5, FALSE )=0, "", VLOOKUP( $A8, _xlfn._xlws.FILTER( INDIRECT("'"&J$14&"'!A2:E1000"), (INDIRECT("'"&J$14&"'!B2:B1000")=$B8) * (INDIRECT("'"&J$14&"'!C2:C1000")=$C8) ), 5, FALSE ) )} -> Enviado | K8: {=IF( VLOOKUP( $A8, _xlfn._xlws.FILTER( INDIRECT("'"&K$14&"'!A2:E1000"), (INDIRECT("'"&K$14&"'!B2:B1000")=$B8) * (INDIRECT("'"&K$14&"'!C2:C1000")=$C8) ), 5, FALSE )=0, "", VLOOKUP( $A8, _xlfn._xlws.FILTER( INDIRECT("'"&K$14&"'!A2:E1000"), (INDIRECT("'"&K$14&"'!B2:B1000")=$B8) * (INDIRECT("'"&K$14&"'!C2:C1000")=$C8) ), 5, FALSE ) )} -> Enviado | ... Q8: {=IF( VLOOKUP( $A8, _xlfn._xlws.FILTER( INDIRECT("'"&Q$14&"'!A2:E1000"), (INDIRECT("'"&Q$14&"'!B2:B1000")=$B8) * (INDIRECT("'"&Q$14&"'!C2:C1000")=$C8) ), 5, FALSE )=0, "", VLOOKUP( $A8, _xlfn._xlws.FILTER( INDIRECT("'"&Q$14&"'!A2:E1000"), (INDIRECT("'"&Q$14&"'!B2:B1000")=$B8) * (INDIRECT("'"&Q$14&"'!C2:C1000")=$C8) ), 5, FALSE ) )}
A9: Bianca | B9: Guaraniacu | C9: 1 | D9: {=IF( VLOOKUP( $A9, _xlfn._xlws.FILTER( INDIRECT("'"&D$14&"'!A2:E1000"), (INDIRECT("'"&D$14&"'!B2:B1000")=$B9) * (INDIRECT("'"&D$14&"'!C2:C1000")=$C9) ), 5, FALSE )=0, "", VLOOKUP( $A9, _xlfn._xlws.FILTER( INDIRECT("'"&D$14&"'!A2:E1000"), (INDIRECT("'"&D$14&"'!B2:B1000")=$B9) * (INDIRECT("'"&D$14&"'!C2:C1000")=$C9) ), 5, FALSE ) )} -> Enviado | E9: {=IF( VLOOKUP( $A9, _xlfn._xlws.FILTER( INDIRECT("'"&E$14&"'!A2:E1000"), (INDIRECT("'"&E$14&"'!B2:B1000")=$B9) * (INDIRECT("'"&E$14&"'!C2:C1000")=$C9) ), 5, FALSE )=0, "", VLOOKUP( $A9, _xlfn._xlws.FILTER( INDIRECT("'"&E$14&"'!A2:E1000"), (INDIRECT("'"&E$14&"'!B2:B1000")=$B9) * (INDIRECT("'"&E$14&"'!C2:C1000")=$C9) ), 5, FALSE ) )} -> Enviado | F9: {=IF( VLOOKUP( $A9, _xlfn._xlws.FILTER( INDIRECT("'"&F$14&"'!A2:E1000"), (INDIRECT("'"&F$14&"'!B2:B1000")=$B9) * (INDIRECT("'"&F$14&"'!C2:C1000")=$C9) ), 5, FALSE )=0, "", VLOOKUP( $A9, _xlfn._xlws.FILTER( INDIRECT("'"&F$14&"'!A2:E1000"), (INDIRECT("'"&F$14&"'!B2:B1000")=$B9) * (INDIRECT("'"&F$14&"'!C2:C1000")=$C9) ), 5, FALSE ) )} -> Enviado | G9: {=IF( VLOOKUP( $A9, _xlfn._xlws.FILTER( INDIRECT("'"&G$14&"'!A2:E1000"), (INDIRECT("'"&G$14&"'!B2:B1000")=$B9) * (INDIRECT("'"&G$14&"'!C2:C1000")=$C9) ), 5, FALSE )=0, "", VLOOKUP( $A9, _xlfn._xlws.FILTER( INDIRECT("'"&G$14&"'!A2:E1000"), (INDIRECT("'"&G$14&"'!B2:B1000")=$B9) * (INDIRECT("'"&G$14&"'!C2:C1000")=$C9) ), 5, FALSE ) )} -> Enviado | H9: {=IF( VLOOKUP( $A9, _xlfn._xlws.FILTER( INDIRECT("'"&H$14&"'!A2:E1000"), (INDIRECT("'"&H$14&"'!B2:B1000")=$B9) * (INDIRECT("'"&H$14&"'!C2:C1000")=$C9) ), 5, FALSE )=0, "", VLOOKUP( $A9, _xlfn._xlws.FILTER( INDIRECT("'"&H$14&"'!A2:E1000"), (INDIRECT("'"&H$14&"'!B2:B1000")=$B9) * (INDIRECT("'"&H$14&"'!C2:C1000")=$C9) ), 5, FALSE ) )} -> Enviado | I9: {=IF( VLOOKUP( $A9, _xlfn._xlws.FILTER( INDIRECT("'"&I$14&"'!A2:E1000"), (INDIRECT("'"&I$14&"'!B2:B1000")=$B9) * (INDIRECT("'"&I$14&"'!C2:C1000")=$C9) ), 5, FALSE )=0, "", VLOOKUP( $A9, _xlfn._xlws.FILTER( INDIRECT("'"&I$14&"'!A2:E1000"), (INDIRECT("'"&I$14&"'!B2:B1000")=$B9) * (INDIRECT("'"&I$14&"'!C2:C1000")=$C9) ), 5, FALSE ) )} -> Enviado | J9: {=IF( VLOOKUP( $A9, _xlfn._xlws.FILTER( INDIRECT("'"&J$14&"'!A2:E1000"), (INDIRECT("'"&J$14&"'!B2:B1000")=$B9) * (INDIRECT("'"&J$14&"'!C2:C1000")=$C9) ), 5, FALSE )=0, "", VLOOKUP( $A9, _xlfn._xlws.FILTER( INDIRECT("'"&J$14&"'!A2:E1000"), (INDIRECT("'"&J$14&"'!B2:B1000")=$B9) * (INDIRECT("'"&J$14&"'!C2:C1000")=$C9) ), 5, FALSE ) )} -> Enviado | K9: {=IF( VLOOKUP( $A9, _xlfn._xlws.FILTER( INDIRECT("'"&K$14&"'!A2:E1000"), (INDIRECT("'"&K$14&"'!B2:B1000")=$B9) * (INDIRECT("'"&K$14&"'!C2:C1000")=$C9) ), 5, FALSE )=0, "", VLOOKUP( $A9, _xlfn._xlws.FILTER( INDIRECT("'"&K$14&"'!A2:E1000"), (INDIRECT("'"&K$14&"'!B2:B1000")=$B9) * (INDIRECT("'"&K$14&"'!C2:C1000")=$C9) ), 5, FALSE ) )} -> Enviado | ... Q9: {=IF( VLOOKUP( $A9, _xlfn._xlws.FILTER( INDIRECT("'"&Q$14&"'!A2:E1000"), (INDIRECT("'"&Q$14&"'!B2:B1000")=$B9) * (INDIRECT("'"&Q$14&"'!C2:C1000")=$C9) ), 5, FALSE )=0, "", VLOOKUP( $A9, _xlfn._xlws.FILTER( INDIRECT("'"&Q$14&"'!A2:E1000"), (INDIRECT("'"&Q$14&"'!B2:B1000")=$B9) * (INDIRECT("'"&Q$14&"'!C2:C1000")=$C9) ), 5, FALSE ) )}
A10: Bianca | B10: Ibema | C10: 1 | D10: {=IF( VLOOKUP( $A10, _xlfn._xlws.FILTER( INDIRECT("'"&D$14&"'!A2:E1000"), (INDIRECT("'"&D$14&"'!B2:B1000")=$B10) * (INDIRECT("'"&D$14&"'!C2:C1000")=$C10) ), 5, FALSE )=0, "", VLOOKUP( $A10, _xlfn._xlws.FILTER( INDIRECT("'"&D$14&"'!A2:E1000"), (INDIRECT("'"&D$14&"'!B2:B1000")=$B10) * (INDIRECT("'"&D$14&"'!C2:C1000")=$C10) ), 5, FALSE ) )} -> Enviado | E10: {=IF( VLOOKUP( $A10, _xlfn._xlws.FILTER( INDIRECT("'"&E$14&"'!A2:E1000"), (INDIRECT("'"&E$14&"'!B2:B1000")=$B10) * (INDIRECT("'"&E$14&"'!C2:C1000")=$C10) ), 5, FALSE )=0, "", VLOOKUP( $A10, _xlfn._xlws.FILTER( INDIRECT("'"&E$14&"'!A2:E1000"), (INDIRECT("'"&E$14&"'!B2:B1000")=$B10) * (INDIRECT("'"&E$14&"'!C2:C1000")=$C10) ), 5, FALSE ) )} -> Enviado | F10: {=IF( VLOOKUP( $A10, _xlfn._xlws.FILTER( INDIRECT("'"&F$14&"'!A2:E1000"), (INDIRECT("'"&F$14&"'!B2:B1000")=$B10) * (INDIRECT("'"&F$14&"'!C2:C1000")=$C10) ), 5, FALSE )=0, "", VLOOKUP( $A10, _xlfn._xlws.FILTER( INDIRECT("'"&F$14&"'!A2:E1000"), (INDIRECT("'"&F$14&"'!B2:B1000")=$B10) * (INDIRECT("'"&F$14&"'!C2:C1000")=$C10) ), 5, FALSE ) )} -> Enviado | G10: {=IF( VLOOKUP( $A10, _xlfn._xlws.FILTER( INDIRECT("'"&G$14&"'!A2:E1000"), (INDIRECT("'"&G$14&"'!B2:B1000")=$B10) * (INDIRECT("'"&G$14&"'!C2:C1000")=$C10) ), 5, FALSE )=0, "", VLOOKUP( $A10, _xlfn._xlws.FILTER( INDIRECT("'"&G$14&"'!A2:E1000"), (INDIRECT("'"&G$14&"'!B2:B1000")=$B10) * (INDIRECT("'"&G$14&"'!C2:C1000")=$C10) ), 5, FALSE ) )} -> Enviado | H10: {=IF( VLOOKUP( $A10, _xlfn._xlws.FILTER( INDIRECT("'"&H$14&"'!A2:E1000"), (INDIRECT("'"&H$14&"'!B2:B1000")=$B10) * (INDIRECT("'"&H$14&"'!C2:C1000")=$C10) ), 5, FALSE )=0, "", VLOOKUP( $A10, _xlfn._xlws.FILTER( INDIRECT("'"&H$14&"'!A2:E1000"), (INDIRECT("'"&H$14&"'!B2:B1000")=$B10) * (INDIRECT("'"&H$14&"'!C2:C1000")=$C10) ), 5, FALSE ) )} -> Enviado | I10: {=IF( VLOOKUP( $A10, _xlfn._xlws.FILTER( INDIRECT("'"&I$14&"'!A2:E1000"), (INDIRECT("'"&I$14&"'!B2:B1000")=$B10) * (INDIRECT("'"&I$14&"'!C2:C1000")=$C10) ), 5, FALSE )=0, "", VLOOKUP( $A10, _xlfn._xlws.FILTER( INDIRECT("'"&I$14&"'!A2:E1000"), (INDIRECT("'"&I$14&"'!B2:B1000")=$B10) * (INDIRECT("'"&I$14&"'!C2:C1000")=$C10) ), 5, FALSE ) )} -> Enviado | J10: {=IF( VLOOKUP( $A10, _xlfn._xlws.FILTER( INDIRECT("'"&J$14&"'!A2:E1000"), (INDIRECT("'"&J$14&"'!B2:B1000")=$B10) * (INDIRECT("'"&J$14&"'!C2:C1000")=$C10) ), 5, FALSE )=0, "", VLOOKUP( $A10, _xlfn._xlws.FILTER( INDIRECT("'"&J$14&"'!A2:E1000"), (INDIRECT("'"&J$14&"'!B2:B1000")=$B10) * (INDIRECT("'"&J$14&"'!C2:C1000")=$C10) ), 5, FALSE ) )} -> Enviado | K10: {=IF( VLOOKUP( $A10, _xlfn._xlws.FILTER( INDIRECT("'"&K$14&"'!A2:E1000"), (INDIRECT("'"&K$14&"'!B2:B1000")=$B10) * (INDIRECT("'"&K$14&"'!C2:C1000")=$C10) ), 5, FALSE )=0, "", VLOOKUP( $A10, _xlfn._xlws.FILTER( INDIRECT("'"&K$14&"'!A2:E1000"), (INDIRECT("'"&K$14&"'!B2:B1000")=$B10) * (INDIRECT("'"&K$14&"'!C2:C1000")=$C10) ), 5, FALSE ) )} -> Enviado | ... Q10: {=IF( VLOOKUP( $A10, _xlfn._xlws.FILTER( INDIRECT("'"&Q$14&"'!A2:E1000"), (INDIRECT("'"&Q$14&"'!B2:B1000")=$B10) * (INDIRECT("'"&Q$14&"'!C2:C1000")=$C10) ), 5, FALSE )=0, "", VLOOKUP( $A10, _xlfn._xlws.FILTER( INDIRECT("'"&Q$14&"'!A2:E1000"), (INDIRECT("'"&Q$14&"'!B2:B1000")=$B10) * (INDIRECT("'"&Q$14&"'!C2:C1000")=$C10) ), 5, FALSE ) )}
A11: Bianca | B11: Iguatu | C11: 1 | D11: {=IF( VLOOKUP( $A11, _xlfn._xlws.FILTER( INDIRECT("'"&D$14&"'!A2:E1000"), (INDIRECT("'"&D$14&"'!B2:B1000")=$B11) * (INDIRECT("'"&D$14&"'!C2:C1000")=$C11) ), 5, FALSE )=0, "", VLOOKUP( $A11, _xlfn._xlws.FILTER( INDIRECT("'"&D$14&"'!A2:E1000"), (INDIRECT("'"&D$14&"'!B2:B1000")=$B11) * (INDIRECT("'"&D$14&"'!C2:C1000")=$C11) ), 5, FALSE ) )} -> Enviado | E11: {=IF( VLOOKUP( $A11, _xlfn._xlws.FILTER( INDIRECT("'"&E$14&"'!A2:E1000"), (INDIRECT("'"&E$14&"'!B2:B1000")=$B11) * (INDIRECT("'"&E$14&"'!C2:C1000")=$C11) ), 5, FALSE )=0, "", VLOOKUP( $A11, _xlfn._xlws.FILTER( INDIRECT("'"&E$14&"'!A2:E1000"), (INDIRECT("'"&E$14&"'!B2:B1000")=$B11) * (INDIRECT("'"&E$14&"'!C2:C1000")=$C11) ), 5, FALSE ) )} -> Enviado | F11: {=IF( VLOOKUP( $A11, _xlfn._xlws.FILTER( INDIRECT("'"&F$14&"'!A2:E1000"), (INDIRECT("'"&F$14&"'!B2:B1000")=$B11) * (INDIRECT("'"&F$14&"'!C2:C1000")=$C11) ), 5, FALSE )=0, "", VLOOKUP( $A11, _xlfn._xlws.FILTER( INDIRECT("'"&F$14&"'!A2:E1000"), (INDIRECT("'"&F$14&"'!B2:B1000")=$B11) * (INDIRECT("'"&F$14&"'!C2:C1000")=$C11) ), 5, FALSE ) )} -> Enviado | G11: {=IF( VLOOKUP( $A11, _xlfn._xlws.FILTER( INDIRECT("'"&G$14&"'!A2:E1000"), (INDIRECT("'"&G$14&"'!B2:B1000")=$B11) * (INDIRECT("'"&G$14&"'!C2:C1000")=$C11) ), 5, FALSE )=0, "", VLOOKUP( $A11, _xlfn._xlws.FILTER( INDIRECT("'"&G$14&"'!A2:E1000"), (INDIRECT("'"&G$14&"'!B2:B1000")=$B11) * (INDIRECT("'"&G$14&"'!C2:C1000")=$C11) ), 5, FALSE ) )} -> Enviado | H11: {=IF( VLOOKUP( $A11, _xlfn._xlws.FILTER( INDIRECT("'"&H$14&"'!A2:E1000"), (INDIRECT("'"&H$14&"'!B2:B1000")=$B11) * (INDIRECT("'"&H$14&"'!C2:C1000")=$C11) ), 5, FALSE )=0, "", VLOOKUP( $A11, _xlfn._xlws.FILTER( INDIRECT("'"&H$14&"'!A2:E1000"), (INDIRECT("'"&H$14&"'!B2:B1000")=$B11) * (INDIRECT("'"&H$14&"'!C2:C1000")=$C11) ), 5, FALSE ) )} -> Enviado | I11: {=IF( VLOOKUP( $A11, _xlfn._xlws.FILTER( INDIRECT("'"&I$14&"'!A2:E1000"), (INDIRECT("'"&I$14&"'!B2:B1000")=$B11) * (INDIRECT("'"&I$14&"'!C2:C1000")=$C11) ), 5, FALSE )=0, "", VLOOKUP( $A11, _xlfn._xlws.FILTER( INDIRECT("'"&I$14&"'!A2:E1000"), (INDIRECT("'"&I$14&"'!B2:B1000")=$B11) * (INDIRECT("'"&I$14&"'!C2:C1000")=$C11) ), 5, FALSE ) )} -> Enviado | J11: {=IF( VLOOKUP( $A11, _xlfn._xlws.FILTER( INDIRECT("'"&J$14&"'!A2:E1000"), (INDIRECT("'"&J$14&"'!B2:B1000")=$B11) * (INDIRECT("'"&J$14&"'!C2:C1000")=$C11) ), 5, FALSE )=0, "", VLOOKUP( $A11, _xlfn._xlws.FILTER( INDIRECT("'"&J$14&"'!A2:E1000"), (INDIRECT("'"&J$14&"'!B2:B1000")=$B11) * (INDIRECT("'"&J$14&"'!C2:C1000")=$C11) ), 5, FALSE ) )} -> Enviado | K11: {=IF( VLOOKUP( $A11, _xlfn._xlws.FILTER( INDIRECT("'"&K$14&"'!A2:E1000"), (INDIRECT("'"&K$14&"'!B2:B1000")=$B11) * (INDIRECT("'"&K$14&"'!C2:C1000")=$C11) ), 5, FALSE )=0, "", VLOOKUP( $A11, _xlfn._xlws.FILTER( INDIRECT("'"&K$14&"'!A2:E1000"), (INDIRECT("'"&K$14&"'!B2:B1000")=$B11) * (INDIRECT("'"&K$14&"'!C2:C1000")=$C11) ), 5, FALSE ) )} -> Enviado | ... Q11: {=IF( VLOOKUP( $A11, _xlfn._xlws.FILTER( INDIRECT("'"&Q$14&"'!A2:E1000"), (INDIRECT("'"&Q$14&"'!B2:B1000")=$B11) * (INDIRECT("'"&Q$14&"'!C2:C1000")=$C11) ), 5, FALSE )=0, "", VLOOKUP( $A11, _xlfn._xlws.FILTER( INDIRECT("'"&Q$14&"'!A2:E1000"), (INDIRECT("'"&Q$14&"'!B2:B1000")=$B11) * (INDIRECT("'"&Q$14&"'!C2:C1000")=$C11) ), 5, FALSE ) )}
A12: Bianca | B12: Tres Barras do Parana | C12: 1 | D12: {=IF( VLOOKUP( $A12, _xlfn._xlws.FILTER( INDIRECT("'"&D$14&"'!A2:E1000"), (INDIRECT("'"&D$14&"'!B2:B1000")=$B12) * (INDIRECT("'"&D$14&"'!C2:C1000")=$C12) ), 5, FALSE )=0, "", VLOOKUP( $A12, _xlfn._xlws.FILTER( INDIRECT("'"&D$14&"'!A2:E1000"), (INDIRECT("'"&D$14&"'!B2:B1000")=$B12) * (INDIRECT("'"&D$14&"'!C2:C1000")=$C12) ), 5, FALSE ) )} -> Enviado | E12: {=IF( VLOOKUP( $A12, _xlfn._xlws.FILTER( INDIRECT("'"&E$14&"'!A2:E1000"), (INDIRECT("'"&E$14&"'!B2:B1000")=$B12) * (INDIRECT("'"&E$14&"'!C2:C1000")=$C12) ), 5, FALSE )=0, "", VLOOKUP( $A12, _xlfn._xlws.FILTER( INDIRECT("'"&E$14&"'!A2:E1000"), (INDIRECT("'"&E$14&"'!B2:B1000")=$B12) * (INDIRECT("'"&E$14&"'!C2:C1000")=$C12) ), 5, FALSE ) )} -> Enviado | F12: {=IF( VLOOKUP( $A12, _xlfn._xlws.FILTER( INDIRECT("'"&F$14&"'!A2:E1000"), (INDIRECT("'"&F$14&"'!B2:B1000")=$B12) * (INDIRECT("'"&F$14&"'!C2:C1000")=$C12) ), 5, FALSE )=0, "", VLOOKUP( $A12, _xlfn._xlws.FILTER( INDIRECT("'"&F$14&"'!A2:E1000"), (INDIRECT("'"&F$14&"'!B2:B1000")=$B12) * (INDIRECT("'"&F$14&"'!C2:C1000")=$C12) ), 5, FALSE ) )} -> Enviado | G12: {=IF( VLOOKUP( $A12, _xlfn._xlws.FILTER( INDIRECT("'"&G$14&"'!A2:E1000"), (INDIRECT("'"&G$14&"'!B2:B1000")=$B12) * (INDIRECT("'"&G$14&"'!C2:C1000")=$C12) ), 5, FALSE )=0, "", VLOOKUP( $A12, _xlfn._xlws.FILTER( INDIRECT("'"&G$14&"'!A2:E1000"), (INDIRECT("'"&G$14&"'!B2:B1000")=$B12) * (INDIRECT("'"&G$14&"'!C2:C1000")=$C12) ), 5, FALSE ) )} -> Enviado | H12: {=IF( VLOOKUP( $A12, _xlfn._xlws.FILTER( INDIRECT("'"&H$14&"'!A2:E1000"), (INDIRECT("'"&H$14&"'!B2:B1000")=$B12) * (INDIRECT("'"&H$14&"'!C2:C1000")=$C12) ), 5, FALSE )=0, "", VLOOKUP( $A12, _xlfn._xlws.FILTER( INDIRECT("'"&H$14&"'!A2:E1000"), (INDIRECT("'"&H$14&"'!B2:B1000")=$B12) * (INDIRECT("'"&H$14&"'!C2:C1000")=$C12) ), 5, FALSE ) )} -> Enviado | I12: {=IF( VLOOKUP( $A12, _xlfn._xlws.FILTER( INDIRECT("'"&I$14&"'!A2:E1000"), (INDIRECT("'"&I$14&"'!B2:B1000")=$B12) * (INDIRECT("'"&I$14&"'!C2:C1000")=$C12) ), 5, FALSE )=0, "", VLOOKUP( $A12, _xlfn._xlws.FILTER( INDIRECT("'"&I$14&"'!A2:E1000"), (INDIRECT("'"&I$14&"'!B2:B1000")=$B12) * (INDIRECT("'"&I$14&"'!C2:C1000")=$C12) ), 5, FALSE ) )} -> Enviado | J12: {=IF( VLOOKUP( $A12, _xlfn._xlws.FILTER( INDIRECT("'"&J$14&"'!A2:E1000"), (INDIRECT("'"&J$14&"'!B2:B1000")=$B12) * (INDIRECT("'"&J$14&"'!C2:C1000")=$C12) ), 5, FALSE )=0, "", VLOOKUP( $A12, _xlfn._xlws.FILTER( INDIRECT("'"&J$14&"'!A2:E1000"), (INDIRECT("'"&J$14&"'!B2:B1000")=$B12) * (INDIRECT("'"&J$14&"'!C2:C1000")=$C12) ), 5, FALSE ) )} -> Enviado | K12: {=IF( VLOOKUP( $A12, _xlfn._xlws.FILTER( INDIRECT("'"&K$14&"'!A2:E1000"), (INDIRECT("'"&K$14&"'!B2:B1000")=$B12) * (INDIRECT("'"&K$14&"'!C2:C1000")=$C12) ), 5, FALSE )=0, "", VLOOKUP( $A12, _xlfn._xlws.FILTER( INDIRECT("'"&K$14&"'!A2:E1000"), (INDIRECT("'"&K$14&"'!B2:B1000")=$B12) * (INDIRECT("'"&K$14&"'!C2:C1000")=$C12) ), 5, FALSE ) )} -> Enviado | ... Q12: {=IF( VLOOKUP( $A12, _xlfn._xlws.FILTER( INDIRECT("'"&Q$14&"'!A2:E1000"), (INDIRECT("'"&Q$14&"'!B2:B1000")=$B12) * (INDIRECT("'"&Q$14&"'!C2:C1000")=$C12) ), 5, FALSE )=0, "", VLOOKUP( $A12, _xlfn._xlws.FILTER( INDIRECT("'"&Q$14&"'!A2:E1000"), (INDIRECT("'"&Q$14&"'!B2:B1000")=$B12) * (INDIRECT("'"&Q$14&"'!C2:C1000")=$C12) ), 5, FALSE ) )}
A14: Regional | B14: Municípios | C14: UVR | D14: 11.24 | E14: 12.24 | F14: 01.25 | G14: 02.25 | H14: 03.25 | I14: 04.25 | J14: 05.25 | K14: 06.25 | L14: 07.25 | M14: 08.25 | N14: 09.25 | O14: 10.25 | P14: 11.25 | Q14: 12.25
A15: Gabriel | B15: Altônia | C15: 1 | D15: {=IF( VLOOKUP( $A15, _xlfn._xlws.FILTER( INDIRECT("'"&D$14&"'!A2:E1000"), (INDIRECT("'"&D$14&"'!B2:B1000")=$B15) * (INDIRECT("'"&D$14&"'!C2:C1000")=$C15) ), 5, FALSE )=0, "", VLOOKUP( $A15, _xlfn._xlws.FILTER( INDIRECT("'"&D$14&"'!A2:E1000"), (INDIRECT("'"&D$14&"'!B2:B1000")=$B15) * (INDIRECT("'"&D$14&"'!C2:C1000")=$C15) ), 5, FALSE ) )} -> Enviado | E15: {=IF( VLOOKUP( $A15, _xlfn._xlws.FILTER( INDIRECT("'"&E$14&"'!A2:E1000"), (INDIRECT("'"&E$14&"'!B2:B1000")=$B15) * (INDIRECT("'"&E$14&"'!C2:C1000")=$C15) ), 5, FALSE )=0, "", VLOOKUP( $A15, _xlfn._xlws.FILTER( INDIRECT("'"&E$14&"'!A2:E1000"), (INDIRECT("'"&E$14&"'!B2:B1000")=$B15) * (INDIRECT("'"&E$14&"'!C2:C1000")=$C15) ), 5, FALSE ) )} -> Enviado | F15: {=IF( VLOOKUP( $A15, _xlfn._xlws.FILTER( INDIRECT("'"&F$14&"'!A2:E1000"), (INDIRECT("'"&F$14&"'!B2:B1000")=$B15) * (INDIRECT("'"&F$14&"'!C2:C1000")=$C15) ), 5, FALSE )=0, "", VLOOKUP( $A15, _xlfn._xlws.FILTER( INDIRECT("'"&F$14&"'!A2:E1000"), (INDIRECT("'"&F$14&"'!B2:B1000")=$B15) * (INDIRECT("'"&F$14&"'!C2:C1000")=$C15) ), 5, FALSE ) )} -> Enviado | G15: {=IF( VLOOKUP( $A15, _xlfn._xlws.FILTER( INDIRECT("'"&G$14&"'!A2:E1000"), (INDIRECT("'"&G$14&"'!B2:B1000")=$B15) * (INDIRECT("'"&G$14&"'!C2:C1000")=$C15) ), 5, FALSE )=0, "", VLOOKUP( $A15, _xlfn._xlws.FILTER( INDIRECT("'"&G$14&"'!A2:E1000"), (INDIRECT("'"&G$14&"'!B2:B1000")=$B15) * (INDIRECT("'"&G$14&"'!C2:C1000")=$C15) ), 5, FALSE ) )} -> Enviado | H15: {=IF( VLOOKUP( $A15, _xlfn._xlws.FILTER( INDIRECT("'"&H$14&"'!A2:E1000"), (INDIRECT("'"&H$14&"'!B2:B1000")=$B15) * (INDIRECT("'"&H$14&"'!C2:C1000")=$C15) ), 5, FALSE )=0, "", VLOOKUP( $A15, _xlfn._xlws.FILTER( INDIRECT("'"&H$14&"'!A2:E1000"), (INDIRECT("'"&H$14&"'!B2:B1000")=$B15) * (INDIRECT("'"&H$14&"'!C2:C1000")=$C15) ), 5, FALSE ) )} -> Enviado | I15: {=IF( VLOOKUP( $A15, _xlfn._xlws.FILTER( INDIRECT("'"&I$14&"'!A2:E1000"), (INDIRECT("'"&I$14&"'!B2:B1000")=$B15) * (INDIRECT("'"&I$14&"'!C2:C1000")=$C15) ), 5, FALSE )=0, "", VLOOKUP( $A15, _xlfn._xlws.FILTER( INDIRECT("'"&I$14&"'!A2:E1000"), (INDIRECT("'"&I$14&"'!B2:B1000")=$B15) * (INDIRECT("'"&I$14&"'!C2:C1000")=$C15) ), 5, FALSE ) )} -> Enviado | J15: {=IF( VLOOKUP( $A15, _xlfn._xlws.FILTER( INDIRECT("'"&J$14&"'!A2:E1000"), (INDIRECT("'"&J$14&"'!B2:B1000")=$B15) * (INDIRECT("'"&J$14&"'!C2:C1000")=$C15) ), 5, FALSE )=0, "", VLOOKUP( $A15, _xlfn._xlws.FILTER( INDIRECT("'"&J$14&"'!A2:E1000"), (INDIRECT("'"&J$14&"'!B2:B1000")=$B15) * (INDIRECT("'"&J$14&"'!C2:C1000")=$C15) ), 5, FALSE ) )} -> Enviado | K15: {=IF( VLOOKUP( $A15, _xlfn._xlws.FILTER( INDIRECT("'"&K$14&"'!A2:E1000"), (INDIRECT("'"&K$14&"'!B2:B1000")=$B15) * (INDIRECT("'"&K$14&"'!C2:C1000")=$C15) ), 5, FALSE )=0, "", VLOOKUP( $A15, _xlfn._xlws.FILTER( INDIRECT("'"&K$14&"'!A2:E1000"), (INDIRECT("'"&K$14&"'!B2:B1000")=$B15) * (INDIRECT("'"&K$14&"'!C2:C1000")=$C15) ), 5, FALSE ) )} -> Enviado | ... Q15: {=IF( VLOOKUP( $A15, _xlfn._xlws.FILTER( INDIRECT("'"&Q$14&"'!A2:E1000"), (INDIRECT("'"&Q$14&"'!B2:B1000")=$B15) * (INDIRECT("'"&Q$14&"'!C2:C1000")=$C15) ), 5, FALSE )=0, "", VLOOKUP( $A15, _xlfn._xlws.FILTER( INDIRECT("'"&Q$14&"'!A2:E1000"), (INDIRECT("'"&Q$14&"'!B2:B1000")=$B15) * (INDIRECT("'"&Q$14&"'!C2:C1000")=$C15) ), 5, FALSE ) )}
