Workbook

Sheet Resumo
A1: Categoria | B1: 01.25 | C1: 02.25 | D1: 03.25 | E1: 04.25 | F1: 05.25 | G1: 06.25 | H1: 07.25 | I1: 08.25 | J1: 09.25 | K1: 10.25 | L1: 11.25 | M1: 12.25 | N1: Total
A2: Enviado | B2: =COUNTIF(INDIRECT(B$1&"!E2:E1000"),$A2) -> 0 | C2: =COUNTIF(INDIRECT(C$1&"!E2:E1000"),$A2) -> 0 | D2: =COUNTIF(INDIRECT(D$1&"!E2:E1000"),$A2) -> 0 | E2: =COUNTIF(INDIRECT(E$1&"!E2:E1000"),$A2) -> 0 | F2: =COUNTIF(INDIRECT(F$1&"!E2:E1000"),$A2) -> 0 | G2: =COUNTIF(INDIRECT(G$1&"!E2:E1000"),$A2) -> 1 | H2: =COUNTIF(INDIRECT(H$1&"!E2:E1000"),$A2) -> 1 | I2: =COUNTIF(INDIRECT(I$1&"!E2:E1000"),$A2) -> 19 | ... M2: =COUNTIF(INDIRECT(M$1&"!E2:E1000"),$A2) -> 0 | N2: =SUM(B2:M2) -> 59
A3: Atrasado | B3: =COUNTIF(INDIRECT(B$1&"!E2:E1000"),$A3) -> 0 | C3: =COUNTIF(INDIRECT(C$1&"!E2:E1000"),$A3) -> 0 | D3: =COUNTIF(INDIRECT(D$1&"!E2:E1000"),$A3) -> 0 | E3: =COUNTIF(INDIRECT(E$1&"!E2:E1000"),$A3) -> 0 | F3: =COUNTIF(INDIRECT(F$1&"!E2:E1000"),$A3) -> 0 | G3: =COUNTIF(INDIRECT(G$1&"!E2:E1000"),$A3) -> 0 | H3: =COUNTIF(INDIRECT(H$1&"!E2:E1000"),$A3) -> 0 | I3: =COUNTIF(INDIRECT(I$1&"!E2:E1000"),$A3) -> 0 | ... M3: =COUNTIF(INDIRECT(M$1&"!E2:E1000"),$A3) -> 0 | N3: =SUM(B3:M3) -> 39
A4: Atrasado >= 2 | B4: =COUNTIF(INDIRECT(B$1&"!E2:E1000"),$A4) -> 0 | C4: =COUNTIF(INDIRECT(C$1&"!E2:E1000"),$A4) -> 0 | D4: =COUNTIF(INDIRECT(D$1&"!E2:E1000"),$A4) -> 0 | E4: =COUNTIF(INDIRECT(E$1&"!E2:E1000"),$A4) -> 0 | F4: =COUNTIF(INDIRECT(F$1&"!E2:E1000"),$A4) -> 0 | G4: =COUNTIF(INDIRECT(G$1&"!E2:E1000"),$A4) -> 0 | H4: =COUNTIF(INDIRECT(H$1&"!E2:E1000"),$A4) -> 0 | I4: =COUNTIF(INDIRECT(I$1&"!E2:E1000"),$A4) -> 19 | ... M4: =COUNTIF(INDIRECT(M$1&"!E2:E1000"),$A4) -> 0 | N4: =SUM(B4:M4) -> 59
A5: Duplicado | B5: =COUNTIF(INDIRECT(B$1&"!E2:E1000"),$A5) -> 0 | C5: =COUNTIF(INDIRECT(C$1&"!E2:E1000"),$A5) -> 0 | D5: =COUNTIF(INDIRECT(D$1&"!E2:E1000"),$A5) -> 0 | E5: =COUNTIF(INDIRECT(E$1&"!E2:E1000"),$A5) -> 0 | F5: =COUNTIF(INDIRECT(F$1&"!E2:E1000"),$A5) -> 0 | G5: =COUNTIF(INDIRECT(G$1&"!E2:E1000"),$A5) -> 0 | H5: =COUNTIF(INDIRECT(H$1&"!E2:E1000"),$A5) -> 0 | I5: =COUNTIF(INDIRECT(I$1&"!E2:E1000"),$A5) -> 1 | ... M5: =COUNTIF(INDIRECT(M$1&"!E2:E1000"),$A5) -> 0 | N5: =SUM(B5:M5) -> 1
A6: Outras Ocorrências | B6: =COUNTIF(INDIRECT(B$1&"!E2:E1000"),$A6) -> 0 | C6: =COUNTIF(INDIRECT(C$1&"!E2:E1000"),$A6) -> 0 | D6: =COUNTIF(INDIRECT(D$1&"!E2:E1000"),$A6) -> 0 | E6: =COUNTIF(INDIRECT(E$1&"!E2:E1000"),$A6) -> 0 | F6: =COUNTIF(INDIRECT(F$1&"!E2:E1000"),$A6) -> 0 | G6: =COUNTIF(INDIRECT(G$1&"!E2:E1000"),$A6) -> 0 | H6: =COUNTIF(INDIRECT(H$1&"!E2:E1000"),$A6) -> 0 | I6: =COUNTIF(INDIRECT(I$1&"!E2:E1000"),$A6) -> 2 | ... M6: =COUNTIF(INDIRECT(M$1&"!E2:E1000"),$A6) -> 2 | N6: =SUM(B6:M6) -> 10
A7: Sem Técnico | B7: =COUNTIF(INDIRECT(B$1&"!E2:E1000"),$A7) -> 46 | C7: =COUNTIF(INDIRECT(C$1&"!E2:E1000"),$A7) -> 46 | D7: =COUNTIF(INDIRECT(D$1&"!E2:E1000"),$A7) -> 46 | E7: =COUNTIF(INDIRECT(E$1&"!E2:E1000"),$A7) -> 46 | F7: =COUNTIF(INDIRECT(F$1&"!E2:E1000"),$A7) -> 46 | G7: =COUNTIF(INDIRECT(G$1&"!E2:E1000"),$A7) -> 45 | H7: =COUNTIF(INDIRECT(H$1&"!E2:E1000"),$A7) -> 45 | I7: =COUNTIF(INDIRECT(I$1&"!E2:E1000"),$A7) -> 5 | ... M7: =COUNTIF(INDIRECT(M$1&"!E2:E1000"),$A7) -> 5 | N7: =SUM(B7:M7) -> 345
A8: Total | B8: =SUM(B2:B7) -> 46 | C8: =SUM(C2:C7) -> 46 | D8: =SUM(D2:D7) -> 46 | E8: =SUM(E2:E7) -> 46 | F8: =SUM(F2:F7) -> 46 | G8: =SUM(G2:G7) -> 46 | H8: =SUM(H2:H7) -> 46 | I8: =SUM(I2:I7) -> 46 | ... M8: =SUM(M2:M7) -> 7 | N8: =SUM(B8:M8) -> 513
A11: Digite o Mês de Referência | C11: Mês de Referência | K11: Acumulado (Total) | R11: Resumo por Regional
A12: 08.25 | C12: Monitoramento (Envios) | K12: Monitoramento (Envios) | R12: Regional | T12: Conisul
C13: Regional | D13: Envi. | E13: Atra. | F13: Atra. >= 2 | G13: Dup. | H13: Out. Ocor. | I13: Sem Tec. | K13: Envi. | L13: Atra. | M13: Atra. >= 2 | N13: Dup. | O13: Out. Ocor. | P13: Sem Tec. | R13: =_xlfn.CONCAT("Envios - Mês de Referência - ", A12) -> Envios - Mês de Referência - 08.25
C14: Coripa | D14: {=IFERROR(ROWS(_xlfn._xlws.FILTER(INDIRECT($A$12&"!A2:E100"),(INDIRECT($A$12&"!A2:A100")=$C14)*(INDIRECT($A$12&"!E2:E100")="Enviado"))), 0)} -> 3 | E14: {=IFERROR(ROWS(_xlfn._xlws.FILTER(INDIRECT($A$12&"!A2:E100"),(INDIRECT($A$12&"!A2:A100")=$C14)*(INDIRECT($A$12&"!E2:E100")="Atrasado"))), 0)} -> 0 | F14: {=IFERROR(ROWS(_xlfn._xlws.FILTER(INDIRECT($A$12&"!A2:E100"),(INDIRECT($A$12&"!A2:A100")=$C14)*(INDIRECT($A$12&"!E2:E100")="Atrasado >= 2"))), 0)} -> 4 | G14: {=IFERROR(ROWS(_xlfn._xlws.FILTER(INDIRECT($A$12&"!A2:E100"),(INDIRECT($A$12&"!A2:A100")=$C14)*(INDIRECT($A$12&"!E2:E100")="Duplicado"))), 0)} -> 0 | H14: {=IFERROR(ROWS(_xlfn._xlws.FILTER(INDIRECT($A$12&"!A2:E100"),(INDIRECT($A$12&"!A2:A100")=$C14)*(INDIRECT($A$12&"!E2:E100")="Outras Ocorrências"))), 0)} -> 1 | I14: {=IFERROR(ROWS(_xlfn._xlws.FILTER(INDIRECT($A$12&"!A2:E100"),(INDIRECT($A$12&"!A2:A100")=$C14)*(INDIRECT($A$12&"!E2:E100")="Sem Técnico"))), 0)} -> 0 | K14: =COUNTIF(INDIRECT("Monitoramento!$D$2:$Q$15"), "Enviado") -> 12 | L14: =COUNTIF(INDIRECT("Monitoramento!$D$2:$Q$15"), "Atrasado") -> 11 | M14: =COUNTIF(INDIRECT("Monitoramento!$D$2:$Q$15"), "Atrasado >= 2") -> 21 | N14: =COUNTIF(INDIRECT("Monitoramento!$D$2:$Q$15"), "Duplicado") -> 0 | O14: =COUNTIF(INDIRECT("Monitoramento!$D$2:$Q$15"), "Outras Ocorrências") -> 5 | P14: =COUNTIF(INDIRECT("Monitoramento!$D$2:$Q$15"), "Sem Técnico") -> 84 | R14: Enviados | S14: =VLOOKUP($T$12,$C$14:$I$18,2, FALSE) -> 6 | T14: =S14/SUM($S$14:$S$19) -> 0.46153846
C15: Comafen | D15: {=IFERROR(ROWS(_xlfn._xlws.FILTER(INDIRECT($A$12&"!A2:E100"),(INDIRECT($A$12&"!A2:A100")=$C15)*(INDIRECT($A$12&"!E2:E100")="Enviado"))), 0)} -> 2 | E15: {=IFERROR(ROWS(_xlfn._xlws.FILTER(INDIRECT($A$12&"!A2:E100"),(INDIRECT($A$12&"!A2:A100")=$C15)*(INDIRECT($A$12&"!E2:E100")="Atrasado"))), 0)} -> 0 | F15: {=IFERROR(ROWS(_xlfn._xlws.FILTER(INDIRECT($A$12&"!A2:E100"),(INDIRECT($A$12&"!A2:A100")=$C15)*(INDIRECT($A$12&"!E2:E100")="Atrasado >= 2"))), 0)} -> 9 | G15: {=IFERROR(ROWS(_xlfn._xlws.FILTER(INDIRECT($A$12&"!A2:E100"),(INDIRECT($A$12&"!A2:A100")=$C15)*(INDIRECT($A$12&"!E2:E100")="Duplicado"))), 0)} -> 0 | H15: {=IFERROR(ROWS(_xlfn._xlws.FILTER(INDIRECT($A$12&"!A2:E100"),(INDIRECT($A$12&"!A2:A100")=$C15)*(INDIRECT($A$12&"!E2:E100")="Outras Ocorrências"))), 0)} -> 0 | I15: {=IFERROR(ROWS(_xlfn._xlws.FILTER(INDIRECT($A$12&"!A2:E100"),(INDIRECT($A$12&"!A2:A100")=$C15)*(INDIRECT($A$12&"!E2:E100")="Sem Técnico"))), 0)} -> 0 | K15: =COUNTIF(INDIRECT("Monitoramento!$D$18:$Q$31"), "Enviado") -> 19 | L15: =COUNTIF(INDIRECT("Monitoramento!$D$18:$Q$31"), "Atrasado") -> 11 | M15: =COUNTIF(INDIRECT("Monitoramento!$D$18:$Q$31"), "Atrasado >= 2") -> 14 | N15: =COUNTIF(INDIRECT("Monitoramento!$D$18:$Q$31"), "Duplicado") -> 0 | O15: =COUNTIF(INDIRECT("Monitoramento!$D$18:$Q$31"), "Outras Ocorrências") -> 5 | P15: =COUNTIF(INDIRECT("Monitoramento!$D$18:$Q$31"), "Sem Técnico") -> 84 | R15: Atrasados | S15: =VLOOKUP($T$12,$C$14:$I$18,3,FALSE) -> 0 | T15: =S15/SUM($S$14:$S$19) -> 0
C16: Cibax | D16: {=IFERROR(ROWS(_xlfn._xlws.FILTER(INDIRECT($A$12&"!A2:E100"),(INDIRECT($A$12&"!A2:A100")=$C16)*(INDIRECT($A$12&"!E2:E100")="Enviado"))), 0)} -> 8 | E16: {=IFERROR(ROWS(_xlfn._xlws.FILTER(INDIRECT($A$12&"!A2:E100"),(INDIRECT($A$12&"!A2:A100")=$C16)*(INDIRECT($A$12&"!E2:E100")="Atrasado"))), 0)} -> 0 | F16: {=IFERROR(ROWS(_xlfn._xlws.FILTER(INDIRECT($A$12&"!A2:E100"),(INDIRECT($A$12&"!A2:A100")=$C16)*(INDIRECT($A$12&"!E2:E100")="Atrasado >= 2"))), 0)} -> 1 | G16: {=IFERROR(ROWS(_xlfn._xlws.FILTER(INDIRECT($A$12&"!A2:E100"),(INDIRECT($A$12&"!A2:A100")=$C16)*(INDIRECT($A$12&"!E2:E100")="Duplicado"))), 0)} -> 0 | H16: {=IFERROR(ROWS(_xlfn._xlws.FILTER(INDIRECT($A$12&"!A2:E100"),(INDIRECT($A$12&"!A2:A100")=$C16)*(INDIRECT($A$12&"!E2:E100")="Outras Ocorrências"))), 0)} -> 1 | I16: {=IFERROR(ROWS(_xlfn._xlws.FILTER(INDIRECT($A$12&"!A2:E100"),(INDIRECT($A$12&"!A2:A100")=$C16)*(INDIRECT($A$12&"!E2:E100")="Sem Técnico"))), 0)} -> 0 | K16: =COUNTIF(INDIRECT("Monitoramento!$D$34:$Q$47"), "Enviado") -> 9 | L16: =COUNTIF(INDIRECT("Monitoramento!$D$34:$Q$47"), "Atrasado") -> 6 | M16: =COUNTIF(INDIRECT("Monitoramento!$D$34:$Q$47"), "Atrasado >= 2") -> 9 | N16: =COUNTIF(INDIRECT("Monitoramento!$D$34:$Q$47"), "Duplicado") -> 0 | O16: =COUNTIF(INDIRECT("Monitoramento!$D$34:$Q$47"), "Outras Ocorrências") -> 0 | P16: =COUNTIF(INDIRECT("Monitoramento!$D$34:$Q$47"), "Sem Técnico") -> 90 | R16: Atrasados >= 2 | S16: =VLOOKUP($T$12,$C$14:$I$18,4,FALSE) -> 5 | T16: =S16/SUM($S$14:$S$19) -> 0.38461538
C17: Cifra | D17: {=IFERROR(ROWS(_xlfn._xlws.FILTER(INDIRECT($A$12&"!A2:E100"),(INDIRECT($A$12&"!A2:A100")=$C17)*(INDIRECT($A$12&"!E2:E100")="Enviado"))), 0)} -> 0 | E17: {=IFERROR(ROWS(_xlfn._xlws.FILTER(INDIRECT($A$12&"!A2:E100"),(INDIRECT($A$12&"!A2:A100")=$C17)*(INDIRECT($A$12&"!E2:E100")="Atrasado"))), 0)} -> 0 | F17: {=IFERROR(ROWS(_xlfn._xlws.FILTER(INDIRECT($A$12&"!A2:E100"),(INDIRECT($A$12&"!A2:A100")=$C17)*(INDIRECT($A$12&"!E2:E100")="Atrasado >= 2"))), 0)} -> 0 | G17: {=IFERROR(ROWS(_xlfn._xlws.FILTER(INDIRECT($A$12&"!A2:E100"),(INDIRECT($A$12&"!A2:A100")=$C17)*(INDIRECT($A$12&"!E2:E100")="Duplicado"))), 0)} -> 0 | H17: {=IFERROR(ROWS(_xlfn._xlws.FILTER(INDIRECT($A$12&"!A2:E100"),(INDIRECT($A$12&"!A2:A100")=$C17)*(INDIRECT($A$12&"!E2:E100")="Outras Ocorrências"))), 0)} -> 0 | I17: {=IFERROR(ROWS(_xlfn._xlws.FILTER(INDIRECT($A$12&"!A2:E100"),(INDIRECT($A$12&"!A2:A100")=$C17)*(INDIRECT($A$12&"!E2:E100")="Sem Técnico"))), 0)} -> 4 | K17: =COUNTIF(INDIRECT("Monitoramento!$D$50:$Q$63"), "Enviado") -> 9 | L17: =COUNTIF(INDIRECT("Monitoramento!$D$50:$Q$63"), "Atrasado") -> 5 | M17: =COUNTIF(INDIRECT("Monitoramento!$D$50:$Q$63"), "Atrasado >= 2") -> 6 | N17: =COUNTIF(INDIRECT("Monitoramento!$D$50:$Q$63"), "Duplicado") -> 1 | O17: =COUNTIF(INDIRECT("Monitoramento!$D$50:$Q$63"), "Outras Ocorrências") -> 0 | P17: =COUNTIF(INDIRECT("Monitoramento!$D$50:$Q$63"), "Sem Técnico") -> 46 | R17: Duplicados | S17: =VLOOKUP($T$12,$C$14:$I$18,5,FALSE) -> 1 | T17: =S17/SUM($S$14:$S$19) -> 0.076923077
C18: Conisul | D18: {=IFERROR(ROWS(_xlfn._xlws.FILTER(INDIRECT($A$12&"!A2:E100"),(INDIRECT($A$12&"!A2:A100")=$C18)*(INDIRECT($A$12&"!E2:E100")="Enviado"))), 0)} -> 6 | E18: {=IFERROR(ROWS(_xlfn._xlws.FILTER(INDIRECT($A$12&"!A2:E100"),(INDIRECT($A$12&"!A2:A100")=$C18)*(INDIRECT($A$12&"!E2:E100")="Atrasado"))), 0)} -> 0 | F18: {=IFERROR(ROWS(_xlfn._xlws.FILTER(INDIRECT($A$12&"!A2:E100"),(INDIRECT($A$12&"!A2:A100")=$C18)*(INDIRECT($A$12&"!E2:E100")="Atrasado >= 2"))), 0)} -> 5 | G18: {=IFERROR(ROWS(_xlfn._xlws.FILTER(INDIRECT($A$12&"!A2:E100"),(INDIRECT($A$12&"!A2:A100")=$C18)*(INDIRECT($A$12&"!E2:E100")="Duplicado"))), 0)} -> 1 | H18: {=IFERROR(ROWS(_xlfn._xlws.FILTER(INDIRECT($A$12&"!A2:E100"),(INDIRECT($A$12&"!A2:A100")=$C18)*(INDIRECT($A$12&"!E2:E100")="Outras Ocorrências"))), 0)} -> 0 | I18: {=IFERROR(ROWS(_xlfn._xlws.FILTER(INDIRECT($A$12&"!A2:E100"),(INDIRECT($A$12&"!A2:A100")=$C18)*(INDIRECT($A$12&"!E2:E100")="Sem Técnico"))), 0)} -> 1 | K18: =COUNTIF(INDIRECT("Monitoramento!$D$66:$Q$78"), "Enviado") -> 0 | L18: =COUNTIF(INDIRECT("Monitoramento!$D$66:$Q$78"), "Atrasado") -> 0 | M18: =COUNTIF(INDIRECT("Monitoramento!$D$66:$Q$78"), "Atrasado >= 2") -> 0 | N18: =COUNTIF(INDIRECT("Monitoramento!$D$66:$Q$78"), "Duplicado") -> 0 | O18: =COUNTIF(INDIRECT("Monitoramento!$D$66:$Q$78"), "Outras Ocorrências") -> 0 | P18: =COUNTIF(INDIRECT("Monitoramento!$D$66:$Q$78"), "Sem Técnico") -> 0 | R18: Outras Ocorrências | S18: =VLOOKUP($T$12,$C$14:$I$18,6,FALSE) -> 0 | T18: =S18/SUM($S$14:$S$19) -> 0
C19: Regionais (Validações) | K19: Regionais (Validações) | R19: Sem Técnico | S19: =VLOOKUP($T$12,$C$14:$I$18,7,FALSE) -> 1 | T19: =S19/SUM($S$14:$S$19) -> 0.076923077
C20: Regional | E20: Validados | G20: Não Validados | I20: % Val. | K20: Validados | M20: Não Validados | O20: % Validados | R20: % Validação | S20: =VLOOKUP($T$12,$C$21:$I$25,7,FALSE) -> 0
C21: Coripa | E21: {=IFERROR(ROWS(_xlfn._xlws.FILTER(INDIRECT($A$12&"!A2:E100"),(INDIRECT($A$12&"!A2:A100")=$C21)*(INDIRECT($A$12&"!G2:G100")="Sim"))), 0)} -> 0 | G21: {=IFERROR(ROWS(_xlfn._xlws.FILTER(INDIRECT($A$12&"!A2:E100"),(INDIRECT($A$12&"!A2:A100")=$C21)*(INDIRECT($A$12&"!G2:G100")="Não"))), 0)} -> 8 | I21: =E21/SUM(E21:H21) -> 0 | K21: =COUNTIF(INDIRECT("Regionais!D2:Q15"), "Sim") -> 84 | M21: =COUNTIF(INDIRECT("Regionais!D2:Q15"), "Não") -> 49 | O21: =IFERROR(K21/SUM(K21:N21), 0) -> 0.63157895 | R21: Envios - Acumulado (Total)
C22: Comafen | E22: {=IFERROR(ROWS(_xlfn._xlws.FILTER(INDIRECT($A$12&"!A2:E100"),(INDIRECT($A$12&"!A2:A100")=$C22)*(INDIRECT($A$12&"!G2:G100")="Sim"))), 0)} -> 0 | G22: {=IFERROR(ROWS(_xlfn._xlws.FILTER(INDIRECT($A$12&"!A2:E100"),(INDIRECT($A$12&"!A2:A100")=$C22)*(INDIRECT($A$12&"!G2:G100")="Não"))), 0)} -> 11 | I22: =E22/SUM(E22:H22) -> 0 | K22: =COUNTIF(INDIRECT("Regionais!D18:Q31"), "Sim") -> 84 | M22: =COUNTIF(INDIRECT("Regionais!D18:Q31"), "Não") -> 49 | O22: =IFERROR(K22/SUM(K22:N22), 0) -> 0.63157895 | R22: Enviados | S22: =VLOOKUP($T$12,$C$13:$P$18,9,FALSE) -> 0 | T22: =S22/SUM($S$22:$S$27) -> #DIV/0!
C23: Cibax | E23: {=IFERROR(ROWS(_xlfn._xlws.FILTER(INDIRECT($A$12&"!A2:E100"),(INDIRECT($A$12&"!A2:A100")=$C23)*(INDIRECT($A$12&"!G2:G100")="Sim"))), 0)} -> 1 | G23: {=IFERROR(ROWS(_xlfn._xlws.FILTER(INDIRECT($A$12&"!A2:E100"),(INDIRECT($A$12&"!A2:A100")=$C23)*(INDIRECT($A$12&"!G2:G100")="Não"))), 0)} -> 9 | I23: =E23/SUM(E23:H23) -> 0.1 | K23: =COUNTIF(INDIRECT("Regionais!D34:Q47"), "Sim") -> 70 | M23: =COUNTIF(INDIRECT("Regionais!D34:Q47"), "Não") -> 44 | O23: =IFERROR(K23/SUM(K23:N23), 0) -> 0.61403509 | R23: Atrasados | S23: =VLOOKUP($T$12,$C$13:$P$18,10,FALSE) -> 0 | T23: =S23/SUM($S$22:$S$27) -> #DIV/0!
C24: Cifra | E24: {=IFERROR(ROWS(_xlfn._xlws.FILTER(INDIRECT($A$12&"!A2:E100"),(INDIRECT($A$12&"!A2:A100")=$C24)*(INDIRECT($A$12&"!G2:G100")="Sim"))), 0)} -> 0 | G24: {=IFERROR(ROWS(_xlfn._xlws.FILTER(INDIRECT($A$12&"!A2:E100"),(INDIRECT($A$12&"!A2:A100")=$C24)*(INDIRECT($A$12&"!G2:G100")="Não"))), 0)} -> 4 | I24: =E24/SUM(E24:H24) -> 0 | K24: =COUNTIF(INDIRECT("Regionais!D50:Q63"), "Sim") -> 41 | M24: =COUNTIF(INDIRECT("Regionais!D50:Q63"), "Não") -> 26 | O24: =IFERROR(K24/SUM(K24:N24), 0) -> 0.6119403 | R24: Atrasados >= 2 | S24: =VLOOKUP($T$12,$C$13:$P$18,11,FALSE) -> 0 | T24: =S24/SUM($S$22:$S$27) -> #DIV/0!
C25: Conisul | E25: {=IFERROR(ROWS(_xlfn._xlws.FILTER(INDIRECT($A$12&"!A2:E100"),(INDIRECT($A$12&"!A2:A100")=$C25)*(INDIRECT($A$12&"!G2:G100")="Sim"))), 0)} -> 0 | G25: {=IFERROR(ROWS(_xlfn._xlws.FILTER(INDIRECT($A$12&"!A2:E100"),(INDIRECT($A$12&"!A2:A100")=$C25)*(INDIRECT($A$12&"!G2:G100")="Não"))), 0)} -> 13 | I25: =E25/SUM(E25:H25) -> 0 | K25: =COUNTIF(INDIRECT("Regionais!D66:Q78"), "Sim") -> 0 | M25: =COUNTIF(INDIRECT("Regionais!D66:Q78"), "Não") -> 0 | O25: =IFERROR(K25/SUM(K25:N25), 0) -> 0 | R25: Duplicados | S25: =VLOOKUP($T$12,$C$13:$P$18,12,FALSE) -> 0 | T25: =S25/SUM($S$22:$S$27) -> #DIV/0!
R26: Outras Ocorrências | S26: =VLOOKUP($T$12,$C$13:$P$18,13,FALSE) -> 0 | T26: =S26/SUM($S$22:$S$27) -> #DIV/0!
R27: Sem Técnico | S27: =VLOOKUP($T$12,$C$13:$P$18,14,FALSE) -> 0 | T27: =S27/SUM($S$22:$S$27) -> #DIV/0!
R28: % Validação | S28: =VLOOKUP($T$12,$C$20:$P$25,13,FALSE) -> 0

Sheet Monitoramento
A1: Regional | B1: Municípios | C1: UVR | D1: 01.25 | E1: 02.25 | F1: 03.25 | G1: 04.25 | H1: 05.25 | I1: 06.25 | J1: 07.25 | K1: 08.25 | L1: 09.25 | M1: 10.25 | N1: 11.25 | O1: 12.25
A2: Coripa | B2: Alto Paraíso | C2: 1 | D2: {=IF( VLOOKUP( $A2, _xlfn._xlws.FILTER( INDIRECT("'"&D$1&"'!A2:E1000"), (INDIRECT("'"&D$1&"'!B2:B1000")=$B2) * (INDIRECT("'"&D$1&"'!C2:C1000")=$C2) ), 5, FALSE )=0, "", VLOOKUP( $A2, _xlfn._xlws.FILTER( INDIRECT("'"&D$1&"'!A2:E1000"), (INDIRECT("'"&D$1&"'!B2:B1000")=$B2) * (INDIRECT("'"&D$1&"'!C2:C1000")=$C2) ), 5, FALSE ) )} -> Sem Técnico | E2: {=IF( VLOOKUP( $A2, _xlfn._xlws.FILTER( INDIRECT("'"&E$1&"'!A2:E1000"), (INDIRECT("'"&E$1&"'!B2:B1000")=$B2) * (INDIRECT("'"&E$1&"'!C2:C1000")=$C2) ), 5, FALSE )=0, "", VLOOKUP( $A2, _xlfn._xlws.FILTER( INDIRECT("'"&E$1&"'!A2:E1000"), (INDIRECT("'"&E$1&"'!B2:B1000")=$B2) * (INDIRECT("'"&E$1&"'!C2:C1000")=$C2) ), 5, FALSE ) )} -> Sem Técnico | F2: {=IF( VLOOKUP( $A2, _xlfn._xlws.FILTER( INDIRECT("'"&F$1&"'!A2:E1000"), (INDIRECT("'"&F$1&"'!B2:B1000")=$B2) * (INDIRECT("'"&F$1&"'!C2:C1000")=$C2) ), 5, FALSE )=0, "", VLOOKUP( $A2, _xlfn._xlws.FILTER( INDIRECT("'"&F$1&"'!A2:E1000"), (INDIRECT("'"&F$1&"'!B2:B1000")=$B2) * (INDIRECT("'"&F$1&"'!C2:C1000")=$C2) ), 5, FALSE ) )} -> Sem Técnico | G2: {=IF( VLOOKUP( $A2, _xlfn._xlws.FILTER( INDIRECT("'"&G$1&"'!A2:E1000"), (INDIRECT("'"&G$1&"'!B2:B1000")=$B2) * (INDIRECT("'"&G$1&"'!C2:C1000")=$C2) ), 5, FALSE )=0, "", VLOOKUP( $A2, _xlfn._xlws.FILTER( INDIRECT("'"&G$1&"'!A2:E1000"), (INDIRECT("'"&G$1&"'!B2:B1000")=$B2) * (INDIRECT("'"&G$1&"'!C2:C1000")=$C2) ), 5, FALSE ) )} -> Sem Técnico | H2: {=IF( VLOOKUP( $A2, _xlfn._xlws.FILTER( INDIRECT("'"&H$1&"'!A2:E1000"), (INDIRECT("'"&H$1&"'!B2:B1000")=$B2) * (INDIRECT("'"&H$1&"'!C2:C1000")=$C2) ), 5, FALSE )=0, "", VLOOKUP( $A2, _xlfn._xlws.FILTER( INDIRECT("'"&H$1&"'!A2:E1000"), (INDIRECT("'"&H$1&"'!B2:B1000")=$B2) * (INDIRECT("'"&H$1&"'!C2:C1000")=$C2) ), 5, FALSE ) )} -> Sem Técnico | I2: {=IF( VLOOKUP( $A2, _xlfn._xlws.FILTER( INDIRECT("'"&I$1&"'!A2:E1000"), (INDIRECT("'"&I$1&"'!B2:B1000")=$B2) * (INDIRECT("'"&I$1&"'!C2:C1000")=$C2) ), 5, FALSE )=0, "", VLOOKUP( $A2, _xlfn._xlws.FILTER( INDIRECT("'"&I$1&"'!A2:E1000"), (INDIRECT("'"&I$1&"'!B2:B1000")=$B2) * (INDIRECT("'"&I$1&"'!C2:C1000")=$C2) ), 5, FALSE ) )} -> Sem Técnico | J2: {=IF( VLOOKUP( $A2, _xlfn._xlws.FILTER( INDIRECT("'"&J$1&"'!A2:E1000"), (INDIRECT("'"&J$1&"'!B2:B1000")=$B2) * (INDIRECT("'"&J$1&"'!C2:C1000")=$C2) ), 5, FALSE )=0, "", VLOOKUP( $A2, _xlfn._xlws.FILTER( INDIRECT("'"&J$1&"'!A2:E1000"), (INDIRECT("'"&J$1&"'!B2:B1000")=$B2) * (INDIRECT("'"&J$1&"'!C2:C1000")=$C2) ), 5, FALSE ) )} -> Sem Técnico | K2: {=IF( VLOOKUP( $A2, _xlfn._xlws.FILTER( INDIRECT("'"&K$1&"'!A2:E1000"), (INDIRECT("'"&K$1&"'!B2:B1000")=$B2) * (INDIRECT("'"&K$1&"'!C2:C1000")=$C2) ), 5, FALSE )=0, "", VLOOKUP( $A2, _xlfn._xlws.FILTER( INDIRECT("'"&K$1&"'!A2:E1000"), (INDIRECT("'"&K$1&"'!B2:B1000")=$B2) * (INDIRECT("'"&K$1&"'!C2:C1000")=$C2) ), 5, FALSE ) )} -> Outras Ocorrências | ... O2: {=IF( VLOOKUP( $A2, _xlfn._xlws.FILTER( INDIRECT("'"&O$1&"'!A2:E1000"), (INDIRECT("'"&O$1&"'!B2:B1000")=$B2) * (INDIRECT("'"&O$1&"'!C2:C1000")=$C2) ), 5, FALSE )=0, "", VLOOKUP( $A2, _xlfn._xlws.FILTER( INDIRECT("'"&O$1&"'!A2:E1000"), (INDIRECT("'"&O$1&"'!B2:B1000")=$B2) * (INDIRECT("'"&O$1&"'!C2:C1000")=$C2) ), 5, FALSE ) )} -> Outras Ocorrências
A3: Coripa | B3: Douradina | C3: 1 | D3: {=IF( VLOOKUP( $A3, _xlfn._xlws.FILTER( INDIRECT("'"&D$1&"'!A2:E1000"), (INDIRECT("'"&D$1&"'!B2:B1000")=$B3) * (INDIRECT("'"&D$1&"'!C2:C1000")=$C3) ), 5, FALSE )=0, "", VLOOKUP( $A3, _xlfn._xlws.FILTER( INDIRECT("'"&D$1&"'!A2:E1000"), (INDIRECT("'"&D$1&"'!B2:B1000")=$B3) * (INDIRECT("'"&D$1&"'!C2:C1000")=$C3) ), 5, FALSE ) )} -> Sem Técnico | E3: {=IF( VLOOKUP( $A3, _xlfn._xlws.FILTER( INDIRECT("'"&E$1&"'!A2:E1000"), (INDIRECT("'"&E$1&"'!B2:B1000")=$B3) * (INDIRECT("'"&E$1&"'!C2:C1000")=$C3) ), 5, FALSE )=0, "", VLOOKUP( $A3, _xlfn._xlws.FILTER( INDIRECT("'"&E$1&"'!A2:E1000"), (INDIRECT("'"&E$1&"'!B2:B1000")=$B3) * (INDIRECT("'"&E$1&"'!C2:C1000")=$C3) ), 5, FALSE ) )} -> Sem Técnico | F3: {=IF( VLOOKUP( $A3, _xlfn._xlws.FILTER( INDIRECT("'"&F$1&"'!A2:E1000"), (INDIRECT("'"&F$1&"'!B2:B1000")=$B3) * (INDIRECT("'"&F$1&"'!C2:C1000")=$C3) ), 5, FALSE )=0, "", VLOOKUP( $A3, _xlfn._xlws.FILTER( INDIRECT("'"&F$1&"'!A2:E1000"), (INDIRECT("'"&F$1&"'!B2:B1000")=$B3) * (INDIRECT("'"&F$1&"'!C2:C1000")=$C3) ), 5, FALSE ) )} -> Sem Técnico | G3: {=IF( VLOOKUP( $A3, _xlfn._xlws.FILTER( INDIRECT("'"&G$1&"'!A2:E1000"), (INDIRECT("'"&G$1&"'!B2:B1000")=$B3) * (INDIRECT("'"&G$1&"'!C2:C1000")=$C3) ), 5, FALSE )=0, "", VLOOKUP( $A3, _xlfn._xlws.FILTER( INDIRECT("'"&G$1&"'!A2:E1000"), (INDIRECT("'"&G$1&"'!B2:B1000")=$B3) * (INDIRECT("'"&G$1&"'!C2:C1000")=$C3) ), 5, FALSE ) )} -> Sem Técnico | H3: {=IF( VLOOKUP( $A3, _xlfn._xlws.FILTER( INDIRECT("'"&H$1&"'!A2:E1000"), (INDIRECT("'"&H$1&"'!B2:B1000")=$B3) * (INDIRECT("'"&H$1&"'!C2:C1000")=$C3) ), 5, FALSE )=0, "", VLOOKUP( $A3, _xlfn._xlws.FILTER( INDIRECT("'"&H$1&"'!A2:E1000"), (INDIRECT("'"&H$1&"'!B2:B1000")=$B3) * (INDIRECT("'"&H$1&"'!C2:C1000")=$C3) ), 5, FALSE ) )} -> Sem Técnico | I3: {=IF( VLOOKUP( $A3, _xlfn._xlws.FILTER( INDIRECT("'"&I$1&"'!A2:E1000"), (INDIRECT("'"&I$1&"'!B2:B1000")=$B3) * (INDIRECT("'"&I$1&"'!C2:C1000")=$C3) ), 5, FALSE )=0, "", VLOOKUP( $A3, _xlfn._xlws.FILTER( INDIRECT("'"&I$1&"'!A2:E1000"), (INDIRECT("'"&I$1&"'!B2:B1000")=$B3) * (INDIRECT("'"&I$1&"'!C2:C1000")=$C3) ), 5, FALSE ) )} -> Sem Técnico | J3: {=IF( VLOOKUP( $A3, _xlfn._xlws.FILTER( INDIRECT("'"&J$1&"'!A2:E1000"), (INDIRECT("'"&J$1&"'!B2:B1000")=$B3) * (INDIRECT("'"&J$1&"'!C2:C1000")=$C3) ), 5, FALSE )=0, "", VLOOKUP( $A3, _xlfn._xlws.FILTER( INDIRECT("'"&J$1&"'!A2:E1000"), (INDIRECT("'"&J$1&"'!B2:B1000")=$B3) * (INDIRECT("'"&J$1&"'!C2:C1000")=$C3) ), 5, FALSE ) )} -> Sem Técnico | K3: {=IF( VLOOKUP( $A3, _xlfn._xlws.FILTER( INDIRECT("'"&K$1&"'!A2:E1000"), (INDIRECT("'"&K$1&"'!B2:B1000")=$B3) * (INDIRECT("'"&K$1&"'!C2:C1000")=$C3) ), 5, FALSE )=0, "", VLOOKUP( $A3, _xlfn._xlws.FILTER( INDIRECT("'"&K$1&"'!A2:E1000"), (INDIRECT("'"&K$1&"'!B2:B1000")=$B3) * (INDIRECT("'"&K$1&"'!C2:C1000")=$C3) ), 5, FALSE ) )} -> Enviado | ... O3: {=IF( VLOOKUP( $A3, _xlfn._xlws.FILTER( INDIRECT("'"&O$1&"'!A2:E1000"), (INDIRECT("'"&O$1&"'!B2:B1000")=$B3) * (INDIRECT("'"&O$1&"'!C2:C1000")=$C3) ), 5, FALSE )=0, "", VLOOKUP( $A3, _xlfn._xlws.FILTER( INDIRECT("'"&O$1&"'!A2:E1000"), (INDIRECT("'"&O$1&"'!B2:B1000")=$B3) * (INDIRECT("'"&O$1&"'!C2:C1000")=$C3) ), 5, FALSE ) )}
A4: Coripa | B4: Esperança Nova | C4: 1 | D4: {=IF( VLOOKUP( $A4, _xlfn._xlws.FILTER( INDIRECT("'"&D$1&"'!A2:E1000"), (INDIRECT("'"&D$1&"'!B2:B1000")=$B4) * (INDIRECT("'"&D$1&"'!C2:C1000")=$C4) ), 5, FALSE )=0, "", VLOOKUP( $A4, _xlfn._xlws.FILTER( INDIRECT("'"&D$1&"'!A2:E1000"), (INDIRECT("'"&D$1&"'!B2:B1000")=$B4) * (INDIRECT("'"&D$1&"'!C2:C1000")=$C4) ), 5, FALSE ) )} -> Sem Técnico | E4: {=IF( VLOOKUP( $A4, _xlfn._xlws.FILTER( INDIRECT("'"&E$1&"'!A2:E1000"), (INDIRECT("'"&E$1&"'!B2:B1000")=$B4) * (INDIRECT("'"&E$1&"'!C2:C1000")=$C4) ), 5, FALSE )=0, "", VLOOKUP( $A4, _xlfn._xlws.FILTER( INDIRECT("'"&E$1&"'!A2:E1000"), (INDIRECT("'"&E$1&"'!B2:B1000")=$B4) * (INDIRECT("'"&E$1&"'!C2:C1000")=$C4) ), 5, FALSE ) )} -> Sem Técnico | F4: {=IF( VLOOKUP( $A4, _xlfn._xlws.FILTER( INDIRECT("'"&F$1&"'!A2:E1000"), (INDIRECT("'"&F$1&"'!B2:B1000")=$B4) * (INDIRECT("'"&F$1&"'!C2:C1000")=$C4) ), 5, FALSE )=0, "", VLOOKUP( $A4, _xlfn._xlws.FILTER( INDIRECT("'"&F$1&"'!A2:E1000"), (INDIRECT("'"&F$1&"'!B2:B1000")=$B4) * (INDIRECT("'"&F$1&"'!C2:C1000")=$C4) ), 5, FALSE ) )} -> Sem Técnico | G4: {=IF( VLOOKUP( $A4, _xlfn._xlws.FILTER( INDIRECT("'"&G$1&"'!A2:E1000"), (INDIRECT("'"&G$1&"'!B2:B1000")=$B4) * (INDIRECT("'"&G$1&"'!C2:C1000")=$C4) ), 5, FALSE )=0, "", VLOOKUP( $A4, _xlfn._xlws.FILTER( INDIRECT("'"&G$1&"'!A2:E1000"), (INDIRECT("'"&G$1&"'!B2:B1000")=$B4) * (INDIRECT("'"&G$1&"'!C2:C1000")=$C4) ), 5, FALSE ) )} -> Sem Técnico | H4: {=IF( VLOOKUP( $A4, _xlfn._xlws.FILTER( INDIRECT("'"&H$1&"'!A2:E1000"), (INDIRECT("'"&H$1&"'!B2:B1000")=$B4) * (INDIRECT("'"&H$1&"'!C2:C1000")=$C4) ), 5, FALSE )=0, "", VLOOKUP( $A4, _xlfn._xlws.FILTER( INDIRECT("'"&H$1&"'!A2:E1000"), (INDIRECT("'"&H$1&"'!B2:B1000")=$B4) * (INDIRECT("'"&H$1&"'!C2:C1000")=$C4) ), 5, FALSE ) )} -> Sem Técnico | I4: {=IF( VLOOKUP( $A4, _xlfn._xlws.FILTER( INDIRECT("'"&I$1&"'!A2:E1000"), (INDIRECT("'"&I$1&"'!B2:B1000")=$B4) * (INDIRECT("'"&I$1&"'!C2:C1000")=$C4) ), 5, FALSE )=0, "", VLOOKUP( $A4, _xlfn._xlws.FILTER( INDIRECT("'"&I$1&"'!A2:E1000"), (INDIRECT("'"&I$1&"'!B2:B1000")=$B4) * (INDIRECT("'"&I$1&"'!C2:C1000")=$C4) ), 5, FALSE ) )} -> Sem Técnico | J4: {=IF( VLOOKUP( $A4, _xlfn._xlws.FILTER( INDIRECT("'"&J$1&"'!A2:E1000"), (INDIRECT("'"&J$1&"'!B2:B1000")=$B4) * (INDIRECT("'"&J$1&"'!C2:C1000")=$C4) ), 5, FALSE )=0, "", VLOOKUP( $A4, _xlfn._xlws.FILTER( INDIRECT("'"&J$1&"'!A2:E1000"), (INDIRECT("'"&J$1&"'!B2:B1000")=$B4) * (INDIRECT("'"&J$1&"'!C2:C1000")=$C4) ), 5, FALSE ) )} -> Sem Técnico | K4: {=IF( VLOOKUP( $A4, _xlfn._xlws.FILTER( INDIRECT("'"&K$1&"'!A2:E1000"), (INDIRECT("'"&K$1&"'!B2:B1000")=$B4) * (INDIRECT("'"&K$1&"'!C2:C1000")=$C4) ), 5, FALSE )=0, "", VLOOKUP( $A4, _xlfn._xlws.FILTER( INDIRECT("'"&K$1&"'!A2:E1000"), (INDIRECT("'"&K$1&"'!B2:B1000")=$B4) * (INDIRECT("'"&K$1&"'!C2:C1000")=$C4) ), 5, FALSE ) )} -> Atrasado >= 2 | ... O4: {=IF( VLOOKUP( $A4, _xlfn._xlws.FILTER( INDIRECT("'"&O$1&"'!A2:E1000"), (INDIRECT("'"&O$1&"'!B2:B1000")=$B4) * (INDIRECT("'"&O$1&"'!C2:C1000")=$C4) ), 5, FALSE )=0, "", VLOOKUP( $A4, _xlfn._xlws.FILTER( INDIRECT("'"&O$1&"'!A2:E1000"), (INDIRECT("'"&O$1&"'!B2:B1000")=$B4) * (INDIRECT("'"&O$1&"'!C2:C1000")=$C4) ), 5, FALSE ) )}
A5: Coripa | B5: Icaraíma | C5: 1 | D5: {=IF( VLOOKUP( $A5, _xlfn._xlws.FILTER( INDIRECT("'"&D$1&"'!A2:E1000"), (INDIRECT("'"&D$1&"'!B2:B1000")=$B5) * (INDIRECT("'"&D$1&"'!C2:C1000")=$C5) ), 5, FALSE )=0, "", VLOOKUP( $A5, _xlfn._xlws.FILTER( INDIRECT("'"&D$1&"'!A2:E1000"), (INDIRECT("'"&D$1&"'!B2:B1000")=$B5) * (INDIRECT("'"&D$1&"'!C2:C1000")=$C5) ), 5, FALSE ) )} -> Sem Técnico | E5: {=IF( VLOOKUP( $A5, _xlfn._xlws.FILTER( INDIRECT("'"&E$1&"'!A2:E1000"), (INDIRECT("'"&E$1&"'!B2:B1000")=$B5) * (INDIRECT("'"&E$1&"'!C2:C1000")=$C5) ), 5, FALSE )=0, "", VLOOKUP( $A5, _xlfn._xlws.FILTER( INDIRECT("'"&E$1&"'!A2:E1000"), (INDIRECT("'"&E$1&"'!B2:B1000")=$B5) * (INDIRECT("'"&E$1&"'!C2:C1000")=$C5) ), 5, FALSE ) )} -> Sem Técnico | F5: {=IF( VLOOKUP( $A5, _xlfn._xlws.FILTER( INDIRECT("'"&F$1&"'!A2:E1000"), (INDIRECT("'"&F$1&"'!B2:B1000")=$B5) * (INDIRECT("'"&F$1&"'!C2:C1000")=$C5) ), 5, FALSE )=0, "", VLOOKUP( $A5, _xlfn._xlws.FILTER( INDIRECT("'"&F$1&"'!A2:E1000"), (INDIRECT("'"&F$1&"'!B2:B1000")=$B5) * (INDIRECT("'"&F$1&"'!C2:C1000")=$C5) ), 5, FALSE ) )} -> Sem Técnico | G5: {=IF( VLOOKUP( $A5, _xlfn._xlws.FILTER( INDIRECT("'"&G$1&"'!A2:E1000"), (INDIRECT("'"&G$1&"'!B2:B1000")=$B5) * (INDIRECT("'"&G$1&"'!C2:C1000")=$C5) ), 5, FALSE )=0, "", VLOOKUP( $A5, _xlfn._xlws.FILTER( INDIRECT("'"&G$1&"'!A2:E1000"), (INDIRECT("'"&G$1&"'!B2:B1000")=$B5) * (INDIRECT("'"&G$1&"'!C2:C1000")=$C5) ), 5, FALSE ) )} -> Sem Técnico | H5: {=IF( VLOOKUP( $A5, _xlfn._xlws.FILTER( INDIRECT("'"&H$1&"'!A2:E1000"), (INDIRECT("'"&H$1&"'!B2:B1000")=$B5) * (INDIRECT("'"&H$1&"'!C2:C1000")=$C5) ), 5, FALSE )=0, "", VLOOKUP( $A5, _xlfn._xlws.FILTER( INDIRECT("'"&H$1&"'!A2:E1000"), (INDIRECT("'"&H$1&"'!B2:B1000")=$B5) * (INDIRECT("'"&H$1&"'!C2:C1000")=$C5) ), 5, FALSE ) )} -> Sem Técnico | I5: {=IF( VLOOKUP( $A5, _xlfn._xlws.FILTER( INDIRECT("'"&I$1&"'!A2:E1000"), (INDIRECT("'"&I$1&"'!B2:B1000")=$B5) * (INDIRECT("'"&I$1&"'!C2:C1000")=$C5) ), 5, FALSE )=0, "", VLOOKUP( $A5, _xlfn._xlws.FILTER( INDIRECT("'"&I$1&"'!A2:E1000"), (INDIRECT("'"&I$1&"'!B2:B1000")=$B5) * (INDIRECT("'"&I$1&"'!C2:C1000")=$C5) ), 5, FALSE ) )} -> Sem Técnico | J5: {=IF( VLOOKUP( $A5, _xlfn._xlws.FILTER( INDIRECT("'"&J$1&"'!A2:E1000"), (INDIRECT("'"&J$1&"'!B2:B1000")=$B5) * (INDIRECT("'"&J$1&"'!C2:C1000")=$C5) ), 5, FALSE )=0, "", VLOOKUP( $A5, _xlfn._xlws.FILTER( INDIRECT("'"&J$1&"'!A2:E1000"), (INDIRECT("'"&J$1&"'!B2:B1000")=$B5) * (INDIRECT("'"&J$1&"'!C2:C1000")=$C5) ), 5, FALSE ) )} -> Sem Técnico | K5: {=IF( VLOOKUP( $A5, _xlfn._xlws.FILTER( INDIRECT("'"&K$1&"'!A2:E1000"), (INDIRECT("'"&K$1&"'!B2:B1000")=$B5) * (INDIRECT("'"&K$1&"'!C2:C1000")=$C5) ), 5, FALSE )=0, "", VLOOKUP( $A5, _xlfn._xlws.FILTER( INDIRECT("'"&K$1&"'!A2:E1000"), (INDIRECT("'"&K$1&"'!B2:B1000")=$B5) * (INDIRECT("'"&K$1&"'!C2:C1000")=$C5) ), 5, FALSE ) )} -> Enviado | ... O5: {=IF( VLOOKUP( $A5, _xlfn._xlws.FILTER( INDIRECT("'"&O$1&"'!A2:E1000"), (INDIRECT("'"&O$1&"'!B2:B1000")=$B5) * (INDIRECT("'"&O$1&"'!C2:C1000")=$C5) ), 5, FALSE )=0, "", VLOOKUP( $A5, _xlfn._xlws.FILTER( INDIRECT("'"&O$1&"'!A2:E1000"), (INDIRECT("'"&O$1&"'!B2:B1000")=$B5) * (INDIRECT("'"&O$1&"'!C2:C1000")=$C5) ), 5, FALSE ) )}
A6: Coripa | B6: Maria Helena | C6: 1 | D6: {=IF( VLOOKUP( $A6, _xlfn._xlws.FILTER( INDIRECT("'"&D$1&"'!A2:E1000"), (INDIRECT("'"&D$1&"'!B2:B1000")=$B6) * (INDIRECT("'"&D$1&"'!C2:C1000")=$C6) ), 5, FALSE )=0, "", VLOOKUP( $A6, _xlfn._xlws.FILTER( INDIRECT("'"&D$1&"'!A2:E1000"), (INDIRECT("'"&D$1&"'!B2:B1000")=$B6) * (INDIRECT("'"&D$1&"'!C2:C1000")=$C6) ), 5, FALSE ) )} -> Sem Técnico | E6: {=IF( VLOOKUP( $A6, _xlfn._xlws.FILTER( INDIRECT("'"&E$1&"'!A2:E1000"), (INDIRECT("'"&E$1&"'!B2:B1000")=$B6) * (INDIRECT("'"&E$1&"'!C2:C1000")=$C6) ), 5, FALSE )=0, "", VLOOKUP( $A6, _xlfn._xlws.FILTER( INDIRECT("'"&E$1&"'!A2:E1000"), (INDIRECT("'"&E$1&"'!B2:B1000")=$B6) * (INDIRECT("'"&E$1&"'!C2:C1000")=$C6) ), 5, FALSE ) )} -> Sem Técnico | F6: {=IF( VLOOKUP( $A6, _xlfn._xlws.FILTER( INDIRECT("'"&F$1&"'!A2:E1000"), (INDIRECT("'"&F$1&"'!B2:B1000")=$B6) * (INDIRECT("'"&F$1&"'!C2:C1000")=$C6) ), 5, FALSE )=0, "", VLOOKUP( $A6, _xlfn._xlws.FILTER( INDIRECT("'"&F$1&"'!A2:E1000"), (INDIRECT("'"&F$1&"'!B2:B1000")=$B6) * (INDIRECT("'"&F$1&"'!C2:C1000")=$C6) ), 5, FALSE ) )} -> Sem Técnico | G6: {=IF( VLOOKUP( $A6, _xlfn._xlws.FILTER( INDIRECT("'"&G$1&"'!A2:E1000"), (INDIRECT("'"&G$1&"'!B2:B1000")=$B6) * (INDIRECT("'"&G$1&"'!C2:C1000")=$C6) ), 5, FALSE )=0, "", VLOOKUP( $A6, _xlfn._xlws.FILTER( INDIRECT("'"&G$1&"'!A2:E1000"), (INDIRECT("'"&G$1&"'!B2:B1000")=$B6) * (INDIRECT("'"&G$1&"'!C2:C1000")=$C6) ), 5, FALSE ) )} -> Sem Técnico | H6: {=IF( VLOOKUP( $A6, _xlfn._xlws.FILTER( INDIRECT("'"&H$1&"'!A2:E1000"), (INDIRECT("'"&H$1&"'!B2:B1000")=$B6) * (INDIRECT("'"&H$1&"'!C2:C1000")=$C6) ), 5, FALSE )=0, "", VLOOKUP( $A6, _xlfn._xlws.FILTER( INDIRECT("'"&H$1&"'!A2:E1000"), (INDIRECT("'"&H$1&"'!B2:B1000")=$B6) * (INDIRECT("'"&H$1&"'!C2:C1000")=$C6) ), 5, FALSE ) )} -> Sem Técnico | I6: {=IF( VLOOKUP( $A6, _xlfn._xlws.FILTER( INDIRECT("'"&I$1&"'!A2:E1000"), (INDIRECT("'"&I$1&"'!B2:B1000")=$B6) * (INDIRECT("'"&I$1&"'!C2:C1000")=$C6) ), 5, FALSE )=0, "", VLOOKUP( $A6, _xlfn._xlws.FILTER( INDIRECT("'"&I$1&"'!A2:E1000"), (INDIRECT("'"&I$1&"'!B2:B1000")=$B6) * (INDIRECT("'"&I$1&"'!C2:C1000")=$C6) ), 5, FALSE ) )} -> Sem Técnico | J6: {=IF( VLOOKUP( $A6, _xlfn._xlws.FILTER( INDIRECT("'"&J$1&"'!A2:E1000"), (INDIRECT("'"&J$1&"'!B2:B1000")=$B6) * (INDIRECT("'"&J$1&"'!C2:C1000")=$C6) ), 5, FALSE )=0, "", VLOOKUP( $A6, _xlfn._xlws.FILTER( INDIRECT("'"&J$1&"'!A2:E1000"), (INDIRECT("'"&J$1&"'!B2:B1000")=$B6) * (INDIRECT("'"&J$1&"'!C2:C1000")=$C6) ), 5, FALSE ) )} -> Sem Técnico | K6: {=IF( VLOOKUP( $A6, _xlfn._xlws.FILTER( INDIRECT("'"&K$1&"'!A2:E1000"), (INDIRECT("'"&K$1&"'!B2:B1000")=$B6) * (INDIRECT("'"&K$1&"'!C2:C1000")=$C6) ), 5, FALSE )=0, "", VLOOKUP( $A6, _xlfn._xlws.FILTER( INDIRECT("'"&K$1&"'!A2:E1000"), (INDIRECT("'"&K$1&"'!B2:B1000")=$B6) * (INDIRECT("'"&K$1&"'!C2:C1000")=$C6) ), 5, FALSE ) )} -> Atrasado >= 2 | ... O6: {=IF( VLOOKUP( $A6, _xlfn._xlws.FILTER( INDIRECT("'"&O$1&"'!A2:E1000"), (INDIRECT("'"&O$1&"'!B2:B1000")=$B6) * (INDIRECT("'"&O$1&"'!C2:C1000")=$C6) ), 5, FALSE )=0, "", VLOOKUP( $A6, _xlfn._xlws.FILTER( INDIRECT("'"&O$1&"'!A2:E1000"), (INDIRECT("'"&O$1&"'!B2:B1000")=$B6) * (INDIRECT("'"&O$1&"'!C2:C1000")=$C6) ), 5, FALSE ) )}
A7: Coripa | B7: Nova Olimpia | C7: 1 | D7: {=IF( VLOOKUP( $A7, _xlfn._xlws.FILTER( INDIRECT("'"&D$1&"'!A2:E1000"), (INDIRECT("'"&D$1&"'!B2:B1000")=$B7) * (INDIRECT("'"&D$1&"'!C2:C1000")=$C7) ), 5, FALSE )=0, "", VLOOKUP( $A7, _xlfn._xlws.FILTER( INDIRECT("'"&D$1&"'!A2:E1000"), (INDIRECT("'"&D$1&"'!B2:B1000")=$B7) * (INDIRECT("'"&D$1&"'!C2:C1000")=$C7) ), 5, FALSE ) )} -> Sem Técnico | E7: {=IF( VLOOKUP( $A7, _xlfn._xlws.FILTER( INDIRECT("'"&E$1&"'!A2:E1000"), (INDIRECT("'"&E$1&"'!B2:B1000")=$B7) * (INDIRECT("'"&E$1&"'!C2:C1000")=$C7) ), 5, FALSE )=0, "", VLOOKUP( $A7, _xlfn._xlws.FILTER( INDIRECT("'"&E$1&"'!A2:E1000"), (INDIRECT("'"&E$1&"'!B2:B1000")=$B7) * (INDIRECT("'"&E$1&"'!C2:C1000")=$C7) ), 5, FALSE ) )} -> Sem Técnico | F7: {=IF( VLOOKUP( $A7, _xlfn._xlws.FILTER( INDIRECT("'"&F$1&"'!A2:E1000"), (INDIRECT("'"&F$1&"'!B2:B1000")=$B7) * (INDIRECT("'"&F$1&"'!C2:C1000")=$C7) ), 5, FALSE )=0, "", VLOOKUP( $A7, _xlfn._xlws.FILTER( INDIRECT("'"&F$1&"'!A2:E1000"), (INDIRECT("'"&F$1&"'!B2:B1000")=$B7) * (INDIRECT("'"&F$1&"'!C2:C1000")=$C7) ), 5, FALSE ) )} -> Sem Técnico | G7: {=IF( VLOOKUP( $A7, _xlfn._xlws.FILTER( INDIRECT("'"&G$1&"'!A2:E1000"), (INDIRECT("'"&G$1&"'!B2:B1000")=$B7) * (INDIRECT("'"&G$1&"'!C2:C1000")=$C7) ), 5, FALSE )=0, "", VLOOKUP( $A7, _xlfn._xlws.FILTER( INDIRECT("'"&G$1&"'!A2:E1000"), (INDIRECT("'"&G$1&"'!B2:B1000")=$B7) * (INDIRECT("'"&G$1&"'!C2:C1000")=$C7) ), 5, FALSE ) )} -> Sem Técnico | H7: {=IF( VLOOKUP( $A7, _xlfn._xlws.FILTER( INDIRECT("'"&H$1&"'!A2:E1000"), (INDIRECT("'"&H$1&"'!B2:B1000")=$B7) * (INDIRECT("'"&H$1&"'!C2:C1000")=$C7) ), 5, FALSE )=0, "", VLOOKUP( $A7, _xlfn._xlws.FILTER( INDIRECT("'"&H$1&"'!A2:E1000"), (INDIRECT("'"&H$1&"'!B2:B1000")=$B7) * (INDIRECT("'"&H$1&"'!C2:C1000")=$C7) ), 5, FALSE ) )} -> Sem Técnico | I7: {=IF( VLOOKUP( $A7, _xlfn._xlws.FILTER( INDIRECT("'"&I$1&"'!A2:E1000"), (INDIRECT("'"&I$1&"'!B2:B1000")=$B7) * (INDIRECT("'"&I$1&"'!C2:C1000")=$C7) ), 5, FALSE )=0, "", VLOOKUP( $A7, _xlfn._xlws.FILTER( INDIRECT("'"&I$1&"'!A2:E1000"), (INDIRECT("'"&I$1&"'!B2:B1000")=$B7) * (INDIRECT("'"&I$1&"'!C2:C1000")=$C7) ), 5, FALSE ) )} -> Sem Técnico | J7: {=IF( VLOOKUP( $A7, _xlfn._xlws.FILTER( INDIRECT("'"&J$1&"'!A2:E1000"), (INDIRECT("'"&J$1&"'!B2:B1000")=$B7) * (INDIRECT("'"&J$1&"'!C2:C1000")=$C7) ), 5, FALSE )=0, "", VLOOKUP( $A7, _xlfn._xlws.FILTER( INDIRECT("'"&J$1&"'!A2:E1000"), (INDIRECT("'"&J$1&"'!B2:B1000")=$B7) * (INDIRECT("'"&J$1&"'!C2:C1000")=$C7) ), 5, FALSE ) )} -> Sem Técnico | K7: {=IF( VLOOKUP( $A7, _xlfn._xlws.FILTER( INDIRECT("'"&K$1&"'!A2:E1000"), (INDIRECT("'"&K$1&"'!B2:B1000")=$B7) * (INDIRECT("'"&K$1&"'!C2:C1000")=$C7) ), 5, FALSE )=0, "", VLOOKUP( $A7, _xlfn._xlws.FILTER( INDIRECT("'"&K$1&"'!A2:E1000"), (INDIRECT("'"&K$1&"'!B2:B1000")=$B7) * (INDIRECT("'"&K$1&"'!C2:C1000")=$C7) ), 5, FALSE ) )} -> Enviado | ... O7: {=IF( VLOOKUP( $A7, _xlfn._xlws.FILTER( INDIRECT("'"&O$1&"'!A2:E1000"), (INDIRECT("'"&O$1&"'!B2:B1000")=$B7) * (INDIRECT("'"&O$1&"'!C2:C1000")=$C7) ), 5, FALSE )=0, "", VLOOKUP( $A7, _xlfn._xlws.FILTER( INDIRECT("'"&O$1&"'!A2:E1000"), (INDIRECT("'"&O$1&"'!B2:B1000")=$B7) * (INDIRECT("'"&O$1&"'!C2:C1000")=$C7) ), 5, FALSE ) )}
A8: Coripa | B8: São Jorge do Patrocinio | C8: 1 | D8: {=IF( VLOOKUP( $A8, _xlfn._xlws.FILTER( INDIRECT("'"&D$1&"'!A2:E1000"), (INDIRECT("'"&D$1&"'!B2:B1000")=$B8) * (INDIRECT("'"&D$1&"'!C2:C1000")=$C8) ), 5, FALSE )=0, "", VLOOKUP( $A8, _xlfn._xlws.FILTER( INDIRECT("'"&D$1&"'!A2:E1000"), (INDIRECT("'"&D$1&"'!B2:B1000")=$B8) * (INDIRECT("'"&D$1&"'!C2:C1000")=$C8) ), 5, FALSE ) )} -> Sem Técnico | E8: {=IF( VLOOKUP( $A8, _xlfn._xlws.FILTER( INDIRECT("'"&E$1&"'!A2:E1000"), (INDIRECT("'"&E$1&"'!B2:B1000")=$B8) * (INDIRECT("'"&E$1&"'!C2:C1000")=$C8) ), 5, FALSE )=0, "", VLOOKUP( $A8, _xlfn._xlws.FILTER( INDIRECT("'"&E$1&"'!A2:E1000"), (INDIRECT("'"&E$1&"'!B2:B1000")=$B8) * (INDIRECT("'"&E$1&"'!C2:C1000")=$C8) ), 5, FALSE ) )} -> Sem Técnico | F8: {=IF( VLOOKUP( $A8, _xlfn._xlws.FILTER( INDIRECT("'"&F$1&"'!A2:E1000"), (INDIRECT("'"&F$1&"'!B2:B1000")=$B8) * (INDIRECT("'"&F$1&"'!C2:C1000")=$C8) ), 5, FALSE )=0, "", VLOOKUP( $A8, _xlfn._xlws.FILTER( INDIRECT("'"&F$1&"'!A2:E1000"), (INDIRECT("'"&F$1&"'!B2:B1000")=$B8) * (INDIRECT("'"&F$1&"'!C2:C1000")=$C8) ), 5, FALSE ) )} -> Sem Técnico | G8: {=IF( VLOOKUP( $A8, _xlfn._xlws.FILTER( INDIRECT("'"&G$1&"'!A2:E1000"), (INDIRECT("'"&G$1&"'!B2:B1000")=$B8) * (INDIRECT("'"&G$1&"'!C2:C1000")=$C8) ), 5, FALSE )=0, "", VLOOKUP( $A8, _xlfn._xlws.FILTER( INDIRECT("'"&G$1&"'!A2:E1000"), (INDIRECT("'"&G$1&"'!B2:B1000")=$B8) * (INDIRECT("'"&G$1&"'!C2:C1000")=$C8) ), 5, FALSE ) )} -> Sem Técnico | H8: {=IF( VLOOKUP( $A8, _xlfn._xlws.FILTER( INDIRECT("'"&H$1&"'!A2:E1000"), (INDIRECT("'"&H$1&"'!B2:B1000")=$B8) * (INDIRECT("'"&H$1&"'!C2:C1000")=$C8) ), 5, FALSE )=0, "", VLOOKUP( $A8, _xlfn._xlws.FILTER( INDIRECT("'"&H$1&"'!A2:E1000"), (INDIRECT("'"&H$1&"'!B2:B1000")=$B8) * (INDIRECT("'"&H$1&"'!C2:C1000")=$C8) ), 5, FALSE ) )} -> Sem Técnico | I8: {=IF( VLOOKUP( $A8, _xlfn._xlws.FILTER( INDIRECT("'"&I$1&"'!A2:E1000"), (INDIRECT("'"&I$1&"'!B2:B1000")=$B8) * (INDIRECT("'"&I$1&"'!C2:C1000")=$C8) ), 5, FALSE )=0, "", VLOOKUP( $A8, _xlfn._xlws.FILTER( INDIRECT("'"&I$1&"'!A2:E1000"), (INDIRECT("'"&I$1&"'!B2:B1000")=$B8) * (INDIRECT("'"&I$1&"'!C2:C1000")=$C8) ), 5, FALSE ) )} -> Sem Técnico | J8: {=IF( VLOOKUP( $A8, _xlfn._xlws.FILTER( INDIRECT("'"&J$1&"'!A2:E1000"), (INDIRECT("'"&J$1&"'!B2:B1000")=$B8) * (INDIRECT("'"&J$1&"'!C2:C1000")=$C8) ), 5, FALSE )=0, "", VLOOKUP( $A8, _xlfn._xlws.FILTER( INDIRECT("'"&J$1&"'!A2:E1000"), (INDIRECT("'"&J$1&"'!B2:B1000")=$B8) * (INDIRECT("'"&J$1&"'!C2:C1000")=$C8) ), 5, FALSE ) )} -> Sem Técnico | K8: {=IF( VLOOKUP( $A8, _xlfn._xlws.FILTER( INDIRECT("'"&K$1&"'!A2:E1000"), (INDIRECT("'"&K$1&"'!B2:B1000")=$B8) * (INDIRECT("'"&K$1&"'!C2:C1000")=$C8) ), 5, FALSE )=0, "", VLOOKUP( $A8, _xlfn._xlws.FILTER( INDIRECT("'"&K$1&"'!A2:E1000"), (INDIRECT("'"&K$1&"'!B2:B1000")=$B8) * (INDIRECT("'"&K$1&"'!C2:C1000")=$C8) ), 5, FALSE ) )} -> Atrasado >= 2 | ... O8: {=IF( VLOOKUP( $A8, _xlfn._xlws.FILTER( INDIRECT("'"&O$1&"'!A2:E1000"), (INDIRECT("'"&O$1&"'!B2:B1000")=$B8) * (INDIRECT("'"&O$1&"'!C2:C1000")=$C8) ), 5, FALSE )=0, "", VLOOKUP( $A8, _xlfn._xlws.FILTER( INDIRECT("'"&O$1&"'!A2:E1000"), (INDIRECT("'"&O$1&"'!B2:B1000")=$B8) * (INDIRECT("'"&O$1&"'!C2:C1000")=$C8) ), 5, FALSE ) )}
A9: Coripa | B9: Tapira | C9: 1 | D9: {=IF( VLOOKUP( $A9, _xlfn._xlws.FILTER( INDIRECT("'"&D$1&"'!A2:E1000"), (INDIRECT("'"&D$1&"'!B2:B1000")=$B9) * (INDIRECT("'"&D$1&"'!C2:C1000")=$C9) ), 5, FALSE )=0, "", VLOOKUP( $A9, _xlfn._xlws.FILTER( INDIRECT("'"&D$1&"'!A2:E1000"), (INDIRECT("'"&D$1&"'!B2:B1000")=$B9) * (INDIRECT("'"&D$1&"'!C2:C1000")=$C9) ), 5, FALSE ) )} -> Sem Técnico | E9: {=IF( VLOOKUP( $A9, _xlfn._xlws.FILTER( INDIRECT("'"&E$1&"'!A2:E1000"), (INDIRECT("'"&E$1&"'!B2:B1000")=$B9) * (INDIRECT("'"&E$1&"'!C2:C1000")=$C9) ), 5, FALSE )=0, "", VLOOKUP( $A9, _xlfn._xlws.FILTER( INDIRECT("'"&E$1&"'!A2:E1000"), (INDIRECT("'"&E$1&"'!B2:B1000")=$B9) * (INDIRECT("'"&E$1&"'!C2:C1000")=$C9) ), 5, FALSE ) )} -> Sem Técnico | F9: {=IF( VLOOKUP( $A9, _xlfn._xlws.FILTER( INDIRECT("'"&F$1&"'!A2:E1000"), (INDIRECT("'"&F$1&"'!B2:B1000")=$B9) * (INDIRECT("'"&F$1&"'!C2:C1000")=$C9) ), 5, FALSE )=0, "", VLOOKUP( $A9, _xlfn._xlws.FILTER( INDIRECT("'"&F$1&"'!A2:E1000"), (INDIRECT("'"&F$1&"'!B2:B1000")=$B9) * (INDIRECT("'"&F$1&"'!C2:C1000")=$C9) ), 5, FALSE ) )} -> Sem Técnico | G9: {=IF( VLOOKUP( $A9, _xlfn._xlws.FILTER( INDIRECT("'"&G$1&"'!A2:E1000"), (INDIRECT("'"&G$1&"'!B2:B1000")=$B9) * (INDIRECT("'"&G$1&"'!C2:C1000")=$C9) ), 5, FALSE )=0, "", VLOOKUP( $A9, _xlfn._xlws.FILTER( INDIRECT("'"&G$1&"'!A2:E1000"), (INDIRECT("'"&G$1&"'!B2:B1000")=$B9) * (INDIRECT("'"&G$1&"'!C2:C1000")=$C9) ), 5, FALSE ) )} -> Sem Técnico | H9: {=IF( VLOOKUP( $A9, _xlfn._xlws.FILTER( INDIRECT("'"&H$1&"'!A2:E1000"), (INDIRECT("'"&H$1&"'!B2:B1000")=$B9) * (INDIRECT("'"&H$1&"'!C2:C1000")=$C9) ), 5, FALSE )=0, "", VLOOKUP( $A9, _xlfn._xlws.FILTER( INDIRECT("'"&H$1&"'!A2:E1000"), (INDIRECT("'"&H$1&"'!B2:B1000")=$B9) * (INDIRECT("'"&H$1&"'!C2:C1000")=$C9) ), 5, FALSE ) )} -> Sem Técnico | I9: {=IF( VLOOKUP( $A9, _xlfn._xlws.FILTER( INDIRECT("'"&I$1&"'!A2:E1000"), (INDIRECT("'"&I$1&"'!B2:B1000")=$B9) * (INDIRECT("'"&I$1&"'!C2:C1000")=$C9) ), 5, FALSE )=0, "", VLOOKUP( $A9, _xlfn._xlws.FILTER( INDIRECT("'"&I$1&"'!A2:E1000"), (INDIRECT("'"&I$1&"'!B2:B1000")=$B9) * (INDIRECT("'"&I$1&"'!C2:C1000")=$C9) ), 5, FALSE ) )} -> Sem Técnico | J9: {=IF( VLOOKUP( $A9, _xlfn._xlws.FILTER( INDIRECT("'"&J$1&"'!A2:E1000"), (INDIRECT("'"&J$1&"'!B2:B1000")=$B9) * (INDIRECT("'"&J$1&"'!C2:C1000")=$C9) ), 5, FALSE )=0, "", VLOOKUP( $A9, _xlfn._xlws.FILTER( INDIRECT("'"&J$1&"'!A2:E1000"), (INDIRECT("'"&J$1&"'!B2:B1000")=$B9) * (INDIRECT("'"&J$1&"'!C2:C1000")=$C9) ), 5, FALSE ) )} -> Sem Técnico | K9: {=IF( VLOOKUP( $A9, _xlfn._xlws.FILTER( INDIRECT("'"&K$1&"'!A2:E1000"), (INDIRECT("'"&K$1&"'!B2:B1000")=$B9) * (INDIRECT("'"&K$1&"'!C2:C1000")=$C9) ), 5, FALSE )=0, "", VLOOKUP( $A9, _xlfn._xlws.FILTER( INDIRECT("'"&K$1&"'!A2:E1000"), (INDIRECT("'"&K$1&"'!B2:B1000")=$B9) * (INDIRECT("'"&K$1&"'!C2:C1000")=$C9) ), 5, FALSE ) )} -> Atrasado >= 2 | ... O9: {=IF( VLOOKUP( $A9, _xlfn._xlws.FILTER( INDIRECT("'"&O$1&"'!A2:E1000"), (INDIRECT("'"&O$1&"'!B2:B1000")=$B9) * (INDIRECT("'"&O$1&"'!C2:C1000")=$C9) ), 5, FALSE )=0, "", VLOOKUP( $A9, _xlfn._xlws.FILTER( INDIRECT("'"&O$1&"'!A2:E1000"), (INDIRECT("'"&O$1&"'!B2:B1000")=$B9) * (INDIRECT("'"&O$1&"'!C2:C1000")=$C9) ), 5, FALSE ) )}
A11: Regional | B11: Municípios | C11: UVR | D11: 01.25 | E11: 02.25 | F11: 03.25 | G11: 04.25 | H11: 05.25 | I11: 06.25 | J11: 07.25 | K11: 08.25 | L11: 09.25 | M11: 10.25 | N11: 11.25 | O11: 12.25
A12: Comafen | B12: Diamante do Norte | C12: 1 | D12: {=IF( VLOOKUP( $A12, _xlfn._xlws.FILTER( INDIRECT("'"&D$1&"'!A2:E1000"), (INDIRECT("'"&D$1&"'!B2:B1000")=$B12) * (INDIRECT("'"&D$1&"'!C2:C1000")=$C12) ), 5, FALSE )=0, "", VLOOKUP( $A12, _xlfn._xlws.FILTER( INDIRECT("'"&D$1&"'!A2:E1000"), (INDIRECT("'"&D$1&"'!B2:B1000")=$B12) * (INDIRECT("'"&D$1&"'!C2:C1000")=$C12) ), 5, FALSE ) )} -> Sem Técnico | E12: {=IF( VLOOKUP( $A12, _xlfn._xlws.FILTER( INDIRECT("'"&E$1&"'!A2:E1000"), (INDIRECT("'"&E$1&"'!B2:B1000")=$B12) * (INDIRECT("'"&E$1&"'!C2:C1000")=$C12) ), 5, FALSE )=0, "", VLOOKUP( $A12, _xlfn._xlws.FILTER( INDIRECT("'"&E$1&"'!A2:E1000"), (INDIRECT("'"&E$1&"'!B2:B1000")=$B12) * (INDIRECT("'"&E$1&"'!C2:C1000")=$C12) ), 5, FALSE ) )} -> Sem Técnico | F12: {=IF( VLOOKUP( $A12, _xlfn._xlws.FILTER( INDIRECT("'"&F$1&"'!A2:E1000"), (INDIRECT("'"&F$1&"'!B2:B1000")=$B12) * (INDIRECT("'"&F$1&"'!C2:C1000")=$C12) ), 5, FALSE )=0, "", VLOOKUP( $A12, _xlfn._xlws.FILTER( INDIRECT("'"&F$1&"'!A2:E1000"), (INDIRECT("'"&F$1&"'!B2:B1000")=$B12) * (INDIRECT("'"&F$1&"'!C2:C1000")=$C12) ), 5, FALSE ) )} -> Sem Técnico | G12: {=IF( VLOOKUP( $A12, _xlfn._xlws.FILTER( INDIRECT("'"&G$1&"'!A2:E1000"), (INDIRECT("'"&G$1&"'!B2:B1000")=$B12) * (INDIRECT("'"&G$1&"'!C2:C1000")=$C12) ), 5, FALSE )=0, "", VLOOKUP( $A12, _xlfn._xlws.FILTER( INDIRECT("'"&G$1&"'!A2:E1000"), (INDIRECT("'"&G$1&"'!B2:B1000")=$B12) * (INDIRECT("'"&G$1&"'!C2:C1000")=$C12) ), 5, FALSE ) )} -> Sem Técnico | H12: {=IF( VLOOKUP( $A12, _xlfn._xlws.FILTER( INDIRECT("'"&H$1&"'!A2:E1000"), (INDIRECT("'"&H$1&"'!B2:B1000")=$B12) * (INDIRECT("'"&H$1&"'!C2:C1000")=$C12) ), 5, FALSE )=0, "", VLOOKUP( $A12, _xlfn._xlws.FILTER( INDIRECT("'"&H$1&"'!A2:E1000"), (INDIRECT("'"&H$1&"'!B2:B1000")=$B12) * (INDIRECT("'"&H$1&"'!C2:C1000")=$C12) ), 5, FALSE ) )} -> Sem Técnico | I12: {=IF( VLOOKUP( $A12, _xlfn._xlws.FILTER( INDIRECT("'"&I$1&"'!A2:E1000"), (INDIRECT("'"&I$1&"'!B2:B1000")=$B12) * (INDIRECT("'"&I$1&"'!C2:C1000")=$C12) ), 5, FALSE )=0, "", VLOOKUP( $A12, _xlfn._xlws.FILTER( INDIRECT("'"&I$1&"'!A2:E1000"), (INDIRECT("'"&I$1&"'!B2:B1000")=$B12) * (INDIRECT("'"&I$1&"'!C2:C1000")=$C12) ), 5, FALSE ) )} -> Sem Técnico | J12: {=IF( VLOOKUP( $A12, _xlfn._xlws.FILTER( INDIRECT("'"&J$1&"'!A2:E1000"), (INDIRECT("'"&J$1&"'!B2:B1000")=$B12) * (INDIRECT("'"&J$1&"'!C2:C1000")=$C12) ), 5, FALSE )=0, "", VLOOKUP( $A12, _xlfn._xlws.FILTER( INDIRECT("'"&J$1&"'!A2:E1000"), (INDIRECT("'"&J$1&"'!B2:B1000")=$B12) * (INDIRECT("'"&J$1&"'!C2:C1000")=$C12) ), 5, FALSE ) )} -> Sem Técnico | K12: {=IF( VLOOKUP( $A12, _xlfn._xlws.FILTER( INDIRECT("'"&K$1&"'!A2:E1000"), (INDIRECT("'"&K$1&"'!B2:B1000")=$B12) * (INDIRECT("'"&K$1&"'!C2:C1000")=$C12) ), 5, FALSE )=0, "", VLOOKUP( $A12, _xlfn._xlws.FILTER( INDIRECT("'"&K$1&"'!A2:E1000"), (INDIRECT("'"&K$1&"'!B2:B1000")=$B12) * (INDIRECT("'"&K$1&"'!C2:C1000")=$C12) ), 5, FALSE ) )} -> Atrasado >= 2 | ... O12: {=IF( VLOOKUP( $A12, _xlfn._xlws.FILTER( INDIRECT("'"&O$1&"'!A2:E1000"), (INDIRECT("'"&O$1&"'!B2:B1000")=$B12) * (INDIRECT("'"&O$1&"'!C2:C1000")=$C12) ), 5, FALSE )=0, "", VLOOKUP( $A12, _xlfn._xlws.FILTER( INDIRECT("'"&O$1&"'!A2:E1000"), (INDIRECT("'"&O$1&"'!B2:B1000")=$B12) * (INDIRECT("'"&O$1&"'!C2:C1000")=$C12) ), 5, FALSE ) )}
A13: Comafen | B13: Itauna do Sul | C13: 1 | D13: {=IF( VLOOKUP( $A13, _xlfn._xlws.FILTER( INDIRECT("'"&D$1&"'!A2:E1000"), (INDIRECT("'"&D$1&"'!B2:B1000")=$B13) * (INDIRECT("'"&D$1&"'!C2:C1000")=$C13) ), 5, FALSE )=0, "", VLOOKUP( $A13, _xlfn._xlws.FILTER( INDIRECT("'"&D$1&"'!A2:E1000"), (INDIRECT("'"&D$1&"'!B2:B1000")=$B13) * (INDIRECT("'"&D$1&"'!C2:C1000")=$C13) ), 5, FALSE ) )} -> Sem Técnico | E13: {=IF( VLOOKUP( $A13, _xlfn._xlws.FILTER( INDIRECT("'"&E$1&"'!A2:E1000"), (INDIRECT("'"&E$1&"'!B2:B1000")=$B13) * (INDIRECT("'"&E$1&"'!C2:C1000")=$C13) ), 5, FALSE )=0, "", VLOOKUP( $A13, _xlfn._xlws.FILTER( INDIRECT("'"&E$1&"'!A2:E1000"), (INDIRECT("'"&E$1&"'!B2:B1000")=$B13) * (INDIRECT("'"&E$1&"'!C2:C1000")=$C13) ), 5, FALSE ) )} -> Sem Técnico | F13: {=IF( VLOOKUP( $A13, _xlfn._xlws.FILTER( INDIRECT("'"&F$1&"'!A2:E1000"), (INDIRECT("'"&F$1&"'!B2:B1000")=$B13) * (INDIRECT("'"&F$1&"'!C2:C1000")=$C13) ), 5, FALSE )=0, "", VLOOKUP( $A13, _xlfn._xlws.FILTER( INDIRECT("'"&F$1&"'!A2:E1000"), (INDIRECT("'"&F$1&"'!B2:B1000")=$B13) * (INDIRECT("'"&F$1&"'!C2:C1000")=$C13) ), 5, FALSE ) )} -> Sem Técnico | G13: {=IF( VLOOKUP( $A13, _xlfn._xlws.FILTER( INDIRECT("'"&G$1&"'!A2:E1000"), (INDIRECT("'"&G$1&"'!B2:B1000")=$B13) * (INDIRECT("'"&G$1&"'!C2:C1000")=$C13) ), 5, FALSE )=0, "", VLOOKUP( $A13, _xlfn._xlws.FILTER( INDIRECT("'"&G$1&"'!A2:E1000"), (INDIRECT("'"&G$1&"'!B2:B1000")=$B13) * (INDIRECT("'"&G$1&"'!C2:C1000")=$C13) ), 5, FALSE ) )} -> Sem Técnico | H13: {=IF( VLOOKUP( $A13, _xlfn._xlws.FILTER( INDIRECT("'"&H$1&"'!A2:E1000"), (INDIRECT("'"&H$1&"'!B2:B1000")=$B13) * (INDIRECT("'"&H$1&"'!C2:C1000")=$C13) ), 5, FALSE )=0, "", VLOOKUP( $A13, _xlfn._xlws.FILTER( INDIRECT("'"&H$1&"'!A2:E1000"), (INDIRECT("'"&H$1&"'!B2:B1000")=$B13) * (INDIRECT("'"&H$1&"'!C2:C1000")=$C13) ), 5, FALSE ) )} -> Sem Técnico | I13: {=IF( VLOOKUP( $A13, _xlfn._xlws.FILTER( INDIRECT("'"&I$1&"'!A2:E1000"), (INDIRECT("'"&I$1&"'!B2:B1000")=$B13) * (INDIRECT("'"&I$1&"'!C2:C1000")=$C13) ), 5, FALSE )=0, "", VLOOKUP( $A13, _xlfn._xlws.FILTER( INDIRECT("'"&I$1&"'!A2:E1000"), (INDIRECT("'"&I$1&"'!B2:B1000")=$B13) * (INDIRECT("'"&I$1&"'!C2:C1000")=$C13) ), 5, FALSE ) )} -> Sem Técnico | J13: {=IF( VLOOKUP( $A13, _xlfn._xlws.FILTER( INDIRECT("'"&J$1&"'!A2:E1000"), (INDIRECT("'"&J$1&"'!B2:B1000")=$B13) * (INDIRECT("'"&J$1&"'!C2:C1000")=$C13) ), 5, FALSE )=0, "", VLOOKUP( $A13, _xlfn._xlws.FILTER( INDIRECT("'"&J$1&"'!A2:E1000"), (INDIRECT("'"&J$1&"'!B2:B1000")=$B13) * (INDIRECT("'"&J$1&"'!C2:C1000")=$C13) ), 5, FALSE ) )} -> Sem Técnico | K13: {=IF( VLOOKUP( $A13, _xlfn._xlws.FILTER( INDIRECT("'"&K$1&"'!A2:E1000"), (INDIRECT("'"&K$1&"'!B2:B1000")=$B13) * (INDIRECT("'"&K$1&"'!C2:C1000")=$C13) ), 5, FALSE )=0, "", VLOOKUP( $A13, _xlfn._xlws.FILTER( INDIRECT("'"&K$1&"'!A2:E1000"), (INDIRECT("'"&K$1&"'!B2:B1000")=$B13) * (INDIRECT("'"&K$1&"'!C2:C1000")=$C13) ), 5, FALSE ) )} -> Atrasado >= 2 | ... O13: {=IF( VLOOKUP( $A13, _xlfn._xlws.FILTER( INDIRECT("'"&O$1&"'!A2:E1000"), (INDIRECT("'"&O$1&"'!B2:B1000")=$B13) * (INDIRECT("'"&O$1&"'!C2:C1000")=$C13) ), 5, FALSE )=0, "", VLOOKUP( $A13, _xlfn._xlws.FILTER( INDIRECT("'"&O$1&"'!A2:E1000"), (INDIRECT("'"&O$1&"'!B2:B1000")=$B13) * (INDIRECT("'"&O$1&"'!C2:C1000")=$C13) ), 5, FALSE ) )}
A14: Comafen | B14: Loanda | C14: 1 | D14: {=IF( VLOOKUP( $A14, _xlfn._xlws.FILTER( INDIRECT("'"&D$1&"'!A2:E1000"), (INDIRECT("'"&D$1&"'!B2:B1000")=$B14) * (INDIRECT("'"&D$1&"'!C2:C1000")=$C14) ), 5, FALSE )=0, "", VLOOKUP( $A14, _xlfn._xlws.FILTER( INDIRECT("'"&D$1&"'!A2:E1000"), (INDIRECT("'"&D$1&"'!B2:B1000")=$B14) * (INDIRECT("'"&D$1&"'!C2:C1000")=$C14) ), 5, FALSE ) )} -> Sem Técnico | E14: {=IF( VLOOKUP( $A14, _xlfn._xlws.FILTER( INDIRECT("'"&E$1&"'!A2:E1000"), (INDIRECT("'"&E$1&"'!B2:B1000")=$B14) * (INDIRECT("'"&E$1&"'!C2:C1000")=$C14) ), 5, FALSE )=0, "", VLOOKUP( $A14, _xlfn._xlws.FILTER( INDIRECT("'"&E$1&"'!A2:E1000"), (INDIRECT("'"&E$1&"'!B2:B1000")=$B14) * (INDIRECT("'"&E$1&"'!C2:C1000")=$C14) ), 5, FALSE ) )} -> Sem Técnico | F14: {=IF( VLOOKUP( $A14, _xlfn._xlws.FILTER( INDIRECT("'"&F$1&"'!A2:E1000"), (INDIRECT("'"&F$1&"'!B2:B1000")=$B14) * (INDIRECT("'"&F$1&"'!C2:C1000")=$C14) ), 5, FALSE )=0, "", VLOOKUP( $A14, _xlfn._xlws.FILTER( INDIRECT("'"&F$1&"'!A2:E1000"), (INDIRECT("'"&F$1&"'!B2:B1000")=$B14) * (INDIRECT("'"&F$1&"'!C2:C1000")=$C14) ), 5, FALSE ) )} -> Sem Técnico | G14: {=IF( VLOOKUP( $A14, _xlfn._xlws.FILTER( INDIRECT("'"&G$1&"'!A2:E1000"), (INDIRECT("'"&G$1&"'!B2:B1000")=$B14) * (INDIRECT("'"&G$1&"'!C2:C1000")=$C14) ), 5, FALSE )=0, "", VLOOKUP( $A14, _xlfn._xlws.FILTER( INDIRECT("'"&G$1&"'!A2:E1000"), (INDIRECT("'"&G$1&"'!B2:B1000")=$B14) * (INDIRECT("'"&G$1&"'!C2:C1000")=$C14) ), 5, FALSE ) )} -> Sem Técnico | H14: {=IF( VLOOKUP( $A14, _xlfn._xlws.FILTER( INDIRECT("'"&H$1&"'!A2:E1000"), (INDIRECT("'"&H$1&"'!B2:B1000")=$B14) * (INDIRECT("'"&H$1&"'!C2:C1000")=$C14) ), 5, FALSE )=0, "", VLOOKUP( $A14, _xlfn._xlws.FILTER( INDIRECT("'"&H$1&"'!A2:E1000"), (INDIRECT("'"&H$1&"'!B2:B1000")=$B14) * (INDIRECT("'"&H$1&"'!C2:C1000")=$C14) ), 5, FALSE ) )} -> Sem Técnico | I14: {=IF( VLOOKUP( $A14, _xlfn._xlws.FILTER( INDIRECT("'"&I$1&"'!A2:E1000"), (INDIRECT("'"&I$1&"'!B2:B1000")=$B14) * (INDIRECT("'"&I$1&"'!C2:C1000")=$C14) ), 5, FALSE )=0, "", VLOOKUP( $A14, _xlfn._xlws.FILTER( INDIRECT("'"&I$1&"'!A2:E1000"), (INDIRECT("'"&I$1&"'!B2:B1000")=$B14) * (INDIRECT("'"&I$1&"'!C2:C1000")=$C14) ), 5, FALSE ) )} -> Sem Técnico | J14: {=IF( VLOOKUP( $A14, _xlfn._xlws.FILTER( INDIRECT("'"&J$1&"'!A2:E1000"), (INDIRECT("'"&J$1&"'!B2:B1000")=$B14) * (INDIRECT("'"&J$1&"'!C2:C1000")=$C14) ), 5, FALSE )=0, "", VLOOKUP( $A14, _xlfn._xlws.FILTER( INDIRECT("'"&J$1&"'!A2:E1000"), (INDIRECT("'"&J$1&"'!B2:B1000")=$B14) * (INDIRECT("'"&J$1&"'!C2:C1000")=$C14) ), 5, FALSE ) )} -> Sem Técnico | K14: {=IF( VLOOKUP( $A14, _xlfn._xlws.FILTER( INDIRECT("'"&K$1&"'!A2:E1000"), (INDIRECT("'"&K$1&"'!B2:B1000")=$B14) * (INDIRECT("'"&K$1&"'!C2:C1000")=$C14) ), 5, FALSE )=0, "", VLOOKUP( $A14, _xlfn._xlws.FILTER( INDIRECT("'"&K$1&"'!A2:E1000"), (INDIRECT("'"&K$1&"'!B2:B1000")=$B14) * (INDIRECT("'"&K$1&"'!C2:C1000")=$C14) ), 5, FALSE ) )} -> Atrasado >= 2 | ... O14: {=IF( VLOOKUP( $A14, _xlfn._xlws.FILTER( INDIRECT("'"&O$1&"'!A2:E1000"), (INDIRECT("'"&O$1&"'!B2:B1000")=$B14) * (INDIRECT("'"&O$1&"'!C2:C1000")=$C14) ), 5, FALSE )=0, "", VLOOKUP( $A14, _xlfn._xlws.FILTER( INDIRECT("'"&O$1&"'!A2:E1000"), (INDIRECT("'"&O$1&"'!B2:B1000")=$B14) * (INDIRECT("'"&O$1&"'!C2:C1000")=$C14) ), 5, FALSE ) )}
A15: Comafen | B15: Marilena | C15: 1 | D15: {=IF( VLOOKUP( $A15, _xlfn._xlws.FILTER( INDIRECT("'"&D$1&"'!A2:E1000"), (INDIRECT("'"&D$1&"'!B2:B1000")=$B15) * (INDIRECT("'"&D$1&"'!C2:C1000")=$C15) ), 5, FALSE )=0, "", VLOOKUP( $A15, _xlfn._xlws.FILTER( INDIRECT("'"&D$1&"'!A2:E1000"), (INDIRECT("'"&D$1&"'!B2:B1000")=$B15) * (INDIRECT("'"&D$1&"'!C2:C1000")=$C15) ), 5, FALSE ) )} -> Sem Técnico | E15: {=IF( VLOOKUP( $A15, _xlfn._xlws.FILTER( INDIRECT("'"&E$1&"'!A2:E1000"), (INDIRECT("'"&E$1&"'!B2:B1000")=$B15) * (INDIRECT("'"&E$1&"'!C2:C1000")=$C15) ), 5, FALSE )=0, "", VLOOKUP( $A15, _xlfn._xlws.FILTER( INDIRECT("'"&E$1&"'!A2:E1000"), (INDIRECT("'"&E$1&"'!B2:B1000")=$B15) * (INDIRECT("'"&E$1&"'!C2:C1000")=$C15) ), 5, FALSE ) )} -> Sem Técnico | F15: {=IF( VLOOKUP( $A15, _xlfn._xlws.FILTER( INDIRECT("'"&F$1&"'!A2:E1000"), (INDIRECT("'"&F$1&"'!B2:B1000")=$B15) * (INDIRECT("'"&F$1&"'!C2:C1000")=$C15) ), 5, FALSE )=0, "", VLOOKUP( $A15, _xlfn._xlws.FILTER( INDIRECT("'"&F$1&"'!A2:E1000"), (INDIRECT("'"&F$1&"'!B2:B1000")=$B15) * (INDIRECT("'"&F$1&"'!C2:C1000")=$C15) ), 5, FALSE ) )} -> Sem Técnico | G15: {=IF( VLOOKUP( $A15, _xlfn._xlws.FILTER( INDIRECT("'"&G$1&"'!A2:E1000"), (INDIRECT("'"&G$1&"'!B2:B1000")=$B15) * (INDIRECT("'"&G$1&"'!C2:C1000")=$C15) ), 5, FALSE )=0, "", VLOOKUP( $A15, _xlfn._xlws.FILTER( INDIRECT("'"&G$1&"'!A2:E1000"), (INDIRECT("'"&G$1&"'!B2:B1000")=$B15) * (INDIRECT("'"&G$1&"'!C2:C1000")=$C15) ), 5, FALSE ) )} -> Sem Técnico | H15: {=IF( VLOOKUP( $A15, _xlfn._xlws.FILTER( INDIRECT("'"&H$1&"'!A2:E1000"), (INDIRECT("'"&H$1&"'!B2:B1000")=$B15) * (INDIRECT("'"&H$1&"'!C2:C1000")=$C15) ), 5, FALSE )=0, "", VLOOKUP( $A15, _xlfn._xlws.FILTER( INDIRECT("'"&H$1&"'!A2:E1000"), (INDIRECT("'"&H$1&"'!B2:B1000")=$B15) * (INDIRECT("'"&H$1&"'!C2:C1000")=$C15) ), 5, FALSE ) )} -> Sem Técnico | I15: {=IF( VLOOKUP( $A15, _xlfn._xlws.FILTER( INDIRECT("'"&I$1&"'!A2:E1000"), (INDIRECT("'"&I$1&"'!B2:B1000")=$B15) * (INDIRECT("'"&I$1&"'!C2:C1000")=$C15) ), 5, FALSE )=0, "", VLOOKUP( $A15, _xlfn._xlws.FILTER( INDIRECT("'"&I$1&"'!A2:E1000"), (INDIRECT("'"&I$1&"'!B2:B1000")=$B15) * (INDIRECT("'"&I$1&"'!C2:C1000")=$C15) ), 5, FALSE ) )} -> Sem Técnico | J15: {=IF( VLOOKUP( $A15, _xlfn._xlws.FILTER( INDIRECT("'"&J$1&"'!A2:E1000"), (INDIRECT("'"&J$1&"'!B2:B1000")=$B15) * (INDIRECT("'"&J$1&"'!C2:C1000")=$C15) ), 5, FALSE )=0, "", VLOOKUP( $A15, _xlfn._xlws.FILTER( INDIRECT("'"&J$1&"'!A2:E1000"), (INDIRECT("'"&J$1&"'!B2:B1000")=$B15) * (INDIRECT("'"&J$1&"'!C2:C1000")=$C15) ), 5, FALSE ) )} -> Sem Técnico | K15: {=IF( VLOOKUP( $A15, _xlfn._xlws.FILTER( INDIRECT("'"&K$1&"'!A2:E1000"), (INDIRECT("'"&K$1&"'!B2:B1000")=$B15) * (INDIRECT("'"&K$1&"'!C2:C1000")=$C15) ), 5, FALSE )=0, "", VLOOKUP( $A15, _xlfn._xlws.FILTER( INDIRECT("'"&K$1&"'!A2:E1000"), (INDIRECT("'"&K$1&"'!B2:B1000")=$B15) * (INDIRECT("'"&K$1&"'!C2:C1000")=$C15) ), 5, FALSE ) )} -> Atrasado >= 2 | ... O15: {=IF( VLOOKUP( $A15, _xlfn._xlws.FILTER( INDIRECT("'"&O$1&"'!A2:E1000"), (INDIRECT("'"&O$1&"'!B2:B1000")=$B15) * (INDIRECT("'"&O$1&"'!C2:C1000")=$C15) ), 5, FALSE )=0, "", VLOOKUP( $A15, _xlfn._xlws.FILTER( INDIRECT("'"&O$1&"'!A2:E1000"), (INDIRECT("'"&O$1&"'!B2:B1000")=$B15) * (INDIRECT("'"&O$1&"'!C2:C1000")=$C15) ), 5, FALSE ) )}
A16: Comafen | B16: Nova Londrina | C16: 1 | D16: {=IF( VLOOKUP( $A16, _xlfn._xlws.FILTER( INDIRECT("'"&D$1&"'!A2:E1000"), (INDIRECT("'"&D$1&"'!B2:B1000")=$B16) * (INDIRECT("'"&D$1&"'!C2:C1000")=$C16) ), 5, FALSE )=0, "", VLOOKUP( $A16, _xlfn._xlws.FILTER( INDIRECT("'"&D$1&"'!A2:E1000"), (INDIRECT("'"&D$1&"'!B2:B1000")=$B16) * (INDIRECT("'"&D$1&"'!C2:C1000")=$C16) ), 5, FALSE ) )} -> Sem Técnico | E16: {=IF( VLOOKUP( $A16, _xlfn._xlws.FILTER( INDIRECT("'"&E$1&"'!A2:E1000"), (INDIRECT("'"&E$1&"'!B2:B1000")=$B16) * (INDIRECT("'"&E$1&"'!C2:C1000")=$C16) ), 5, FALSE )=0, "", VLOOKUP( $A16, _xlfn._xlws.FILTER( INDIRECT("'"&E$1&"'!A2:E1000"), (INDIRECT("'"&E$1&"'!B2:B1000")=$B16) * (INDIRECT("'"&E$1&"'!C2:C1000")=$C16) ), 5, FALSE ) )} -> Sem Técnico | F16: {=IF( VLOOKUP( $A16, _xlfn._xlws.FILTER( INDIRECT("'"&F$1&"'!A2:E1000"), (INDIRECT("'"&F$1&"'!B2:B1000")=$B16) * (INDIRECT("'"&F$1&"'!C2:C1000")=$C16) ), 5, FALSE )=0, "", VLOOKUP( $A16, _xlfn._xlws.FILTER( INDIRECT("'"&F$1&"'!A2:E1000"), (INDIRECT("'"&F$1&"'!B2:B1000")=$B16) * (INDIRECT("'"&F$1&"'!C2:C1000")=$C16) ), 5, FALSE ) )} -> Sem Técnico | G16: {=IF( VLOOKUP( $A16, _xlfn._xlws.FILTER( INDIRECT("'"&G$1&"'!A2:E1000"), (INDIRECT("'"&G$1&"'!B2:B1000")=$B16) * (INDIRECT("'"&G$1&"'!C2:C1000")=$C16) ), 5, FALSE )=0, "", VLOOKUP( $A16, _xlfn._xlws.FILTER( INDIRECT("'"&G$1&"'!A2:E1000"), (INDIRECT("'"&G$1&"'!B2:B1000")=$B16) * (INDIRECT("'"&G$1&"'!C2:C1000")=$C16) ), 5, FALSE ) )} -> Sem Técnico | H16: {=IF( VLOOKUP( $A16, _xlfn._xlws.FILTER( INDIRECT("'"&H$1&"'!A2:E1000"), (INDIRECT("'"&H$1&"'!B2:B1000")=$B16) * (INDIRECT("'"&H$1&"'!C2:C1000")=$C16) ), 5, FALSE )=0, "", VLOOKUP( $A16, _xlfn._xlws.FILTER( INDIRECT("'"&H$1&"'!A2:E1000"), (INDIRECT("'"&H$1&"'!B2:B1000")=$B16) * (INDIRECT("'"&H$1&"'!C2:C1000")=$C16) ), 5, FALSE ) )} -> Sem Técnico | I16: {=IF( VLOOKUP( $A16, _xlfn._xlws.FILTER( INDIRECT("'"&I$1&"'!A2:E1000"), (INDIRECT("'"&I$1&"'!B2:B1000")=$B16) * (INDIRECT("'"&I$1&"'!C2:C1000")=$C16) ), 5, FALSE )=0, "", VLOOKUP( $A16, _xlfn._xlws.FILTER( INDIRECT("'"&I$1&"'!A2:E1000"), (INDIRECT("'"&I$1&"'!B2:B1000")=$B16) * (INDIRECT("'"&I$1&"'!C2:C1000")=$C16) ), 5, FALSE ) )} -> Sem Técnico | J16: {=IF( VLOOKUP( $A16, _xlfn._xlws.FILTER( INDIRECT("'"&J$1&"'!A2:E1000"), (INDIRECT("'"&J$1&"'!B2:B1000")=$B16) * (INDIRECT("'"&J$1&"'!C2:C1000")=$C16) ), 5, FALSE )=0, "", VLOOKUP( $A16, _xlfn._xlws.FILTER( INDIRECT("'"&J$1&"'!A2:E1000"), (INDIRECT("'"&J$1&"'!B2:B1000")=$B16) * (INDIRECT("'"&J$1&"'!C2:C1000")=$C16) ), 5, FALSE ) )} -> Sem Técnico | K16: {=IF( VLOOKUP( $A16, _xlfn._xlws.FILTER( INDIRECT("'"&K$1&"'!A2:E1000"), (INDIRECT("'"&K$1&"'!B2:B1000")=$B16) * (INDIRECT("'"&K$1&"'!C2:C1000")=$C16) ), 5, FALSE )=0, "", VLOOKUP( $A16, _xlfn._xlws.FILTER( INDIRECT("'"&K$1&"'!A2:E1000"), (INDIRECT("'"&K$1&"'!B2:B1000")=$B16) * (INDIRECT("'"&K$1&"'!C2:C1000")=$C16) ), 5, FALSE ) )} -> Atrasado >= 2 | ... O16: {=IF( VLOOKUP( $A16, _xlfn._xlws.FILTER( INDIRECT("'"&O$1&"'!A2:E1000"), (INDIRECT("'"&O$1&"'!B2:B1000")=$B16) * (INDIRECT("'"&O$1&"'!C2:C1000")=$C16) ), 5, FALSE )=0, "", VLOOKUP( $A16, _xlfn._xlws.FILTER( INDIRECT("'"&O$1&"'!A2:E1000"), (INDIRECT("'"&O$1&"'!B2:B1000")=$B16) * (INDIRECT("'"&O$1&"'!C2:C1000")=$C16) ), 5, FALSE ) )}
