Workbook

Sheet Lacunas
A1: Regional | B1: Município | C1: UVR | D1: Mês da Lacuna | E1: Data de Referência CSV | F1: Data de Referência CSV - Trocado
A2: Valquiria | B2: Formosa do Oeste | C2: 01 | D2: 11.24 | E2: 15/11/2024 | F2: =""&RIGHT(LEFT(E2,5),2)&"/"&LEFT(E2,2)&"/"&RIGHT(E2,4) -> 11/15/2024
A3: Gabriel | B3: Maripa | C3: 01 | D3: 11.24 | E3: 15/11/2024 | F3: =""&RIGHT(LEFT(E3,5),2)&"/"&LEFT(E3,2)&"/"&RIGHT(E3,4) -> 11/15/2024
A4: Gabriel | B4: Mundo Novo | C4: 01 | D4: 11.24 | E4: 15/11/2024 | F4: =""&RIGHT(LEFT(E4,5),2)&"/"&LEFT(E4,2)&"/"&RIGHT(E4,4) -> 11/15/2024
A5: Gabriel | B5: Assis Chateaubriand | C5: 01 | D5: 12.24 | E5: 15/12/2024 | F5: =""&RIGHT(LEFT(E5,5),2)&"/"&LEFT(E5,2)&"/"&RIGHT(E5,4) -> 12/15/2024
A6: Valquiria | B6: Cafelândia | C6: 01 | D6: 12.24 | E6: 15/12/2024 | F6: =""&RIGHT(LEFT(E6,5),2)&"/"&LEFT(E6,2)&"/"&RIGHT(E6,4) -> 12/15/2024
A7: Valquiria | B7: Formosa do Oeste | C7: 01 | D7: 12.24 | E7: 15/12/2024 | F7: =""&RIGHT(LEFT(E7,5),2)&"/"&LEFT(E7,2)&"/"&RIGHT(E7,4) -> 12/15/2024
A8: Larissa | B8: Foz do Iguaçu | C8: 06 | D8: 12.24 | E8: 15/12/2024 | F8: =""&RIGHT(LEFT(E8,5),2)&"/"&LEFT(E8,2)&"/"&RIGHT(E8,4) -> 12/15/2024
A9: Valquiria | B9: Jesuítas | C9: 01 | D9: 12.24 | E9: 15/12/2024 | F9: =""&RIGHT(LEFT(E9,5),2)&"/"&LEFT(E9,2)&"/"&RIGHT(E9,4) -> 12/15/2024
A10: Luana | B10: Marechal Candido Rondon | C10: 01 | D10: 12.24 | E10: 15/12/2024 | F10: =""&RIGHT(LEFT(E10,5),2)&"/"&LEFT(E10,2)&"/"&RIGHT(E10,4) -> 12/15/2024
A11: Luana | B11: Marechal Candido Rondon | C11: 02 | D11: 12.24 | E11: 15/12/2024 | F11: =""&RIGHT(LEFT(E11,5),2)&"/"&LEFT(E11,2)&"/"&RIGHT(E11,4) -> 12/15/2024
A12: Gabriel | B12: Maripa | C12: 01 | D12: 12.24 | E12: 15/12/2024 | F12: =""&RIGHT(LEFT(E12,5),2)&"/"&LEFT(E12,2)&"/"&RIGHT(E12,4) -> 12/15/2024
A13: Gabriel | B13: Palotina | C13: 01 | D13: 12.24 | E13: 15/12/2024 | F13: =""&RIGHT(LEFT(E13,5),2)&"/"&LEFT(E13,2)&"/"&RIGHT(E13,4) -> 12/15/2024
A14: Gabriel | B14: Assis Chateaubriand | C14: 01 | D14: 01.25 | E14: 15/1/2025 | F14: =""&RIGHT(LEFT(E14,5),2)&""&LEFT(E14,2)&"/"&RIGHT(E14,4) -> 1/15/2025
A15: Gabriel | B15: Brasilândia do Sul | C15: 01 | D15: 01.25 | E15: 15/1/2025 | F15: =""&RIGHT(LEFT(E15,5),2)&""&LEFT(E15,2)&"/"&RIGHT(E15,4) -> 1/15/2025
A16: Valquiria | B16: Cafelândia | C16: 01 | D16: 01.25 | E16: 15/1/2025 | F16: =""&RIGHT(LEFT(E16,5),2)&""&LEFT(E16,2)&"/"&RIGHT(E16,4) -> 1/15/2025
A17: Larissa | B17: Foz do Iguaçu | C17: 06 | D17: 01.25 | E17: 15/1/2025 | F17: =""&RIGHT(LEFT(E17,5),2)&""&LEFT(E17,2)&"/"&RIGHT(E17,4) -> 1/15/2025
A18: Valquiria | B18: Jesuítas | C18: 01 | D18: 01.25 | E18: 15/1/2025 | F18: =""&RIGHT(LEFT(E18,5),2)&""&LEFT(E18,2)&"/"&RIGHT(E18,4) -> 1/15/2025
A19: Luana | B19: Marechal Candido Rondon | C19: 01 | D19: 01.25 | E19: 15/1/2025 | F19: =""&RIGHT(LEFT(E19,5),2)&""&LEFT(E19,2)&"/"&RIGHT(E19,4) -> 1/15/2025
A20: Luana | B20: Marechal Candido Rondon | C20: 02 | D20: 01.25 | E20: 15/1/2025 | F20: =""&RIGHT(LEFT(E20,5),2)&""&LEFT(E20,2)&"/"&RIGHT(E20,4) -> 1/15/2025
A21: Gabriel | B21: Palotina | C21: 01 | D21: 01.25 | E21: 15/1/2025 | F21: =""&RIGHT(LEFT(E21,5),2)&""&LEFT(E21,2)&"/"&RIGHT(E21,4) -> 1/15/2025
A22: Gabriel | B22: Palotina | C22: 01 | D22: 01.25 | E22: 15/1/2025 | F22: =""&RIGHT(LEFT(E22,5),2)&""&LEFT(E22,2)&"/"&RIGHT(E22,4) -> 1/15/2025
A23: Bianca | B23: Tres Barras do Parana | C23: 01 | D23: 01.25 | E23: 15/1/2025 | F23: =""&RIGHT(LEFT(E23,5),2)&""&LEFT(E23,2)&"/"&RIGHT(E23,4) -> 1/15/2025

Sheet Macro Dados - Todos
A1: Município | B1: UVR Município + Número | C1: UVR Número | D1: Data de referência | E1: Número de catadores na UVR no mês da data de referência | F1: Observações | G1: Receita venda recicláveis | H1: Receita prestação serviços | I1: Despesas | J1: Quantidade de recicláveis vendidos (kg) | K1: Rejeito (kg) | L1: Renda média catadores
A2: Boa Vista da Aparecida | B2: UVR 01 - Boa Vista da Aparecida | C2: 01 | D2: 15/11/2024 | E2: 9 | G2: 19071.16 | H2: 0 | I2: 0 | J2: 16471.4 | K2: 0 | L2: 1200
A3: Matelândia | B3: UVR 01 - Matelândia | C3: 01 | D3: 15/11/2024 | E3: 19 | F3: Essa valor corresponde a divisão entre os 19 associados. Entretanto, cabe ressaltar que a divisão é realizado por um associado a mais, com escopo de promover o diferencial dos coletores. Destarte, isso, há na somatória as sobras de um associado, 17 dias. | G3: 67793.31 | H3: 26176.5 | I3: 7256.65 | J3: 59380.3 | K3: 22672 | L3: 4478.52
A4: Terra Roxa | B4: UVR 01 - Terra Roxa | C4: 01 | D4: 15/11/2024 | E4: 15 | G4: 25610.16 | H4: 25610.16 | I4: 477.25 | J4: 33396.6 | K4: 13697.9 | L4: 2176.34
A5: Palotina | B5: UVR 01 - Palotina | C5: 01 | D5: 15/11/2024 | E5: 20 | F5: O total de Associados que trabalharam todos os dias( não tiveram faltas) foram 2 dois) | G5: 60299.1 | H5: 0 | I5: 12857.6 | J5: 94134 | K5: 59280 | L5: 3489.6
A6: Foz do Iguaçu | B6: UVR 04 - Foz do Iguaçu | C6: 04 | D6: 15/11/2024 | E6: 21 | F6: Os valores acima se referem ao mês de Novembro. | G6: 48942.46 | H6: 35639.19 | I6: 35639.19 | J6: 41305.4 | K6: 6100 | L6: 2933.21
A7: Capitão Leonidas Marques | B7: UVR 01 - Capitão Leonidas Marques | C7: 01 | D7: 15/11/2024 | E7: 17 | G7: 63618.97 | H7: 22223.11 | I7: 31891.02 | J7: 61224.5 | K7: 8825 | L7: 3156.12
A8: Foz do Iguaçu | B8: UVR 08 - Foz do Iguaçu | C8: 08 | D8: 15/11/2024 | E8: 19 | G8: 17530.5 | H8: 29212.43 | I8: 22694.42 | J8: 22318 | K8: 3347.7 | L8: 1368
A9: Missal | B9: UVR 01 - Missal | C9: 01 | D9: 15/11/2024 | E9: 20 | G9: 66332.61 | H9: 77678.97 | I9: 8627.96 | J9: 64840.18 | K9: 11.87 | L9: 3848.61
A10: Cascavel | B10: UVR 06 - Cascavel | C10: 06 | D10: 15/11/2024 | E10: 16 | G10: 23098.7 | H10: 1123.68 | I10: 9730.39 | J10: 24649.8 | K10: 4340.3 | L10: 1015.01
A11: Foz do Iguaçu | B11: UVR 03 - Foz do Iguaçu | C11: 03 | D11: 15/11/2024 | E11: 20 | G11: 30408.25 | H11: 39123.23 | I11: 24093.5 | J11: 43674.5 | K11: 6551 | L11: 2700
A12: Diamante do Sul | B12: UVR 01 - Diamante do Sul | C12: 01 | D12: 15/11/2024 | E12: 1 | G12: 6282.8 | H12: 0 | I12: 2200 | J12: 5570 | K12: 0 | L12: 4083.5
A13: Cascavel | B13: UVR 03 - Cascavel | C13: 03 | D13: 15/11/2024 | E13: 21 | G13: 44923.39 | H13: 19122.44 | I13: 23286.2 | J13: 66740 | K13: 14198.7 | L13: 1240.06
A14: São Pedro do Iguaçu | B14: UVR 01 - São Pedro do Iguaçu | C14: 01 | D14: 15/11/2024 | E14: 14 | G14: 17061.9 | H14: 9000 | I14: 0 | J14: 17656 | K14: 1600 | L14: 1981.6
A15: Serranopolis do Iguaçu | B15: UVR 01 - Serranopolis do Iguaçu | C15: 01 | D15: 15/11/2024 | E15: 10 | G15: 21807.74 | H15: 12249 | I15: 5460.57 | J15: 21585.5 | K15: 5639 | L15: 2860.51
A16: Itaipulândia | B16: UVR 01 - Itaipulândia | C16: 01 | D16: 15/11/2024 | E16: 60 | F16: 1 se encontra em auxilio reclusão | G16: 93880.62 | H16: 92350.38 | I16: 32721.62 | J16: 85412.81 | K16: 16950 | L16: 2601.5
A17: Foz do Iguaçu | B17: UVR 05 - Foz do Iguaçu | C17: 05 | D17: 15/11/2024 | E17: 14 | F17: Valores referente ao mês de novembro | G17: 29531.08 | H17: 39123.24 | I17: 39123.24 | J17: 43525.2 | K17: 6525 | L17: 2280.39
A18: Campo Bonito | B18: UVR 01 - Campo Bonito | C18: 01 | D18: 15/11/2024 | E18: 8 | G18: 13672.84 | H18: 19500 | I18: 7735.18 | J18: 11611.6 | K18: 4800 | L18: 2936.5
A19: Mundo Novo | B19: UVR 01 - Mundo Novo | C19: 01 | D19: 15/11/2024 | E19: 15 | G19: 35681.9 | H19: 0 | I19: 628.32 | J19: 51259.5 | K19: 5469 | L19: 2334.2
A20: Santa Helena | B20: UVR 01 - Santa Helena | C20: 01 | D20: 15/11/2024 | E20: 69 | G20: 93013.12 | H20: 0 | I20: 28451.22 | J20: 113235.1 | K20: 15000 | L20: 2104.83
A21: Vera Cruz do Oeste | B21: UVR 01 - Vera Cruz do Oeste | C21: 01 | D21: 15/11/2024 | E21: 16 | G21: 17881.93 | H21: 6660.28 | I21: 7837.81 | J21: 19418 | K21: 8780 | L21: 1500
A22: Jesuítas | B22: UVR 01 - Jesuítas | C22: 01 | D22: 15/11/2024 | E22: 9 | G22: 31383.45 | H22: 0 | I22: 0 | J22: 34526 | K22: 0 | L22: 3487
A23: Assis Chateaubriand | B23: UVR 01 - Assis Chateaubriand | C23: 01 | D23: 15/11/2024 | E23: 35 | F23: 1 à 18/11/2024. O término do mês foi antecipado, devido ao encerramento do contrato com o município. | G23: 50302.61 | H23: 15245.65 | I23: 870.37 | J23: 43559 | K23: 20650 | L23: 1936.56
A24: Iguatu | B24: UVR 01 - Iguatu | C24: 01 | D24: 15/11/2024 | E24: 5 | G24: 5806.27 | H24: 2653 | I24: 1100 | J24: 7580 | K24: 915 | L24: 1800
A25: Anahy | B25: UVR 01 - Anahy | C25: 01 | D25: 15/11/2024 | E25: 5 | G25: 8731.05 | H25: 0 | I25: 0 | J25: 10080 | K25: 0 | L25: 3129.24
A26: Pato Bragado | B26: UVR 01 - Pato Bragado | C26: 01 | D26: 15/11/2024 | E26: 11 | G26: 25017.69 | H26: 20059.85 | I26: 15663.72 | J26: 25560.89 | K26: 3072.09 | L26: 1889.8
A27: São Miguel do Iguaçu | B27: UVR 01 - São Miguel do Iguaçu | C27: 01 | D27: 15/11/2024 | E27: 41 | F27: renda com prestação de serviço | G27: 70493.19 | H27: 32570 | I27: 12341.4 | J27: 77242.2 | K27: 42550 | L27: 3000
A28: Medianeira | B28: UVR 01 - Medianeira | C28: 01 | D28: 15/11/2024 | E28: 50 | G28: 65077.51 | H28: 35250 | I28: 11112.5 | J28: 66201.5 | K28: 2750 | L28: 2064.27
A29: São Jose das Palmeiras | B29: UVR 01 - São Jose das Palmeiras | C29: 01 | D29: 15/11/2024 | E29: 6 | G29: 12943.5 | H29: 10220.59 | I29: 1197.79 | J29: 10725.3 | K29: 1121 | L29: 3660.8
A30: Catanduvas | B30: UVR 01 - Catanduvas | C30: 01 | D30: 15/11/2024 | E30: 10 | G30: 29839.84 | H30: 10036.15 | I30: 790.81 | J30: 24389 | K30: 4719 | L30: 3550
A31: Cafelândia | B31: UVR 01 - Cafelândia | C31: 01 | D31: 15/11/2024 | E31: 54 | G31: 53998.08 | H31: 0 | I31: 18963.58 | J31: 60590 | K31: 0 | L31: 2210
A32: Cascavel | B32: UVR 02 - Cascavel | C32: 02 | D32: 15/11/2024 | E32: 24 | G32: 68057.39 | H32: 59808.36 | I32: 28912.5 | J32: 99914.5 | K32: 9557.13 | L32: 1958.59
A33: Nova Santa Rosa | B33: UVR 01 - Nova Santa Rosa | C33: 01 | D33: 15/11/2024 | E33: 9 | G33: 25895.9 | H33: 6090.29 | I33: 1982.59 | J33: 33698.5 | K33: 3580 | L33: 3628.57
A34: Tupassi | B34: UVR 01 - Tupassi | C34: 01 | D34: 15/11/2024 | E34: 3 | G34: 8253.88 | H34: 0 | I34: 293 | J34: 10204 | K34: 2500 | L34: 2751
A35: Altônia | B35: UVR 01 - Altônia | C35: 01 | D35: 15/11/2024 | E35: 15 | G35: 34460.29 | H35: 0 | I35: 2630.77 | J35: 39412.5 | K35: 4474 | L35: 2500
A36: Cascavel | B36: UVR 04 - Cascavel | C36: 04 | D36: 15/11/2024 | E36: 22 | G36: 34172.1 | H36: 550 | I36: 17072.86 | J36: 27595.2 | K36: 10907 | L36: 1500
A37: Iracema do Oeste | B37: UVR 01 - Iracema do Oeste | C37: 01 | D37: 15/11/2024 | E37: 7 | G37: 11556.5 | H37: 16512 | I37: 1087.24 | J37: 14886.5 | K37: 1402 | L37: 2732.74
A38: Ubirata | B38: UVR 01 - Ubirata | C38: 01 | D38: 15/11/2024 | E38: 16 | G38: 32144.62 | H38: 5074.23 | I38: 3883.5 | J38: 30060 | K38: 10000 | L38: 2328.15
A39: Tres Barras do Parana | B39: UVR 01 - Tres Barras do Parana | C39: 01 | D39: 15/11/2024 | E39: 10 | G39: 24170.2 | H39: 1300 | I39: 0 | J39: 42170 | K39: 0 | L39: 2800
A40: Toledo | B40: UVR 01 - Toledo | C40: 01 | D40: 15/11/2024 | E40: 60 | G40: 109016.76 | H40: 40158 | I40: 112000 | J40: 200740 | K40: 134770 | L40: 2200
...

Sheet Macro Dados - Filtrados
A1: Regional | B1: Município | C1: UVR Município + Número | D1: UVR Número | E1: Data de referência | F1: Número de catadores na UVR no mês da data de referência | G1: Observações | H1: Receita venda recicláveis | I1: Receita prestação serviços | J1: Despesas | K1: Quantidade de recicláveis vendidos (kg) | L1: Rejeito (kg) | M1: Renda média catadores
A2: Valquiria | B2: {=_xlfn._xlws.FILTER( 'Macro Dados - Todos'!$A$2:$L$20000, ('Macro Dados - Todos'!$A$2:$A$20000=Lacunas!B2) * ('Macro Dados - Todos'!$C$2:$C$20000=Lacunas!C2) * ('Macro Dados - Todos'!$D$2:$D$20000=Lacunas!E2) )} -> Formosa do Oeste | C2: UVR 01 - Formosa do Oeste | D2: 01 | E2: 15/11/2024 | F2: 7 | G2: 0 | H2: 9598.75 | I2: 0 | J2: 0 | K2: 7363 | L2: 3620 | M2: 1371.25
A3: Gabriel | B3: {=_xlfn._xlws.FILTER( 'Macro Dados - Todos'!$A$2:$L$20000, ('Macro Dados - Todos'!$A$2:$A$20000=Lacunas!B3) * ('Macro Dados - Todos'!$C$2:$C$20000=Lacunas!C3) * ('Macro Dados - Todos'!$D$2:$D$20000=Lacunas!E3) )} -> Maripa | C3: UVR 01 - Maripa | D3: 01 | E3: 15/11/2024 | F3: 5 | G3: A Recima é uma empresa tercerizada contratada pelo Município e o pagamento é realizado pela empresa | H3: 24858.1 | I3: 29503.37 | J3: 0 | K3: 28540 | L3: 0 | M3: 2500
A4: Gabriel | B4: {=_xlfn._xlws.FILTER( 'Macro Dados - Todos'!$A$2:$L$20000, ('Macro Dados - Todos'!$A$2:$A$20000=Lacunas!B4) * ('Macro Dados - Todos'!$C$2:$C$20000=Lacunas!C4) * ('Macro Dados - Todos'!$D$2:$D$20000=Lacunas!E4) )} -> Mundo Novo | C4: UVR 01 - Mundo Novo | D4: 01 | E4: 15/11/2024 | F4: 15 | G4: 0 | H4: 35681.9 | I4: 0 | J4: 628.32 | K4: 51259.5 | L4: 5469 | M4: 2334.2
A5: Gabriel | B5: {=_xlfn._xlws.FILTER( 'Macro Dados - Todos'!$A$2:$L$20000, ('Macro Dados - Todos'!$A$2:$A$20000=Lacunas!B5) * ('Macro Dados - Todos'!$C$2:$C$20000=Lacunas!C5) * ('Macro Dados - Todos'!$D$2:$D$20000=Lacunas!E5) )} -> Assis Chateaubriand | C5: UVR 01 - Assis Chateaubriand | D5: 01 | E5: 15/12/2024 | F5: 34 | G5: 01/12 à 23/12/2024 | H5: 69057.61 | I5: 30460.27 | J5: 8744 | K5: 87028.86 | L5: 15606 | M5: 3185
A6: Valquiria | B6: {=_xlfn._xlws.FILTER( 'Macro Dados - Todos'!$A$2:$L$20000, ('Macro Dados - Todos'!$A$2:$A$20000=Lacunas!B6) * ('Macro Dados - Todos'!$C$2:$C$20000=Lacunas!C6) * ('Macro Dados - Todos'!$D$2:$D$20000=Lacunas!E6) )} -> Cafelândia | C6: UVR 01 - Cafelândia | D6: 01 | E6: 15/12/2024 | F6: 54 | G6: valor da diaria mês de Dezembro R$113,71 | H6: 64350.62 | I6: 20918.32 | J6: 16068.48 | K6: 70264 | L6: 18290 | M6: 2103.63
A7: Valquiria | B7: {=_xlfn._xlws.FILTER( 'Macro Dados - Todos'!$A$2:$L$20000, ('Macro Dados - Todos'!$A$2:$A$20000=Lacunas!B7) * ('Macro Dados - Todos'!$C$2:$C$20000=Lacunas!C7) * ('Macro Dados - Todos'!$D$2:$D$20000=Lacunas!E7) )} -> Formosa do Oeste | C7: UVR 01 - Formosa do Oeste | D7: 01 | E7: 15/12/2024 | F7: 7 | G7: 0 | H7: 11863.9 | I7: 0 | J7: 0 | K7: 9235 | L7: 4030 | M7: 1694.84
A8: Larissa | B8: {=_xlfn._xlws.FILTER( 'Macro Dados - Todos'!$A$2:$L$20000, ('Macro Dados - Todos'!$A$2:$A$20000=Lacunas!B8) * ('Macro Dados - Todos'!$C$2:$C$20000=Lacunas!C8) * ('Macro Dados - Todos'!$D$2:$D$20000=Lacunas!E8) )} -> Foz do Iguaçu | C8: UVR 06 - Foz do Iguaçu | D8: 06 | E8: 15/12/2024 | F8: 19 | G8: 0 | H8: 24687.4 | I8: 44852.27 | J8: 20769.16 | K8: 20980 | L8: 4210 | M8: 1596.64
A9: Valquiria | B9: {=_xlfn._xlws.FILTER( 'Macro Dados - Todos'!$A$2:$L$20000, ('Macro Dados - Todos'!$A$2:$A$20000=Lacunas!B9) * ('Macro Dados - Todos'!$C$2:$C$20000=Lacunas!C9) * ('Macro Dados - Todos'!$D$2:$D$20000=Lacunas!E9) )} -> Jesuítas | C9: UVR 01 - Jesuítas | D9: 01 | E9: 15/12/2024 | F9: 10 | G9: 0 | H9: 32954.2 | I9: 0 | J9: 0 | K9: 30594 | L9: 0 | M9: 3295.42
A10: Luana | B10: {=_xlfn._xlws.FILTER( 'Macro Dados - Todos'!$A$2:$L$20000, ('Macro Dados - Todos'!$A$2:$A$20000=Lacunas!B10) * ('Macro Dados - Todos'!$C$2:$C$20000=Lacunas!C10) * ('Macro Dados - Todos'!$D$2:$D$20000=Lacunas!E10) )} -> Marechal Candido Rondon | C10: UVR 01 - Marechal Candido Rondon | D10: 01 | E10: 15/12/2024 | F10: 30 | G10: 0 | H10: 81830.64 | I10: 76402.32 | J10: 0 | K10: 150054.1 | L10: 29740 | M10: 2900
A11: Luana | B11: {=_xlfn._xlws.FILTER( 'Macro Dados - Todos'!$A$2:$L$20000, ('Macro Dados - Todos'!$A$2:$A$20000=Lacunas!B11) * ('Macro Dados - Todos'!$C$2:$C$20000=Lacunas!C11) * ('Macro Dados - Todos'!$D$2:$D$20000=Lacunas!E11) )} -> Marechal Candido Rondon | C11: UVR 02 - Marechal Candido Rondon | D11: 02 | E11: 15/12/2024 | F11: 29 | G11: 0 | H11: 139018.76 | I11: 76402.67 | J11: 0 | K11: 154296.2 | L11: 25980 | M11: 3000
A12: Gabriel | B12: {=_xlfn._xlws.FILTER( 'Macro Dados - Todos'!$A$2:$L$20000, ('Macro Dados - Todos'!$A$2:$A$20000=Lacunas!B12) * ('Macro Dados - Todos'!$C$2:$C$20000=Lacunas!C12) * ('Macro Dados - Todos'!$D$2:$D$20000=Lacunas!E12) )} -> Maripa | C12: UVR 01 - Maripa | D12: 01 | E12: 15/12/2024 | F12: 5 | G12: A Recima é uma empresa tercerizada contratada pelo Município e o pagamento é realizado pela empresa | H12: 22822 | I12: 29503.37 | J12: 0 | K12: 20398 | L12: 0 | M12: 2500
A13: Gabriel | B13: {=_xlfn._xlws.FILTER( 'Macro Dados - Todos'!$A$2:$L$20000, ('Macro Dados - Todos'!$A$2:$A$20000=Lacunas!B13) * ('Macro Dados - Todos'!$C$2:$C$20000=Lacunas!C13) * ('Macro Dados - Todos'!$D$2:$D$20000=Lacunas!E13) )} -> Palotina | C13: UVR 01 - Palotina | D13: 01 | E13: 15/12/2024 | F13: 20 | G13: O total de Associados que trabalharam todos os dias( não tiveram faltas) foram 3 três) | H13: 65586.5 | I13: 0 | J13: 18985.51 | K13: 102194 | L13: 48200 | M13: 6642.2
A14: Gabriel | B14: {=_xlfn._xlws.FILTER( 'Macro Dados - Todos'!$A$2:$L$20000, ('Macro Dados - Todos'!$A$2:$A$20000=Lacunas!B14) * ('Macro Dados - Todos'!$C$2:$C$20000=Lacunas!C14) * ('Macro Dados - Todos'!$D$2:$D$20000=Lacunas!E14) )} -> Assis Chateaubriand | C14: UVR 01 - Assis Chateaubriand | D14: 01 | E14: 15/1/2025 | F14: 35 | G14: 0 | H14: 60635.57 | I14: 20852.5 | J14: 6862.97 | K14: 59542 | L14: 26447 | M14: 2800
A15: Gabriel | B15: {=_xlfn._xlws.FILTER( 'Macro Dados - Todos'!$A$2:$L$20000, ('Macro Dados - Todos'!$A$2:$A$20000=Lacunas!B15) * ('Macro Dados - Todos'!$C$2:$C$20000=Lacunas!C15) * ('Macro Dados - Todos'!$D$2:$D$20000=Lacunas!E15) )} -> Brasilândia do Sul | C15: UVR 01 - Brasilândia do Sul | D15: 01 | E15: 15/1/2025 | F15: 5 | G15: 0 | H15: 7861.9 | I15: 7700 | J15: 0 | K15: 15260 | L15: 1815 | M15: 2957.84
A16: Valquiria | B16: {=_xlfn._xlws.FILTER( 'Macro Dados - Todos'!$A$2:$L$20000, ('Macro Dados - Todos'!$A$2:$A$20000=Lacunas!B16) * ('Macro Dados - Todos'!$C$2:$C$20000=Lacunas!C16) * ('Macro Dados - Todos'!$D$2:$D$20000=Lacunas!E16) )} -> Cafelândia | C16: UVR 01 - Cafelândia | D16: 01 | E16: 15/1/2025 | F16: 48 | G16: Valor da diaria dos associados foi de R$122,90 | H16: 64957.32 | I16: 77184.72 | J16: 18645.48 | K16: 74791 | L16: 27340 | M16: 2235.03
A17: Larissa | B17: {=_xlfn._xlws.FILTER( 'Macro Dados - Todos'!$A$2:$L$20000, ('Macro Dados - Todos'!$A$2:$A$20000=Lacunas!B17) * ('Macro Dados - Todos'!$C$2:$C$20000=Lacunas!C17) * ('Macro Dados - Todos'!$D$2:$D$20000=Lacunas!E17) )} -> Foz do Iguaçu | C17: UVR 06 - Foz do Iguaçu | D17: 06 | E17: 15/1/2025 | F17: 19 | G17: 1943,48 | H17: 50035 | I17: 40307.67 | J17: 18148.15 | K17: 54742 | L17: 8450 | M17: 1943.48
A18: Valquiria | B18: {=_xlfn._xlws.FILTER( 'Macro Dados - Todos'!$A$2:$L$20000, ('Macro Dados - Todos'!$A$2:$A$20000=Lacunas!B18) * ('Macro Dados - Todos'!$C$2:$C$20000=Lacunas!C18) * ('Macro Dados - Todos'!$D$2:$D$20000=Lacunas!E18) )} -> Jesuítas | C18: UVR 01 - Jesuítas | D18: 01 | E18: 15/1/2025 | F18: 10 | G18: 0 | H18: 35453.7 | I18: 0 | J18: 0 | K18: 36695 | L18: 0 | M18: 3545.37
A19: Luana | B19: {=_xlfn._xlws.FILTER( 'Macro Dados - Todos'!$A$2:$L$20000, ('Macro Dados - Todos'!$A$2:$A$20000=Lacunas!B19) * ('Macro Dados - Todos'!$C$2:$C$20000=Lacunas!C19) * ('Macro Dados - Todos'!$D$2:$D$20000=Lacunas!E19) )} -> Marechal Candido Rondon | C19: UVR 01 - Marechal Candido Rondon | D19: 01 | E19: 15/1/2025 | F19: 30 | G19: 0 | H19: 115584.26 | I19: 76402.32 | J19: 0 | K19: 149335 | L19: 75790 | M19: 2900
A20: Luana | B20: {=_xlfn._xlws.FILTER( 'Macro Dados - Todos'!$A$2:$L$20000, ('Macro Dados - Todos'!$A$2:$A$20000=Lacunas!B20) * ('Macro Dados - Todos'!$C$2:$C$20000=Lacunas!C20) * ('Macro Dados - Todos'!$D$2:$D$20000=Lacunas!E20) )} -> Marechal Candido Rondon | C20: UVR 02 - Marechal Candido Rondon | D20: 02 | E20: 15/1/2025 | F20: 29 | G20: 0 | H20: 141072.9 | I20: 76402.67 | J20: 0 | K20: 150768 | L20: 45450 | M20: 3000
A21: Gabriel | B21: {=_xlfn._xlws.FILTER( 'Macro Dados - Todos'!$A$2:$L$20000, ('Macro Dados - Todos'!$A$2:$A$20000=Lacunas!B21) * ('Macro Dados - Todos'!$C$2:$C$20000=Lacunas!C21) * ('Macro Dados - Todos'!$D$2:$D$20000=Lacunas!E21) )} -> Palotina | C21: UVR 01 - Palotina | D21: 01 | E21: 15/1/2025 | F21: 20 | G21: O total de Associados que trabalharam todos os dias( não tiveram faltas) foram 2 (dois) | H21: 65797.05 | I21: 0 | J21: 13146.12 | K21: 101551 | L21: 46340 | M21: 3776.6
A22: Gabriel | B22: Palotina | C22: UVR 01 - Palotina | D22: 01 | E22: 15/1/2025 | F22: 22 | G22: O total de Associados que trabalharam todos os dias( não tiveram faltas) foram 03 (três) | H22: 74420.42 | I22: 0 | J22: 0 | K22: 86706 | L22: 48560 | M22: 4181.9
A23: Bianca | B23: {=_xlfn._xlws.FILTER( 'Macro Dados - Todos'!$A$2:$L$20000, ('Macro Dados - Todos'!$A$2:$A$20000=Lacunas!B23) * ('Macro Dados - Todos'!$C$2:$C$20000=Lacunas!C23) * ('Macro Dados - Todos'!$D$2:$D$20000=Lacunas!E23) )} -> Tres Barras do Parana | C23: UVR 01 - Tres Barras do Parana | D23: 01 | E23: 15/1/2025 | F23: 12 | G23: 0 | H23: 13698.85 | I23: 0 | J23: 0 | K23: 24207 | L23: 0 | M23: 1325

Sheet Micro Dados - Todos
A1: UVR Município + Número | B1: UVR Número | C1: Município | D1: Data de referência | E1: Tipo do registro | F1: Subtipo do registro | G1: Material | H1: Qual outro material? | I1: Quantidade | J1: Valor Absoluto (R$) | K1: Preço Médio | L1: Subtipo do Registro - Outro | M1: Data de referência
A2: UVR 01 - Tres Barras do Parana | B2: 01 | C2: Tres Barras do Parana | D2: =LEFT(M2,10) -> 12/15/2024 | E2: Receita da venda de recicláveis | F2: Metal | G2: Alumínio Latinha | I2: 87.5 | J2: 437.5 | K2: 5 | M2: 12/15/2024, 12:00 PM
A3: UVR 01 - Tres Barras do Parana | B3: 01 | C3: Tres Barras do Parana | D3: =LEFT(M3,10) -> 12/15/2024 | E3: Receita da venda de recicláveis | F3: Metal | G3: Inox | I3: 12.9 | J3: 32.25 | K3: 2.5 | M3: 12/15/2024, 12:00 PM
A4: UVR 01 - Tres Barras do Parana | B4: 01 | C4: Tres Barras do Parana | D4: =LEFT(M4,10) -> 12/15/2024 | E4: Receita da venda de recicláveis | F4: Metal | G4: Alumínio Bloco | I4: 12.4 | J4: 50.4 | K4: 4.06 | M4: 12/15/2024, 12:00 PM
A5: UVR 01 - Tres Barras do Parana | B5: 01 | C5: Tres Barras do Parana | D5: =LEFT(M5,10) -> 12/15/2024 | E5: Receita da venda de recicláveis | F5: Metal | G5: Alumínio Panela | I5: 28 | J5: 196 | K5: 7 | M5: 12/15/2024, 12:00 PM
A6: UVR 01 - Tres Barras do Parana | B6: 01 | C6: Tres Barras do Parana | D6: =LEFT(M6,10) -> 12/15/2024 | E6: Receita da venda de recicláveis | F6: Elétrico ou Eletrônicos | G6: Bateria | I6: 2 | J6: 5 | K6: 2.5 | M6: 12/15/2024, 12:00 PM
A7: UVR 01 - Tres Barras do Parana | B7: 01 | C7: Tres Barras do Parana | D7: =LEFT(M7,10) -> 12/15/2024 | E7: Receita da venda de recicláveis | F7: Elétrico ou Eletrônicos | G7: Informática | I7: 3 | J7: 60 | K7: 20 | M7: 12/15/2024, 12:00 PM
A8: UVR 01 - Tres Barras do Parana | B8: 01 | C8: Tres Barras do Parana | D8: =LEFT(M8,10) -> 12/15/2024 | E8: Receita da venda de recicláveis | F8: Elétrico ou Eletrônicos | G8: Informática | I8: 4 | J8: 80 | K8: 20 | M8: 12/15/2024, 12:00 PM
A9: UVR 01 - Tres Barras do Parana | B9: 01 | C9: Tres Barras do Parana | D9: =LEFT(M9,10) -> 12/15/2024 | E9: Receita da venda de recicláveis | F9: Elétrico ou Eletrônicos | G9: placa | I9: 15 | J9: 82.5 | K9: 5.5 | M9: 12/15/2024, 12:00 PM
A10: UVR 01 - Tres Barras do Parana | B10: 01 | C10: Tres Barras do Parana | D10: =LEFT(M10,10) -> 12/15/2024 | E10: Receita da venda de recicláveis | F10: Elétrico ou Eletrônicos | G10: Memória | I10: 2 | J10: 9.6 | K10: 4.8 | M10: 12/15/2024, 12:00 PM
A11: UVR 01 - Tres Barras do Parana | B11: 01 | C11: Tres Barras do Parana | D11: =LEFT(M11,10) -> 12/15/2024 | E11: Receita da venda de recicláveis | F11: Elétrico ou Eletrônicos | G11: Informática | I11: 467 | J11: 280.2 | K11: 0.6 | M11: 12/15/2024, 12:00 PM
A12: UVR 01 - Tres Barras do Parana | B12: 01 | C12: Tres Barras do Parana | D12: =LEFT(M12,10) -> 12/15/2024 | E12: Receita da venda de recicláveis | F12: Elétrico ou Eletrônicos | G12: Sucata Eletrônica | I12: 200 | J12: 180 | K12: 0.9 | M12: 12/15/2024, 12:00 PM
A13: UVR 01 - Tres Barras do Parana | B13: 01 | C13: Tres Barras do Parana | D13: =LEFT(M13,10) -> 12/15/2024 | E13: Receita da venda de recicláveis | F13: Elétrico ou Eletrônicos | G13: Sucata Eletrônica | I13: 136 | J13: 68 | K13: 0.5 | M13: 12/15/2024, 12:00 PM
... A27: UVR 01 - Tres Barras do Parana | B27: 01 | C27: Tres Barras do Parana | D27: =LEFT(M27,10) -> 12/15/2024 | E27: Receita da venda de recicláveis | F27: Papéis | G27: Papelão | I27: 8800 | J27: 3520 | K27: 0.4 | M27: 12/15/2024, 12:00 PM
A28: UVR 01 - Tres Barras do Parana | B28: 01 | C28: Tres Barras do Parana | D28: =LEFT(M28,10) -> 12/15/2024 | E28: Receita da prestação de serviços | F28: Serviço de Logística Reversa | I28: 0 | J28: 823 | M28: 12/15/2024, 12:00 PM
A29: UVR 01 - Tres Barras do Parana | B29: 01 | C29: Tres Barras do Parana | D29: =LEFT(M29,10) -> 12/15/2024 | E29: Despesa | F29: Impostos/taxas | I29: 0 | J29: 1200 | M29: 12/15/2024, 12:00 PM
A30: UVR 01 - Tres Barras do Parana | B30: 01 | C30: Tres Barras do Parana | D30: =LEFT(M30,10) -> 12/15/2024 | E30: Rejeito | F30: Rejeito | I30: 0 | M30: 12/15/2024, 12:00 PM
A31: UVR 01 - Tres Barras do Parana | B31: 01 | C31: Tres Barras do Parana | D31: =LEFT(M31,10) -> 12/15/2024 | E31: Receita da venda de recicláveis | F31: Metal | G31: Chaparia | I31: 23 | J31: 18 | K31: 0.78 | M31: 12/15/2024, 12:00 PM
A32: UVR 01 - Matelândia | B32: 01 | C32: Matelândia | D32: =LEFT(M32,10) -> 12/15/2024 | E32: Receita da venda de recicláveis | F32: Metal | G32: Sucatas | I32: 1086.5 | J32: 6667.3 | K32: 6.14 | M32: 12/15/2024, 12:00 PM
A33: UVR 01 - Matelândia | B33: 01 | C33: Matelândia | D33: =LEFT(M33,10) -> 12/15/2024 | E33: Receita da venda de recicláveis | F33: Metal | G33: Sucatas | I33: 4180 | J33: 1881 | K33: 0.45 | M33: 12/15/2024, 12:00 PM
A34: UVR 01 - Matelândia | B34: 01 | C34: Matelândia | D34: =LEFT(M34,10) -> 12/15/2024 | E34: Receita da venda de recicláveis | F34: Papéis | G34: Papelão | I34: 8130 | J34: 3252 | K34: 0.4 | M34: 12/15/2024, 12:00 PM
A35: UVR 01 - Matelândia | B35: 01 | C35: Matelândia | D35: =LEFT(M35,10) -> 12/15/2024 | E35: Receita da venda de recicláveis | F35: Papéis | G35: Papel Branco | I35: 1210 | J35: 726 | K35: 0.6 | M35: 12/15/2024, 12:00 PM
A36: UVR 01 - Matelândia | B36: 01 | C36: Matelândia | D36: =LEFT(M36,10) -> 12/15/2024 | E36: Receita da venda de recicláveis | F36: Papéis | G36: Papel Cimento | I36: 860 | J36: 129 | K36: 0.15 | M36: 12/15/2024, 12:00 PM
A37: UVR 01 - Matelândia | B37: 01 | C37: Matelândia | D37: =LEFT(M37,10) -> 12/15/2024 | E37: Receita da venda de recicláveis | F37: Papéis | G37: Papel Misto | I37: 6280 | J37: 942 | K37: 0.15 | M37: 12/15/2024, 12:00 PM
A38: UVR 01 - Matelândia | B38: 01 | C38: Matelândia | D38: =LEFT(M38,10) -> 12/15/2024 | E38: Receita da venda de recicláveis | F38: Papéis | G38: Papelão | I38: 9020 | J38: 3608 | K38: 0.4 | M38: 12/15/2024, 12:00 PM
A39: UVR 01 - Matelândia | B39: 01 | C39: Matelândia | D39: =LEFT(M39,10) -> 12/15/2024 | E39: Receita da venda de recicláveis | F39: Papéis | G39: Papel Branco | I39: 1120 | J39: 672 | K39: 0.6 | M39: 12/15/2024, 12:00 PM
A40: UVR 01 - Matelândia | B40: 01 | C40: Matelândia | D40: =LEFT(M40,10) -> 12/15/2024 | E40: Receita da venda de recicláveis | F40: Papéis | G40: Papel Cimento | I40: 320 | J40: 48 | K40: 0.15 | M40: 12/15/2024, 12:00 PM
A41: UVR 01 - Matelândia | B41: 01 | C41: Matelândia | D41: =LEFT(M41,10) -> 12/15/2024 | E41: Receita da venda de recicláveis | F41: Papéis | G41: Papel Misto | I41: 7150 | J41: 1072.5 | K41: 0.15 | M41: 12/15/2024, 12:00 PM
A42: UVR 01 - Matelândia | B42: 01 | C42: Matelândia | D42: =LEFT(M42,10) -> 12/15/2024 | E42: Receita da venda de recicláveis | F42: Plástico | G42: PS Expansível (Isopor) | I42: 250 | J42: 50 | K42: 0.2 | M42: 12/15/2024, 12:00 PM
... A50: UVR 01 - Matelândia | B50: 01 | C50: Matelândia | D50: =LEFT(M50,10) -> 12/15/2024 | E50: Receita da venda de recicláveis | F50: Plástico | G50: PEAD (Embalagens de produtos de limpeza) | I50: 544 | J50: 1196.8 | K50: 2.2 | M50: 12/15/2024, 12:00 PM
A51: UVR 01 - Matelândia | B51: 01 | C51: Matelândia | D51: =LEFT(M51,10) -> 12/15/2024 | E51: Receita da venda de recicláveis | F51: Plástico | G51: Outro tipo de plástico | H51: Fita arquemento ( PET ) | I51: 103 | J51: 51.5 | K51: 0.5 | M51: 12/15/2024, 12:00 PM
A52: UVR 01 - Matelândia | B52: 01 | C52: Matelândia | D52: =LEFT(M52,10) -> 12/15/2024 | E52: Receita da venda de recicláveis | F52: Plástico | G52: PP Rígido (Balde, bacia, potes de sorvetes, margarina, entre outros) | I52: 112 | J52: 156.8 | K52: 1.4 | M52: 12/15/2024, 12:00 PM
A53: UVR 01 - Matelândia | B53: 01 | C53: Matelândia | D53: =LEFT(M53,10) -> 12/15/2024 | E53: Receita da venda de recicláveis | F53: Plástico | G53: PS (Copos descartáveis) | I53: 317 | J53: 253.6 | K53: 0.8 | M53: 12/15/2024, 12:00 PM
A54: UVR 01 - Matelândia | B54: 01 | C54: Matelândia | D54: =LEFT(M54,10) -> 12/15/2024 | E54: Receita da venda de recicláveis | F54: Plástico | G54: PEBD Filme (Sacolinha, Sacos de lixo, Lona Preta) | I54: 504 | J54: 252 | K54: 0.5 | M54: 12/15/2024, 12:00 PM
A55: UVR 01 - Matelândia | B55: 01 | C55: Matelândia | D55: =LEFT(M55,10) -> 12/15/2024 | E55: Receita da venda de recicláveis | F55: Plástico | G55: PEBD Filme (Sacolinha, Sacos de lixo, Lona Preta) | I55: 1502 | J55: 1051.4 | K55: 0.7 | M55: 12/15/2024, 12:00 PM
A56: UVR 01 - Matelândia | B56: 01 | C56: Matelândia | D56: =LEFT(M56,10) -> 12/15/2024 | E56: Receita da venda de recicláveis | F56: Plástico | G56: PEAD Filme (Cristal) | I56: 1038 | J56: 1349.4 | K56: 1.3 | M56: 12/15/2024, 12:00 PM
A57: UVR 01 - Matelândia | B57: 01 | C57: Matelândia | D57: =LEFT(M57,10) -> 12/15/2024 | E57: Receita da venda de recicláveis | F57: Plástico | G57: PS Rígido (Forro de geladeiras) | I57: 113 | J57: 22.6 | K57: 0.2 | M57: 12/15/2024, 12:00 PM
A58: UVR 01 - Matelândia | B58: 01 | C58: Matelândia | D58: =LEFT(M58,10) -> 12/15/2024 | E58: Receita da venda de recicláveis | F58: Plástico | G58: PP Ráfia (Sacaria) | I58: 352 | J58: 176 | K58: 0.5 | M58: 12/15/2024, 12:00 PM
A59: UVR 01 - Matelândia | B59: 01 | C59: Matelândia | D59: =LEFT(M59,10) -> 12/15/2024 | E59: Receita da venda de recicláveis | F59: Plástico | G59: PET Cristal (Embalagens de refrigerante transparente) | I59: 1669 | J59: 3504.9 | K59: 2.1 | M59: 12/15/2024, 12:00 PM
A60: UVR 01 - Matelândia | B60: 01 | C60: Matelândia | D60: =LEFT(M60,10) -> 12/15/2024 | E60: Receita da venda de recicláveis | F60: Plástico | G60: Outro tipo de plástico | H60: Tampinha de Garrafas ( PP ) 2 Bags | I60: 243 | J60: 243 | K60: 1 | M60: 12/15/2024, 12:00 PM
...

Sheet Micro Dados - Filtrados
A1: Regional | B1: UVR Município + Número | C1: UVR Número | D1: Município | E1: Data de referência | F1: Tipo do registro | G1: Subtipo do registro | H1: Material | I1: Qual outro material? | J1: Quantidade | K1: Valor Absoluto (R$) | L1: Preço Médio | M1: Subtipo do Registro - Outro
A2: Valquiria | B2: {=_xlfn._xlws.FILTER( 'Micro Dados - Todos'!$A$2:$L$20000, ('Micro Dados - Todos'!$C$2:$C$20000=Lacunas!B2) * ('Micro Dados - Todos'!$B$2:$B$20000=Lacunas!C2) * ('Micro Dados - Todos'!$D$2:$D$20000=Lacunas!F2) )} -> UVR 01 - Formosa do Oeste | C2: 01 | D2: Formosa do Oeste | E2: 11/15/2024 | F2: Receita da venda de recicláveis | G2: Plástico | H2: PET Cristal (Embalagens de refrigerante transparente) | I2: 0 | J2: 830 | K2: 3486 | L2: 4.2 | M2: 0
A3: Valquiria | B3: UVR 01 - Formosa do Oeste | C3: 01 | D3: Formosa do Oeste | E3: 11/15/2024 | F3: Receita da venda de recicláveis | G3: Plástico | H3: PP Rígido (Balde, bacia, potes de sorvetes, margarina, entre outros) | I3: 0 | J3: 185 | K3: 259 | L3: 1.4 | M3: 0
A4: Valquiria | B4: UVR 01 - Formosa do Oeste | C4: 01 | D4: Formosa do Oeste | E4: 11/15/2024 | F4: Receita da venda de recicláveis | G4: Plástico | H4: PP Rígido (Balde, bacia, potes de sorvetes, margarina, entre outros) | I4: 0 | J4: 150 | K4: 270 | L4: 1.8 | M4: 0
A5: Valquiria | B5: UVR 01 - Formosa do Oeste | C5: 01 | D5: Formosa do Oeste | E5: 11/15/2024 | F5: Receita da venda de recicláveis | G5: Plástico | H5: PP Mineral (Copinho de água mineral) | I5: 0 | J5: 40 | K5: 40 | L5: 1 | M5: 0
A6: Valquiria | B6: UVR 01 - Formosa do Oeste | C6: 01 | D6: Formosa do Oeste | E6: 11/15/2024 | F6: Receita da venda de recicláveis | G6: Papéis | H6: Tetra Pack | I6: 0 | J6: 250 | K6: 62.5 | L6: 0.25 | M6: 0
A7: Valquiria | B7: UVR 01 - Formosa do Oeste | C7: 01 | D7: Formosa do Oeste | E7: 11/15/2024 | F7: Receita da venda de recicláveis | G7: Plástico | H7: PEBD Filme (Sacolinha, Sacos de lixo, Lona Preta) | I7: 0 | J7: 280 | K7: 196 | L7: 0.7 | M7: 0
A8: Valquiria | B8: UVR 01 - Formosa do Oeste | C8: 01 | D8: Formosa do Oeste | E8: 11/15/2024 | F8: Receita da venda de recicláveis | G8: Plástico | H8: PP Ráfia (Sacaria) | I8: 0 | J8: 110 | K8: 38.5 | L8: 0.35 | M8: 0
A9: Valquiria | B9: UVR 01 - Formosa do Oeste | C9: 01 | D9: Formosa do Oeste | E9: 11/15/2024 | F9: Receita da venda de recicláveis | G9: Plástico | H9: PP Rígido (Balde, bacia, potes de sorvetes, margarina, entre outros) | I9: 0 | J9: 75 | K9: 112.5 | L9: 1.5 | M9: 0
A10: Valquiria | B10: UVR 01 - Formosa do Oeste | C10: 01 | D10: Formosa do Oeste | E10: 11/15/2024 | F10: Receita da venda de recicláveis | G10: Plástico | H10: PEAD (Embalagens de produtos de limpeza) | I10: 0 | J10: 338 | K10: 760.5 | L10: 2.25 | M10: 0
A11: Valquiria | B11: UVR 01 - Formosa do Oeste | C11: 01 | D11: Formosa do Oeste | E11: 11/15/2024 | F11: Receita da venda de recicláveis | G11: Plástico | H11: PET Óleo (Embalagens de óleo de cozinha) | I11: 0 | J11: 75 | K11: 135 | L11: 1.8 | M11: 0
A12: Valquiria | B12: UVR 01 - Formosa do Oeste | C12: 01 | D12: Formosa do Oeste | E12: 11/15/2024 | F12: Receita da venda de recicláveis | G12: Plástico | H12: PP Rígido (Balde, bacia, potes de sorvetes, margarina, entre outros) | I12: 0 | J12: 50 | K12: 65 | L12: 1.3 | M12: 0
A13: Valquiria | B13: UVR 01 - Formosa do Oeste | C13: 01 | D13: Formosa do Oeste | E13: 11/15/2024 | F13: Receita da venda de recicláveis | G13: Plástico | H13: PET Colorido (Embalagens de PET colorido, PET bagunça) | I13: 0 | J13: 150 | K13: 30 | L13: 0.2 | M13: 0
A14: Valquiria | B14: UVR 01 - Formosa do Oeste | C14: 01 | D14: Formosa do Oeste | E14: 11/15/2024 | F14: Receita da venda de recicláveis | G14: Plástico | H14: PEBD Filme (Sacolinha, Sacos de lixo, Lona Preta) | I14: 0 | J14: 50 | K14: 30 | L14: 0.6 | M14: 0
... A25: Valquiria | B25: UVR 01 - Formosa do Oeste | C25: 01 | D25: Formosa do Oeste | E25: 11/15/2024 | F25: Rejeito | G25: Rejeito | H25: null | I25: 0 | J25: 3620 | K25: 0 | L25: 0 | M25: 0
A26: Gabriel | B26: {=_xlfn._xlws.FILTER( 'Micro Dados - Todos'!$A$2:$L$20000, ('Micro Dados - Todos'!$C$2:$C$20000=Lacunas!B3) * ('Micro Dados - Todos'!$B$2:$B$20000=Lacunas!C3) * ('Micro Dados - Todos'!$D$2:$D$20000=Lacunas!F3) )} -> UVR 01 - Maripa | C26: 01 | D26: Maripa | E26: 11/15/2024 | F26: Receita da venda de recicláveis | G26: Papéis | H26: Papel Branco | I26: 0 | J26: 800 | K26: 560 | L26: 0.7 | M26: 0
A27: Gabriel | B27: UVR 01 - Maripa | C27: 01 | D27: Maripa | E27: 11/15/2024 | F27: Receita da venda de recicláveis | G27: Papéis | H27: Papel Misto | I27: 0 | J27: 1300 | K27: 325 | L27: 0.25 | M27: 0
A28: Gabriel | B28: UVR 01 - Maripa | C28: 01 | D28: Maripa | E28: 11/15/2024 | F28: Receita da venda de recicláveis | G28: Papéis | H28: Papelão | I28: 0 | J28: 8500 | K28: 5950 | L28: 0.7 | M28: 0
A29: Gabriel | B29: UVR 01 - Maripa | C29: 01 | D29: Maripa | E29: 11/15/2024 | F29: Receita da venda de recicláveis | G29: Papéis | H29: Tetra Pack | I29: 0 | J29: 500 | K29: 150 | L29: 0.3 | M29: 0
A30: Gabriel | B30: UVR 01 - Maripa | C30: 01 | D30: Maripa | E30: 11/15/2024 | F30: Receita da venda de recicláveis | G30: Plástico | H30: PVC (Cano, Forro, Tubulação de cano) | I30: 0 | J30: 100 | K30: 80 | L30: 0.8 | M30: 0
A31: Gabriel | B31: UVR 01 - Maripa | C31: 01 | D31: Maripa | E31: 11/15/2024 | F31: Receita da venda de recicláveis | G31: Plástico | H31: PEAD (Embalagens de produtos de limpeza) | I31: 0 | J31: 1050 | K31: 2310 | L31: 2.2 | M31: 0
A32: Gabriel | B32: UVR 01 - Maripa | C32: 01 | D32: Maripa | E32: 11/15/2024 | F32: Receita da venda de recicláveis | G32: Plástico | H32: PEAD Filme (Cristal) | I32: 0 | J32: 1500 | K32: 1950 | L32: 1.3 | M32: 0
A33: Gabriel | B33: UVR 01 - Maripa | C33: 01 | D33: Maripa | E33: 11/15/2024 | F33: Receita da venda de recicláveis | G33: Plástico | H33: PEBD Filme (Sacolinha, Sacos de lixo, Lona Preta) | I33: 0 | J33: 2000 | K33: 1500 | L33: 0.75 | M33: 0
A34: Gabriel | B34: UVR 01 - Maripa | C34: 01 | D34: Maripa | E34: 11/15/2024 | F34: Receita da venda de recicláveis | G34: Plástico | H34: PET Verde (Embalagens de refrigerante verde) | I34: 0 | J34: 450 | K34: 1800 | L34: 4 | M34: 0
A35: Gabriel | B35: UVR 01 - Maripa | C35: 01 | D35: Maripa | E35: 11/15/2024 | F35: Receita da venda de recicláveis | G35: Plástico | H35: PET Cristal (Embalagens de refrigerante transparente) | I35: 0 | J35: 450 | K35: 1800 | L35: 4 | M35: 0
A36: Gabriel | B36: UVR 01 - Maripa | C36: 01 | D36: Maripa | E36: 11/15/2024 | F36: Receita da venda de recicláveis | G36: Plástico | H36: PET Óleo (Embalagens de óleo de cozinha) | I36: 0 | J36: 150 | K36: 195 | L36: 1.3 | M36: 0
A37: Gabriel | B37: UVR 01 - Maripa | C37: 01 | D37: Maripa | E37: 11/15/2024 | F37: Receita da venda de recicláveis | G37: Plástico | H37: PET Colorido (Embalagens de PET colorido, PET bagunça) | I37: 0 | J37: 100 | K37: 5 | L37: 0.05 | M37: 0
A38: Gabriel | B38: UVR 01 - Maripa | C38: 01 | D38: Maripa | E38: 11/15/2024 | F38: Receita da venda de recicláveis | G38: Plástico | H38: PS (Copos descartáveis) | I38: 0 | J38: 160 | K38: 160 | L38: 1 | M38: 0
... A48: Gabriel | B48: UVR 01 - Maripa | C48: 01 | D48: Maripa | E48: 11/15/2024 | F48: Receita da venda de recicláveis | G48: Elétrico ou Eletrônicos | H48: Bateria | I48: 0 | J48: 21 | K48: 54.6 | L48: 2.6 | M48: 0
A49: Gabriel | B49: UVR 01 - Maripa | C49: 01 | D49: Maripa | E49: 11/15/2024 | F49: Receita da prestação de serviços | G49: Contratos | H49: 0 | I49: 0 | J49: 0 | K49: 29503.37 | L49: 0 | M49: 0
A50: Gabriel | B50: {=_xlfn._xlws.FILTER( 'Micro Dados - Todos'!$A$2:$L$20000, ('Micro Dados - Todos'!$C$2:$C$20000=Lacunas!B4) * ('Micro Dados - Todos'!$B$2:$B$20000=Lacunas!C4) * ('Micro Dados - Todos'!$D$2:$D$20000=Lacunas!F4) )} -> UVR 01 - Mundo Novo | C50: 01 | D50: Mundo Novo | E50: 11/15/2024 | F50: Receita da venda de recicláveis | G50: Vidro | H50: Caco | I50: 0 | J50: 19340 | K50: 1934 | L50: 0.1 | M50: 0
A51: Gabriel | B51: UVR 01 - Mundo Novo | C51: 01 | D51: Mundo Novo | E51: 11/15/2024 | F51: Receita da venda de recicláveis | G51: Papéis | H51: Papelão | I51: 0 | J51: 21036 | K51: 16868.8 | L51: 0.8 | M51: 0
A52: Gabriel | B52: UVR 01 - Mundo Novo | C52: 01 | D52: Mundo Novo | E52: 11/15/2024 | F52: Receita da venda de recicláveis | G52: Papéis | H52: Papel Misto | I52: 0 | J52: 871 | K52: 348.8 | L52: 0.4 | M52: 0
A53: Gabriel | B53: UVR 01 - Mundo Novo | C53: 01 | D53: Mundo Novo | E53: 11/15/2024 | F53: Receita da venda de recicláveis | G53: Papéis | H53: Papel Branco | I53: 0 | J53: 778 | K53: 466.8 | L53: 0.6 | M53: 0
A54: Gabriel | B54: UVR 01 - Mundo Novo | C54: 01 | D54: Mundo Novo | E54: 11/15/2024 | F54: Receita da venda de recicláveis | G54: Papéis | H54: Tetra Pack | I54: 0 | J54: 251 | K54: 87.85 | L54: 0.35 | M54: 0
A55: Gabriel | B55: UVR 01 - Mundo Novo | C55: 01 | D55: Mundo Novo | E55: 11/15/2024 | F55: Receita da venda de recicláveis | G55: Papéis | H55: Papel Cimento | I55: 0 | J55: 366 | K55: 146.4 | L55: 0.4 | M55: 0
A56: Gabriel | B56: UVR 01 - Mundo Novo | C56: 01 | D56: Mundo Novo | E56: 11/15/2024 | F56: Receita da venda de recicláveis | G56: Papéis | H56: Papel Branco | I56: 0 | J56: 412 | K56: 247.2 | L56: 0.6 | M56: 0
A57: Gabriel | B57: UVR 01 - Mundo Novo | C57: 01 | D57: Mundo Novo | E57: 11/15/2024 | F57: Receita da venda de recicláveis | G57: Plástico | H57: PET Cristal (Embalagens de refrigerante transparente) | I57: 0 | J57: 1157 | K57: 5206.5 | L57: 4.5 | M57: 0
A58: Gabriel | B58: UVR 01 - Mundo Novo | C58: 01 | D58: Mundo Novo | E58: 11/15/2024 | F58: Receita da venda de recicláveis | G58: Plástico | H58: PEAD (Embalagens de produtos de limpeza) | I58: 0 | J58: 583 | K58: 1311.75 | L58: 2.25 | M58: 0
A59: Gabriel | B59: UVR 01 - Mundo Novo | C59: 01 | D59: Mundo Novo | E59: 11/15/2024 | F59: Receita da venda de recicláveis | G59: Plástico | H59: PEAD Filme (Cristal) | I59: 0 | J59: 1106 | K59: 1548.4 | L59: 1.4 | M59: 0
...
